INFO:     Will watch for changes in these directories: ['/home/alex/Downloads/new-pr/backend']
INFO:     Uvicorn running on http://127.0.0.1:8000 (Press CTRL+C to quit)
INFO:     Started reloader process [28143] using StatReload
Process SpawnProcess-1:
Traceback (most recent call last):
  File "/usr/lib/python3.12/multiprocessing/process.py", line 314, in _bootstrap
    self.run()
  File "/usr/lib/python3.12/multiprocessing/process.py", line 108, in run
    self._target(*self._args, **self._kwargs)
  File "/home/alex/Downloads/new-pr/ai_env/lib/python3.12/site-packages/uvicorn/_subprocess.py", line 80, in subprocess_started
    target(sockets=sockets)
  File "/home/alex/Downloads/new-pr/ai_env/lib/python3.12/site-packages/uvicorn/server.py", line 67, in run
    return asyncio.run(self.serve(sockets=sockets))
           ^^^^^^^^^^^^^^^^^^^^^^^^^^^^^^^^^^^^^^^^
  File "/usr/lib/python3.12/asyncio/runners.py", line 194, in run
    return runner.run(main)
           ^^^^^^^^^^^^^^^^
  File "/usr/lib/python3.12/asyncio/runners.py", line 118, in run
    return self._loop.run_until_complete(task)
           ^^^^^^^^^^^^^^^^^^^^^^^^^^^^^^^^^^^
  File "/usr/lib/python3.12/asyncio/base_events.py", line 687, in run_until_complete
    return future.result()
           ^^^^^^^^^^^^^^^
  File "/home/alex/Downloads/new-pr/ai_env/lib/python3.12/site-packages/uvicorn/server.py", line 71, in serve
    await self._serve(sockets)
  File "/home/alex/Downloads/new-pr/ai_env/lib/python3.12/site-packages/uvicorn/server.py", line 78, in _serve
    config.load()
  File "/home/alex/Downloads/new-pr/ai_env/lib/python3.12/site-packages/uvicorn/config.py", line 436, in load
    self.loaded_app = import_from_string(self.app)
                      ^^^^^^^^^^^^^^^^^^^^^^^^^^^^
  File "/home/alex/Downloads/new-pr/ai_env/lib/python3.12/site-packages/uvicorn/importer.py", line 19, in import_from_string
    module = importlib.import_module(module_str)
             ^^^^^^^^^^^^^^^^^^^^^^^^^^^^^^^^^^^
  File "/usr/lib/python3.12/importlib/__init__.py", line 90, in import_module
    return _bootstrap._gcd_import(name[level:], package, level)
           ^^^^^^^^^^^^^^^^^^^^^^^^^^^^^^^^^^^^^^^^^^^^^^^^^^^^
  File "<frozen importlib._bootstrap>", line 1387, in _gcd_import
  File "<frozen importlib._bootstrap>", line 1360, in _find_and_load
  File "<frozen importlib._bootstrap>", line 1331, in _find_and_load_unlocked
  File "<frozen importlib._bootstrap>", line 935, in _load_unlocked
  File "<frozen importlib._bootstrap_external>", line 995, in exec_module
  File "<frozen importlib._bootstrap>", line 488, in _call_with_frames_removed
  File "/home/alex/Downloads/new-pr/backend/app/main.py", line 22, in <module>
    from .config import settings
  File "/home/alex/Downloads/new-pr/backend/app/config.py", line 17, in <module>
    class Settings(BaseSettings):
  File "/home/alex/Downloads/new-pr/ai_env/lib/python3.12/site-packages/pydantic/_internal/_model_construction.py", line 110, in __new__
    config_wrapper = ConfigWrapper.for_model(bases, namespace, kwargs)
                     ^^^^^^^^^^^^^^^^^^^^^^^^^^^^^^^^^^^^^^^^^^^^^^^^^
  File "/home/alex/Downloads/new-pr/ai_env/lib/python3.12/site-packages/pydantic/_internal/_config.py", line 134, in for_model
    raise PydanticUserError('"Config" and "model_config" cannot be used together', code='config-both')
pydantic.errors.PydanticUserError: "Config" and "model_config" cannot be used together

For further information visit https://errors.pydantic.dev/2.11/u/config-both
INFO:     Will watch for changes in these directories: ['/home/alex/Downloads/new-pr/backend']
INFO:     Uvicorn running on http://127.0.0.1:8000 (Press CTRL+C to quit)
INFO:     Started reloader process [29216] using StatReload
Process SpawnProcess-1:
Traceback (most recent call last):
  File "/usr/lib/python3.12/multiprocessing/process.py", line 314, in _bootstrap
    self.run()
  File "/usr/lib/python3.12/multiprocessing/process.py", line 108, in run
    self._target(*self._args, **self._kwargs)
  File "/home/alex/Downloads/new-pr/ai_env/lib/python3.12/site-packages/uvicorn/_subprocess.py", line 80, in subprocess_started
    target(sockets=sockets)
  File "/home/alex/Downloads/new-pr/ai_env/lib/python3.12/site-packages/uvicorn/server.py", line 67, in run
    return asyncio.run(self.serve(sockets=sockets))
           ^^^^^^^^^^^^^^^^^^^^^^^^^^^^^^^^^^^^^^^^
  File "/usr/lib/python3.12/asyncio/runners.py", line 194, in run
    return runner.run(main)
           ^^^^^^^^^^^^^^^^
  File "/usr/lib/python3.12/asyncio/runners.py", line 118, in run
    return self._loop.run_until_complete(task)
           ^^^^^^^^^^^^^^^^^^^^^^^^^^^^^^^^^^^
  File "/usr/lib/python3.12/asyncio/base_events.py", line 687, in run_until_complete
    return future.result()
           ^^^^^^^^^^^^^^^
  File "/home/alex/Downloads/new-pr/ai_env/lib/python3.12/site-packages/uvicorn/server.py", line 71, in serve
    await self._serve(sockets)
  File "/home/alex/Downloads/new-pr/ai_env/lib/python3.12/site-packages/uvicorn/server.py", line 78, in _serve
    config.load()
  File "/home/alex/Downloads/new-pr/ai_env/lib/python3.12/site-packages/uvicorn/config.py", line 436, in load
    self.loaded_app = import_from_string(self.app)
                      ^^^^^^^^^^^^^^^^^^^^^^^^^^^^
  File "/home/alex/Downloads/new-pr/ai_env/lib/python3.12/site-packages/uvicorn/importer.py", line 19, in import_from_string
    module = importlib.import_module(module_str)
             ^^^^^^^^^^^^^^^^^^^^^^^^^^^^^^^^^^^
  File "/usr/lib/python3.12/importlib/__init__.py", line 90, in import_module
    return _bootstrap._gcd_import(name[level:], package, level)
           ^^^^^^^^^^^^^^^^^^^^^^^^^^^^^^^^^^^^^^^^^^^^^^^^^^^^
  File "<frozen importlib._bootstrap>", line 1387, in _gcd_import
  File "<frozen importlib._bootstrap>", line 1360, in _find_and_load
  File "<frozen importlib._bootstrap>", line 1331, in _find_and_load_unlocked
  File "<frozen importlib._bootstrap>", line 935, in _load_unlocked
  File "<frozen importlib._bootstrap_external>", line 995, in exec_module
  File "<frozen importlib._bootstrap>", line 488, in _call_with_frames_removed
  File "/home/alex/Downloads/new-pr/backend/app/main.py", line 22, in <module>
    from .config import settings
  File "/home/alex/Downloads/new-pr/backend/app/config.py", line 17, in <module>
    class Settings(BaseSettings):
  File "/home/alex/Downloads/new-pr/ai_env/lib/python3.12/site-packages/pydantic/_internal/_model_construction.py", line 110, in __new__
    config_wrapper = ConfigWrapper.for_model(bases, namespace, kwargs)
                     ^^^^^^^^^^^^^^^^^^^^^^^^^^^^^^^^^^^^^^^^^^^^^^^^^
  File "/home/alex/Downloads/new-pr/ai_env/lib/python3.12/site-packages/pydantic/_internal/_config.py", line 134, in for_model
    raise PydanticUserError('"Config" and "model_config" cannot be used together', code='config-both')
pydantic.errors.PydanticUserError: "Config" and "model_config" cannot be used together

For further information visit https://errors.pydantic.dev/2.11/u/config-both
WARNING:  StatReload detected changes in 'app/services/websocket_manager.py'. Reloading...
WARNING:  StatReload detected changes in 'app/services/websocket_manager.py'. Reloading...
Process SpawnProcess-2:
Traceback (most recent call last):
  File "/usr/lib/python3.12/multiprocessing/process.py", line 314, in _bootstrap
    self.run()
  File "/usr/lib/python3.12/multiprocessing/process.py", line 108, in run
    self._target(*self._args, **self._kwargs)
  File "/home/alex/Downloads/new-pr/ai_env/lib/python3.12/site-packages/uvicorn/_subprocess.py", line 80, in subprocess_started
    target(sockets=sockets)
  File "/home/alex/Downloads/new-pr/ai_env/lib/python3.12/site-packages/uvicorn/server.py", line 67, in run
    return asyncio.run(self.serve(sockets=sockets))
           ^^^^^^^^^^^^^^^^^^^^^^^^^^^^^^^^^^^^^^^^
  File "/usr/lib/python3.12/asyncio/runners.py", line 194, in run
    return runner.run(main)
           ^^^^^^^^^^^^^^^^
  File "/usr/lib/python3.12/asyncio/runners.py", line 118, in run
    return self._loop.run_until_complete(task)
           ^^^^^^^^^^^^^^^^^^^^^^^^^^^^^^^^^^^
  File "/usr/lib/python3.12/asyncio/base_events.py", line 687, in run_until_complete
    return future.result()
           ^^^^^^^^^^^^^^^
  File "/home/alex/Downloads/new-pr/ai_env/lib/python3.12/site-packages/uvicorn/server.py", line 71, in serve
    await self._serve(sockets)
  File "/home/alex/Downloads/new-pr/ai_env/lib/python3.12/site-packages/uvicorn/server.py", line 78, in _serve
    config.load()
  File "/home/alex/Downloads/new-pr/ai_env/lib/python3.12/site-packages/uvicorn/config.py", line 436, in load
    self.loaded_app = import_from_string(self.app)
                      ^^^^^^^^^^^^^^^^^^^^^^^^^^^^
  File "/home/alex/Downloads/new-pr/ai_env/lib/python3.12/site-packages/uvicorn/importer.py", line 19, in import_from_string
    module = importlib.import_module(module_str)
             ^^^^^^^^^^^^^^^^^^^^^^^^^^^^^^^^^^^
  File "/usr/lib/python3.12/importlib/__init__.py", line 90, in import_module
    return _bootstrap._gcd_import(name[level:], package, level)
           ^^^^^^^^^^^^^^^^^^^^^^^^^^^^^^^^^^^^^^^^^^^^^^^^^^^^
  File "<frozen importlib._bootstrap>", line 1387, in _gcd_import
  File "<frozen importlib._bootstrap>", line 1360, in _find_and_load
  File "<frozen importlib._bootstrap>", line 1331, in _find_and_load_unlocked
  File "<frozen importlib._bootstrap>", line 935, in _load_unlocked
  File "<frozen importlib._bootstrap_external>", line 995, in exec_module
  File "<frozen importlib._bootstrap>", line 488, in _call_with_frames_removed
  File "/home/alex/Downloads/new-pr/backend/app/main.py", line 22, in <module>
    from .config import settings
  File "/home/alex/Downloads/new-pr/backend/app/config.py", line 17, in <module>
    class Settings(BaseSettings):
  File "/home/alex/Downloads/new-pr/ai_env/lib/python3.12/site-packages/pydantic/_internal/_model_construction.py", line 110, in __new__
    config_wrapper = ConfigWrapper.for_model(bases, namespace, kwargs)
                     ^^^^^^^^^^^^^^^^^^^^^^^^^^^^^^^^^^^^^^^^^^^^^^^^^
  File "/home/alex/Downloads/new-pr/ai_env/lib/python3.12/site-packages/pydantic/_internal/_config.py", line 134, in for_model
    raise PydanticUserError('"Config" and "model_config" cannot be used together', code='config-both')
pydantic.errors.PydanticUserError: "Config" and "model_config" cannot be used together

For further information visit https://errors.pydantic.dev/2.11/u/config-both
Process SpawnProcess-2:
Traceback (most recent call last):
  File "/usr/lib/python3.12/multiprocessing/process.py", line 314, in _bootstrap
    self.run()
  File "/usr/lib/python3.12/multiprocessing/process.py", line 108, in run
    self._target(*self._args, **self._kwargs)
  File "/home/alex/Downloads/new-pr/ai_env/lib/python3.12/site-packages/uvicorn/_subprocess.py", line 80, in subprocess_started
    target(sockets=sockets)
  File "/home/alex/Downloads/new-pr/ai_env/lib/python3.12/site-packages/uvicorn/server.py", line 67, in run
    return asyncio.run(self.serve(sockets=sockets))
           ^^^^^^^^^^^^^^^^^^^^^^^^^^^^^^^^^^^^^^^^
  File "/usr/lib/python3.12/asyncio/runners.py", line 194, in run
    return runner.run(main)
           ^^^^^^^^^^^^^^^^
  File "/usr/lib/python3.12/asyncio/runners.py", line 118, in run
    return self._loop.run_until_complete(task)
           ^^^^^^^^^^^^^^^^^^^^^^^^^^^^^^^^^^^
  File "/usr/lib/python3.12/asyncio/base_events.py", line 687, in run_until_complete
    return future.result()
           ^^^^^^^^^^^^^^^
  File "/home/alex/Downloads/new-pr/ai_env/lib/python3.12/site-packages/uvicorn/server.py", line 71, in serve
    await self._serve(sockets)
  File "/home/alex/Downloads/new-pr/ai_env/lib/python3.12/site-packages/uvicorn/server.py", line 78, in _serve
    config.load()
  File "/home/alex/Downloads/new-pr/ai_env/lib/python3.12/site-packages/uvicorn/config.py", line 436, in load
    self.loaded_app = import_from_string(self.app)
                      ^^^^^^^^^^^^^^^^^^^^^^^^^^^^
  File "/home/alex/Downloads/new-pr/ai_env/lib/python3.12/site-packages/uvicorn/importer.py", line 19, in import_from_string
    module = importlib.import_module(module_str)
             ^^^^^^^^^^^^^^^^^^^^^^^^^^^^^^^^^^^
  File "/usr/lib/python3.12/importlib/__init__.py", line 90, in import_module
    return _bootstrap._gcd_import(name[level:], package, level)
           ^^^^^^^^^^^^^^^^^^^^^^^^^^^^^^^^^^^^^^^^^^^^^^^^^^^^
  File "<frozen importlib._bootstrap>", line 1387, in _gcd_import
  File "<frozen importlib._bootstrap>", line 1360, in _find_and_load
  File "<frozen importlib._bootstrap>", line 1331, in _find_and_load_unlocked
  File "<frozen importlib._bootstrap>", line 935, in _load_unlocked
  File "<frozen importlib._bootstrap_external>", line 995, in exec_module
  File "<frozen importlib._bootstrap>", line 488, in _call_with_frames_removed
  File "/home/alex/Downloads/new-pr/backend/app/main.py", line 22, in <module>
    from .config import settings
  File "/home/alex/Downloads/new-pr/backend/app/config.py", line 17, in <module>
    class Settings(BaseSettings):
  File "/home/alex/Downloads/new-pr/ai_env/lib/python3.12/site-packages/pydantic/_internal/_model_construction.py", line 110, in __new__
    config_wrapper = ConfigWrapper.for_model(bases, namespace, kwargs)
                     ^^^^^^^^^^^^^^^^^^^^^^^^^^^^^^^^^^^^^^^^^^^^^^^^^
  File "/home/alex/Downloads/new-pr/ai_env/lib/python3.12/site-packages/pydantic/_internal/_config.py", line 134, in for_model
    raise PydanticUserError('"Config" and "model_config" cannot be used together', code='config-both')
pydantic.errors.PydanticUserError: "Config" and "model_config" cannot be used together

For further information visit https://errors.pydantic.dev/2.11/u/config-both
INFO:     Will watch for changes in these directories: ['/home/alex/Downloads/new-pr/backend']
INFO:     Uvicorn running on http://127.0.0.1:8000 (Press CTRL+C to quit)
INFO:     Started reloader process [29938] using StatReload
Process SpawnProcess-1:
Traceback (most recent call last):
  File "/usr/lib/python3.12/multiprocessing/process.py", line 314, in _bootstrap
    self.run()
  File "/usr/lib/python3.12/multiprocessing/process.py", line 108, in run
    self._target(*self._args, **self._kwargs)
  File "/home/alex/Downloads/new-pr/ai_env/lib/python3.12/site-packages/uvicorn/_subprocess.py", line 80, in subprocess_started
    target(sockets=sockets)
  File "/home/alex/Downloads/new-pr/ai_env/lib/python3.12/site-packages/uvicorn/server.py", line 67, in run
    return asyncio.run(self.serve(sockets=sockets))
           ^^^^^^^^^^^^^^^^^^^^^^^^^^^^^^^^^^^^^^^^
  File "/usr/lib/python3.12/asyncio/runners.py", line 194, in run
    return runner.run(main)
           ^^^^^^^^^^^^^^^^
  File "/usr/lib/python3.12/asyncio/runners.py", line 118, in run
    return self._loop.run_until_complete(task)
           ^^^^^^^^^^^^^^^^^^^^^^^^^^^^^^^^^^^
  File "/usr/lib/python3.12/asyncio/base_events.py", line 687, in run_until_complete
    return future.result()
           ^^^^^^^^^^^^^^^
  File "/home/alex/Downloads/new-pr/ai_env/lib/python3.12/site-packages/uvicorn/server.py", line 71, in serve
    await self._serve(sockets)
  File "/home/alex/Downloads/new-pr/ai_env/lib/python3.12/site-packages/uvicorn/server.py", line 78, in _serve
    config.load()
  File "/home/alex/Downloads/new-pr/ai_env/lib/python3.12/site-packages/uvicorn/config.py", line 436, in load
    self.loaded_app = import_from_string(self.app)
                      ^^^^^^^^^^^^^^^^^^^^^^^^^^^^
  File "/home/alex/Downloads/new-pr/ai_env/lib/python3.12/site-packages/uvicorn/importer.py", line 19, in import_from_string
    module = importlib.import_module(module_str)
             ^^^^^^^^^^^^^^^^^^^^^^^^^^^^^^^^^^^
  File "/usr/lib/python3.12/importlib/__init__.py", line 90, in import_module
    return _bootstrap._gcd_import(name[level:], package, level)
           ^^^^^^^^^^^^^^^^^^^^^^^^^^^^^^^^^^^^^^^^^^^^^^^^^^^^
  File "<frozen importlib._bootstrap>", line 1387, in _gcd_import
  File "<frozen importlib._bootstrap>", line 1360, in _find_and_load
  File "<frozen importlib._bootstrap>", line 1331, in _find_and_load_unlocked
  File "<frozen importlib._bootstrap>", line 935, in _load_unlocked
  File "<frozen importlib._bootstrap_external>", line 995, in exec_module
  File "<frozen importlib._bootstrap>", line 488, in _call_with_frames_removed
  File "/home/alex/Downloads/new-pr/backend/app/main.py", line 22, in <module>
    from .config import settings
  File "/home/alex/Downloads/new-pr/backend/app/config.py", line 17, in <module>
    class Settings(BaseSettings):
  File "/home/alex/Downloads/new-pr/ai_env/lib/python3.12/site-packages/pydantic/_internal/_model_construction.py", line 110, in __new__
    config_wrapper = ConfigWrapper.for_model(bases, namespace, kwargs)
                     ^^^^^^^^^^^^^^^^^^^^^^^^^^^^^^^^^^^^^^^^^^^^^^^^^
  File "/home/alex/Downloads/new-pr/ai_env/lib/python3.12/site-packages/pydantic/_internal/_config.py", line 134, in for_model
    raise PydanticUserError('"Config" and "model_config" cannot be used together', code='config-both')
pydantic.errors.PydanticUserError: "Config" and "model_config" cannot be used together

For further information visit https://errors.pydantic.dev/2.11/u/config-both
WARNING:  StatReload detected changes in 'app/config.py'. Reloading...
WARNING:  StatReload detected changes in 'app/config.py'. Reloading...
WARNING:  StatReload detected changes in 'app/config.py'. Reloading...
ElevenLabs API ключ не установлен
ElevenLabs API ключ не установлен
ElevenLabs API ключ не установлен
WARNING:  StatReload detected changes in 'app/services/websocket_manager.py'. Reloading...
WARNING:  StatReload detected changes in 'app/services/websocket_manager.py'. Reloading...
WARNING:  StatReload detected changes in 'app/services/websocket_manager.py'. Reloading...
INFO:     Started server process [30542]
INFO:     Waiting for application startup.
INFO:     Started server process [30543]
INFO:     Waiting for application startup.
INFO:     Started server process [30544]
INFO:     Waiting for application startup.
INFO:     Application startup complete.
INFO:     Application startup complete.
ERROR:    Traceback (most recent call last):
  File "/usr/lib/python3.12/asyncio/runners.py", line 194, in run
    return runner.run(main)
           ^^^^^^^^^^^^^^^^
  File "/usr/lib/python3.12/asyncio/runners.py", line 118, in run
    return self._loop.run_until_complete(task)
           ^^^^^^^^^^^^^^^^^^^^^^^^^^^^^^^^^^^
  File "/usr/lib/python3.12/asyncio/base_events.py", line 687, in run_until_complete
    return future.result()
           ^^^^^^^^^^^^^^^
  File "/home/alex/Downloads/new-pr/ai_env/lib/python3.12/site-packages/uvicorn/server.py", line 71, in serve
    await self._serve(sockets)
  File "/home/alex/Downloads/new-pr/ai_env/lib/python3.12/site-packages/uvicorn/server.py", line 86, in _serve
    await self.startup(sockets=sockets)
  File "/home/alex/Downloads/new-pr/ai_env/lib/python3.12/site-packages/uvicorn/server.py", line 136, in startup
    server = await loop.create_server(create_protocol, sock=sock, ssl=config.ssl, backlog=config.backlog)
             ^^^^^^^^^^^^^^^^^^^^^^^^^^^^^^^^^^^^^^^^^^^^^^^^^^^^^^^^^^^^^^^^^^^^^^^^^^^^^^^^^^^^^^^^^^^^
  File "/usr/lib/python3.12/asyncio/base_events.py", line 1597, in create_server
    server._start_serving()
  File "/usr/lib/python3.12/asyncio/base_events.py", line 317, in _start_serving
    sock.listen(self._backlog)
OSError: [Errno 98] Address already in use

During handling of the above exception, another exception occurred:

Traceback (most recent call last):
  File "/home/alex/Downloads/new-pr/ai_env/lib/python3.12/site-packages/starlette/routing.py", line 701, in lifespan
    await receive()
  File "/home/alex/Downloads/new-pr/ai_env/lib/python3.12/site-packages/uvicorn/lifespan/on.py", line 137, in receive
    return await self.receive_queue.get()
           ^^^^^^^^^^^^^^^^^^^^^^^^^^^^^^
  File "/usr/lib/python3.12/asyncio/queues.py", line 158, in get
    await getter
asyncio.exceptions.CancelledError

Process SpawnProcess-3:
Traceback (most recent call last):
  File "/usr/lib/python3.12/multiprocessing/process.py", line 314, in _bootstrap
    self.run()
  File "/usr/lib/python3.12/multiprocessing/process.py", line 108, in run
    self._target(*self._args, **self._kwargs)
  File "/home/alex/Downloads/new-pr/ai_env/lib/python3.12/site-packages/uvicorn/_subprocess.py", line 80, in subprocess_started
    target(sockets=sockets)
  File "/home/alex/Downloads/new-pr/ai_env/lib/python3.12/site-packages/uvicorn/server.py", line 67, in run
    return asyncio.run(self.serve(sockets=sockets))
           ^^^^^^^^^^^^^^^^^^^^^^^^^^^^^^^^^^^^^^^^
  File "/usr/lib/python3.12/asyncio/runners.py", line 194, in run
    return runner.run(main)
           ^^^^^^^^^^^^^^^^
  File "/usr/lib/python3.12/asyncio/runners.py", line 118, in run
    return self._loop.run_until_complete(task)
           ^^^^^^^^^^^^^^^^^^^^^^^^^^^^^^^^^^^
  File "/usr/lib/python3.12/asyncio/base_events.py", line 687, in run_until_complete
    return future.result()
           ^^^^^^^^^^^^^^^
  File "/home/alex/Downloads/new-pr/ai_env/lib/python3.12/site-packages/uvicorn/server.py", line 71, in serve
    await self._serve(sockets)
  File "/home/alex/Downloads/new-pr/ai_env/lib/python3.12/site-packages/uvicorn/server.py", line 86, in _serve
    await self.startup(sockets=sockets)
  File "/home/alex/Downloads/new-pr/ai_env/lib/python3.12/site-packages/uvicorn/server.py", line 136, in startup
    server = await loop.create_server(create_protocol, sock=sock, ssl=config.ssl, backlog=config.backlog)
             ^^^^^^^^^^^^^^^^^^^^^^^^^^^^^^^^^^^^^^^^^^^^^^^^^^^^^^^^^^^^^^^^^^^^^^^^^^^^^^^^^^^^^^^^^^^^
  File "/usr/lib/python3.12/asyncio/base_events.py", line 1597, in create_server
    server._start_serving()
  File "/usr/lib/python3.12/asyncio/base_events.py", line 317, in _start_serving
    sock.listen(self._backlog)
OSError: [Errno 98] Address already in use
INFO:     Application startup complete.
ERROR:    Traceback (most recent call last):
  File "/usr/lib/python3.12/asyncio/runners.py", line 194, in run
    return runner.run(main)
           ^^^^^^^^^^^^^^^^
  File "/usr/lib/python3.12/asyncio/runners.py", line 118, in run
    return self._loop.run_until_complete(task)
           ^^^^^^^^^^^^^^^^^^^^^^^^^^^^^^^^^^^
  File "/usr/lib/python3.12/asyncio/base_events.py", line 687, in run_until_complete
    return future.result()
           ^^^^^^^^^^^^^^^
  File "/home/alex/Downloads/new-pr/ai_env/lib/python3.12/site-packages/uvicorn/server.py", line 71, in serve
    await self._serve(sockets)
  File "/home/alex/Downloads/new-pr/ai_env/lib/python3.12/site-packages/uvicorn/server.py", line 86, in _serve
    await self.startup(sockets=sockets)
  File "/home/alex/Downloads/new-pr/ai_env/lib/python3.12/site-packages/uvicorn/server.py", line 136, in startup
    server = await loop.create_server(create_protocol, sock=sock, ssl=config.ssl, backlog=config.backlog)
             ^^^^^^^^^^^^^^^^^^^^^^^^^^^^^^^^^^^^^^^^^^^^^^^^^^^^^^^^^^^^^^^^^^^^^^^^^^^^^^^^^^^^^^^^^^^^
  File "/usr/lib/python3.12/asyncio/base_events.py", line 1597, in create_server
    server._start_serving()
  File "/usr/lib/python3.12/asyncio/base_events.py", line 317, in _start_serving
    sock.listen(self._backlog)
OSError: [Errno 98] Address already in use

During handling of the above exception, another exception occurred:

Traceback (most recent call last):
  File "/home/alex/Downloads/new-pr/ai_env/lib/python3.12/site-packages/starlette/routing.py", line 701, in lifespan
    await receive()
  File "/home/alex/Downloads/new-pr/ai_env/lib/python3.12/site-packages/uvicorn/lifespan/on.py", line 137, in receive
    return await self.receive_queue.get()
           ^^^^^^^^^^^^^^^^^^^^^^^^^^^^^^
  File "/usr/lib/python3.12/asyncio/queues.py", line 158, in get
    await getter
asyncio.exceptions.CancelledError

Process SpawnProcess-2:
Traceback (most recent call last):
  File "/usr/lib/python3.12/multiprocessing/process.py", line 314, in _bootstrap
    self.run()
  File "/usr/lib/python3.12/multiprocessing/process.py", line 108, in run
    self._target(*self._args, **self._kwargs)
  File "/home/alex/Downloads/new-pr/ai_env/lib/python3.12/site-packages/uvicorn/_subprocess.py", line 80, in subprocess_started
    target(sockets=sockets)
  File "/home/alex/Downloads/new-pr/ai_env/lib/python3.12/site-packages/uvicorn/server.py", line 67, in run
    return asyncio.run(self.serve(sockets=sockets))
           ^^^^^^^^^^^^^^^^^^^^^^^^^^^^^^^^^^^^^^^^
  File "/usr/lib/python3.12/asyncio/runners.py", line 194, in run
    return runner.run(main)
           ^^^^^^^^^^^^^^^^
  File "/usr/lib/python3.12/asyncio/runners.py", line 118, in run
    return self._loop.run_until_complete(task)
           ^^^^^^^^^^^^^^^^^^^^^^^^^^^^^^^^^^^
  File "/usr/lib/python3.12/asyncio/base_events.py", line 687, in run_until_complete
    return future.result()
           ^^^^^^^^^^^^^^^
  File "/home/alex/Downloads/new-pr/ai_env/lib/python3.12/site-packages/uvicorn/server.py", line 71, in serve
    await self._serve(sockets)
  File "/home/alex/Downloads/new-pr/ai_env/lib/python3.12/site-packages/uvicorn/server.py", line 86, in _serve
    await self.startup(sockets=sockets)
  File "/home/alex/Downloads/new-pr/ai_env/lib/python3.12/site-packages/uvicorn/server.py", line 136, in startup
    server = await loop.create_server(create_protocol, sock=sock, ssl=config.ssl, backlog=config.backlog)
             ^^^^^^^^^^^^^^^^^^^^^^^^^^^^^^^^^^^^^^^^^^^^^^^^^^^^^^^^^^^^^^^^^^^^^^^^^^^^^^^^^^^^^^^^^^^^
  File "/usr/lib/python3.12/asyncio/base_events.py", line 1597, in create_server
    server._start_serving()
  File "/usr/lib/python3.12/asyncio/base_events.py", line 317, in _start_serving
    sock.listen(self._backlog)
OSError: [Errno 98] Address already in use
ElevenLabs API ключ не установлен
ElevenLabs API ключ не установлен
ElevenLabs API ключ не установлен
INFO:     Started server process [30646]
INFO:     Waiting for application startup.
INFO:     Application startup complete.
INFO:     127.0.0.1:55510 - "WebSocket /ws" [accepted]
ERROR:    Exception in ASGI application
Traceback (most recent call last):
  File "/home/alex/Downloads/new-pr/ai_env/lib/python3.12/site-packages/uvicorn/protocols/websockets/websockets_impl.py", line 244, in run_asgi
    result = await self.app(self.scope, self.asgi_receive, self.asgi_send)  # type: ignore[func-returns-value]
             ^^^^^^^^^^^^^^^^^^^^^^^^^^^^^^^^^^^^^^^^^^^^^^^^^^^^^^^^^^^^^
  File "/home/alex/Downloads/new-pr/ai_env/lib/python3.12/site-packages/uvicorn/middleware/proxy_headers.py", line 60, in __call__
    return await self.app(scope, receive, send)
           ^^^^^^^^^^^^^^^^^^^^^^^^^^^^^^^^^^^^
  File "/home/alex/Downloads/new-pr/ai_env/lib/python3.12/site-packages/fastapi/applications.py", line 1054, in __call__
    await super().__call__(scope, receive, send)
  File "/home/alex/Downloads/new-pr/ai_env/lib/python3.12/site-packages/starlette/applications.py", line 113, in __call__
    await self.middleware_stack(scope, receive, send)
  File "/home/alex/Downloads/new-pr/ai_env/lib/python3.12/site-packages/starlette/middleware/errors.py", line 151, in __call__
    await self.app(scope, receive, send)
  File "/home/alex/Downloads/new-pr/ai_env/lib/python3.12/site-packages/starlette/middleware/trustedhost.py", line 36, in __call__
    await self.app(scope, receive, send)
  File "/home/alex/Downloads/new-pr/ai_env/lib/python3.12/site-packages/starlette/middleware/cors.py", line 77, in __call__
    await self.app(scope, receive, send)
  File "/home/alex/Downloads/new-pr/ai_env/lib/python3.12/site-packages/starlette/middleware/exceptions.py", line 63, in __call__
    await wrap_app_handling_exceptions(self.app, conn)(scope, receive, send)
  File "/home/alex/Downloads/new-pr/ai_env/lib/python3.12/site-packages/starlette/_exception_handler.py", line 53, in wrapped_app
    raise exc
  File "/home/alex/Downloads/new-pr/ai_env/lib/python3.12/site-packages/starlette/_exception_handler.py", line 42, in wrapped_app
    await app(scope, receive, sender)
  File "/home/alex/Downloads/new-pr/ai_env/lib/python3.12/site-packages/starlette/routing.py", line 716, in __call__
    await self.middleware_stack(scope, receive, send)
  File "/home/alex/Downloads/new-pr/ai_env/lib/python3.12/site-packages/starlette/routing.py", line 736, in app
    await route.handle(scope, receive, send)
  File "/home/alex/Downloads/new-pr/ai_env/lib/python3.12/site-packages/starlette/routing.py", line 364, in handle
    await self.app(scope, receive, send)
  File "/home/alex/Downloads/new-pr/ai_env/lib/python3.12/site-packages/starlette/routing.py", line 97, in app
    await wrap_app_handling_exceptions(app, session)(scope, receive, send)
  File "/home/alex/Downloads/new-pr/ai_env/lib/python3.12/site-packages/starlette/_exception_handler.py", line 53, in wrapped_app
    raise exc
  File "/home/alex/Downloads/new-pr/ai_env/lib/python3.12/site-packages/starlette/_exception_handler.py", line 42, in wrapped_app
    await app(scope, receive, sender)
  File "/home/alex/Downloads/new-pr/ai_env/lib/python3.12/site-packages/starlette/routing.py", line 95, in app
    await func(session)
  File "/home/alex/Downloads/new-pr/ai_env/lib/python3.12/site-packages/fastapi/routing.py", line 384, in app
    await dependant.call(**solved_result.values)
  File "/home/alex/Downloads/new-pr/backend/app/main.py", line 222, in simple_websocket_endpoint
    await websocket_manager.connect(websocket, client_id)
  File "/home/alex/Downloads/new-pr/backend/app/services/websocket_manager.py", line 40, in connect
    logger.info("Клиент подключен", client_id=client_id)
    ^^^^^^
NameError: name 'logger' is not defined
INFO:     connection open
INFO:     connection closed
INFO:     Started server process [30671]
INFO:     Waiting for application startup.
INFO:     Application startup complete.
ERROR:    Traceback (most recent call last):
  File "/usr/lib/python3.12/asyncio/runners.py", line 194, in run
    return runner.run(main)
           ^^^^^^^^^^^^^^^^
  File "/usr/lib/python3.12/asyncio/runners.py", line 118, in run
    return self._loop.run_until_complete(task)
           ^^^^^^^^^^^^^^^^^^^^^^^^^^^^^^^^^^^
  File "/usr/lib/python3.12/asyncio/base_events.py", line 687, in run_until_complete
    return future.result()
           ^^^^^^^^^^^^^^^
  File "/home/alex/Downloads/new-pr/ai_env/lib/python3.12/site-packages/uvicorn/server.py", line 71, in serve
    await self._serve(sockets)
  File "/home/alex/Downloads/new-pr/ai_env/lib/python3.12/site-packages/uvicorn/server.py", line 86, in _serve
    await self.startup(sockets=sockets)
  File "/home/alex/Downloads/new-pr/ai_env/lib/python3.12/site-packages/uvicorn/server.py", line 136, in startup
    server = await loop.create_server(create_protocol, sock=sock, ssl=config.ssl, backlog=config.backlog)
             ^^^^^^^^^^^^^^^^^^^^^^^^^^^^^^^^^^^^^^^^^^^^^^^^^^^^^^^^^^^^^^^^^^^^^^^^^^^^^^^^^^^^^^^^^^^^
  File "/usr/lib/python3.12/asyncio/base_events.py", line 1597, in create_server
    server._start_serving()
  File "/usr/lib/python3.12/asyncio/base_events.py", line 317, in _start_serving
    sock.listen(self._backlog)
OSError: [Errno 98] Address already in use

During handling of the above exception, another exception occurred:

Traceback (most recent call last):
  File "/home/alex/Downloads/new-pr/ai_env/lib/python3.12/site-packages/starlette/routing.py", line 701, in lifespan
    await receive()
  File "/home/alex/Downloads/new-pr/ai_env/lib/python3.12/site-packages/uvicorn/lifespan/on.py", line 137, in receive
    return await self.receive_queue.get()
           ^^^^^^^^^^^^^^^^^^^^^^^^^^^^^^
  File "/usr/lib/python3.12/asyncio/queues.py", line 158, in get
    await getter
asyncio.exceptions.CancelledError

Process SpawnProcess-3:
Traceback (most recent call last):
  File "/usr/lib/python3.12/multiprocessing/process.py", line 314, in _bootstrap
    self.run()
  File "/usr/lib/python3.12/multiprocessing/process.py", line 108, in run
    self._target(*self._args, **self._kwargs)
  File "/home/alex/Downloads/new-pr/ai_env/lib/python3.12/site-packages/uvicorn/_subprocess.py", line 80, in subprocess_started
    target(sockets=sockets)
  File "/home/alex/Downloads/new-pr/ai_env/lib/python3.12/site-packages/uvicorn/server.py", line 67, in run
    return asyncio.run(self.serve(sockets=sockets))
           ^^^^^^^^^^^^^^^^^^^^^^^^^^^^^^^^^^^^^^^^
  File "/usr/lib/python3.12/asyncio/runners.py", line 194, in run
    return runner.run(main)
           ^^^^^^^^^^^^^^^^
  File "/usr/lib/python3.12/asyncio/runners.py", line 118, in run
    return self._loop.run_until_complete(task)
           ^^^^^^^^^^^^^^^^^^^^^^^^^^^^^^^^^^^
  File "/usr/lib/python3.12/asyncio/base_events.py", line 687, in run_until_complete
    return future.result()
           ^^^^^^^^^^^^^^^
  File "/home/alex/Downloads/new-pr/ai_env/lib/python3.12/site-packages/uvicorn/server.py", line 71, in serve
    await self._serve(sockets)
  File "/home/alex/Downloads/new-pr/ai_env/lib/python3.12/site-packages/uvicorn/server.py", line 86, in _serve
    await self.startup(sockets=sockets)
  File "/home/alex/Downloads/new-pr/ai_env/lib/python3.12/site-packages/uvicorn/server.py", line 136, in startup
    server = await loop.create_server(create_protocol, sock=sock, ssl=config.ssl, backlog=config.backlog)
             ^^^^^^^^^^^^^^^^^^^^^^^^^^^^^^^^^^^^^^^^^^^^^^^^^^^^^^^^^^^^^^^^^^^^^^^^^^^^^^^^^^^^^^^^^^^^
  File "/usr/lib/python3.12/asyncio/base_events.py", line 1597, in create_server
    server._start_serving()
  File "/usr/lib/python3.12/asyncio/base_events.py", line 317, in _start_serving
    sock.listen(self._backlog)
OSError: [Errno 98] Address already in use
INFO:     Started server process [30670]
INFO:     Waiting for application startup.
INFO:     Application startup complete.
ERROR:    Traceback (most recent call last):
  File "/usr/lib/python3.12/asyncio/runners.py", line 194, in run
    return runner.run(main)
           ^^^^^^^^^^^^^^^^
  File "/usr/lib/python3.12/asyncio/runners.py", line 118, in run
    return self._loop.run_until_complete(task)
           ^^^^^^^^^^^^^^^^^^^^^^^^^^^^^^^^^^^
  File "/usr/lib/python3.12/asyncio/base_events.py", line 687, in run_until_complete
    return future.result()
           ^^^^^^^^^^^^^^^
  File "/home/alex/Downloads/new-pr/ai_env/lib/python3.12/site-packages/uvicorn/server.py", line 71, in serve
    await self._serve(sockets)
  File "/home/alex/Downloads/new-pr/ai_env/lib/python3.12/site-packages/uvicorn/server.py", line 86, in _serve
    await self.startup(sockets=sockets)
  File "/home/alex/Downloads/new-pr/ai_env/lib/python3.12/site-packages/uvicorn/server.py", line 136, in startup
    server = await loop.create_server(create_protocol, sock=sock, ssl=config.ssl, backlog=config.backlog)
             ^^^^^^^^^^^^^^^^^^^^^^^^^^^^^^^^^^^^^^^^^^^^^^^^^^^^^^^^^^^^^^^^^^^^^^^^^^^^^^^^^^^^^^^^^^^^
  File "/usr/lib/python3.12/asyncio/base_events.py", line 1597, in create_server
    server._start_serving()
  File "/usr/lib/python3.12/asyncio/base_events.py", line 317, in _start_serving
    sock.listen(self._backlog)
OSError: [Errno 98] Address already in use

During handling of the above exception, another exception occurred:

Traceback (most recent call last):
  File "/home/alex/Downloads/new-pr/ai_env/lib/python3.12/site-packages/starlette/routing.py", line 701, in lifespan
    await receive()
  File "/home/alex/Downloads/new-pr/ai_env/lib/python3.12/site-packages/uvicorn/lifespan/on.py", line 137, in receive
    return await self.receive_queue.get()
           ^^^^^^^^^^^^^^^^^^^^^^^^^^^^^^
  File "/usr/lib/python3.12/asyncio/queues.py", line 158, in get
    await getter
asyncio.exceptions.CancelledError

Process SpawnProcess-4:
Traceback (most recent call last):
  File "/usr/lib/python3.12/multiprocessing/process.py", line 314, in _bootstrap
    self.run()
  File "/usr/lib/python3.12/multiprocessing/process.py", line 108, in run
    self._target(*self._args, **self._kwargs)
  File "/home/alex/Downloads/new-pr/ai_env/lib/python3.12/site-packages/uvicorn/_subprocess.py", line 80, in subprocess_started
    target(sockets=sockets)
  File "/home/alex/Downloads/new-pr/ai_env/lib/python3.12/site-packages/uvicorn/server.py", line 67, in run
    return asyncio.run(self.serve(sockets=sockets))
           ^^^^^^^^^^^^^^^^^^^^^^^^^^^^^^^^^^^^^^^^
  File "/usr/lib/python3.12/asyncio/runners.py", line 194, in run
    return runner.run(main)
           ^^^^^^^^^^^^^^^^
  File "/usr/lib/python3.12/asyncio/runners.py", line 118, in run
    return self._loop.run_until_complete(task)
           ^^^^^^^^^^^^^^^^^^^^^^^^^^^^^^^^^^^
  File "/usr/lib/python3.12/asyncio/base_events.py", line 687, in run_until_complete
    return future.result()
           ^^^^^^^^^^^^^^^
  File "/home/alex/Downloads/new-pr/ai_env/lib/python3.12/site-packages/uvicorn/server.py", line 71, in serve
    await self._serve(sockets)
  File "/home/alex/Downloads/new-pr/ai_env/lib/python3.12/site-packages/uvicorn/server.py", line 86, in _serve
    await self.startup(sockets=sockets)
  File "/home/alex/Downloads/new-pr/ai_env/lib/python3.12/site-packages/uvicorn/server.py", line 136, in startup
    server = await loop.create_server(create_protocol, sock=sock, ssl=config.ssl, backlog=config.backlog)
             ^^^^^^^^^^^^^^^^^^^^^^^^^^^^^^^^^^^^^^^^^^^^^^^^^^^^^^^^^^^^^^^^^^^^^^^^^^^^^^^^^^^^^^^^^^^^
  File "/usr/lib/python3.12/asyncio/base_events.py", line 1597, in create_server
    server._start_serving()
  File "/usr/lib/python3.12/asyncio/base_events.py", line 317, in _start_serving
    sock.listen(self._backlog)
OSError: [Errno 98] Address already in use
INFO:     127.0.0.1:55514 - "WebSocket /ws" [accepted]
ERROR:    Exception in ASGI application
Traceback (most recent call last):
  File "/home/alex/Downloads/new-pr/ai_env/lib/python3.12/site-packages/uvicorn/protocols/websockets/websockets_impl.py", line 244, in run_asgi
    result = await self.app(self.scope, self.asgi_receive, self.asgi_send)  # type: ignore[func-returns-value]
             ^^^^^^^^^^^^^^^^^^^^^^^^^^^^^^^^^^^^^^^^^^^^^^^^^^^^^^^^^^^^^
  File "/home/alex/Downloads/new-pr/ai_env/lib/python3.12/site-packages/uvicorn/middleware/proxy_headers.py", line 60, in __call__
    return await self.app(scope, receive, send)
           ^^^^^^^^^^^^^^^^^^^^^^^^^^^^^^^^^^^^
  File "/home/alex/Downloads/new-pr/ai_env/lib/python3.12/site-packages/fastapi/applications.py", line 1054, in __call__
    await super().__call__(scope, receive, send)
  File "/home/alex/Downloads/new-pr/ai_env/lib/python3.12/site-packages/starlette/applications.py", line 113, in __call__
    await self.middleware_stack(scope, receive, send)
  File "/home/alex/Downloads/new-pr/ai_env/lib/python3.12/site-packages/starlette/middleware/errors.py", line 151, in __call__
    await self.app(scope, receive, send)
  File "/home/alex/Downloads/new-pr/ai_env/lib/python3.12/site-packages/starlette/middleware/trustedhost.py", line 36, in __call__
    await self.app(scope, receive, send)
  File "/home/alex/Downloads/new-pr/ai_env/lib/python3.12/site-packages/starlette/middleware/cors.py", line 77, in __call__
    await self.app(scope, receive, send)
  File "/home/alex/Downloads/new-pr/ai_env/lib/python3.12/site-packages/starlette/middleware/exceptions.py", line 63, in __call__
    await wrap_app_handling_exceptions(self.app, conn)(scope, receive, send)
  File "/home/alex/Downloads/new-pr/ai_env/lib/python3.12/site-packages/starlette/_exception_handler.py", line 53, in wrapped_app
    raise exc
  File "/home/alex/Downloads/new-pr/ai_env/lib/python3.12/site-packages/starlette/_exception_handler.py", line 42, in wrapped_app
    await app(scope, receive, sender)
  File "/home/alex/Downloads/new-pr/ai_env/lib/python3.12/site-packages/starlette/routing.py", line 716, in __call__
    await self.middleware_stack(scope, receive, send)
  File "/home/alex/Downloads/new-pr/ai_env/lib/python3.12/site-packages/starlette/routing.py", line 736, in app
    await route.handle(scope, receive, send)
  File "/home/alex/Downloads/new-pr/ai_env/lib/python3.12/site-packages/starlette/routing.py", line 364, in handle
    await self.app(scope, receive, send)
  File "/home/alex/Downloads/new-pr/ai_env/lib/python3.12/site-packages/starlette/routing.py", line 97, in app
    await wrap_app_handling_exceptions(app, session)(scope, receive, send)
  File "/home/alex/Downloads/new-pr/ai_env/lib/python3.12/site-packages/starlette/_exception_handler.py", line 53, in wrapped_app
    raise exc
  File "/home/alex/Downloads/new-pr/ai_env/lib/python3.12/site-packages/starlette/_exception_handler.py", line 42, in wrapped_app
    await app(scope, receive, sender)
  File "/home/alex/Downloads/new-pr/ai_env/lib/python3.12/site-packages/starlette/routing.py", line 95, in app
    await func(session)
  File "/home/alex/Downloads/new-pr/ai_env/lib/python3.12/site-packages/fastapi/routing.py", line 384, in app
    await dependant.call(**solved_result.values)
  File "/home/alex/Downloads/new-pr/backend/app/main.py", line 222, in simple_websocket_endpoint
    await websocket_manager.connect(websocket, client_id)
  File "/home/alex/Downloads/new-pr/backend/app/services/websocket_manager.py", line 40, in connect
    logger.info("Клиент подключен", client_id=client_id)
    ^^^^^^
NameError: name 'logger' is not defined
INFO:     connection open
INFO:     connection closed
INFO:     127.0.0.1:55522 - "WebSocket /ws" [accepted]
ERROR:    Exception in ASGI application
Traceback (most recent call last):
  File "/home/alex/Downloads/new-pr/ai_env/lib/python3.12/site-packages/uvicorn/protocols/websockets/websockets_impl.py", line 244, in run_asgi
    result = await self.app(self.scope, self.asgi_receive, self.asgi_send)  # type: ignore[func-returns-value]
             ^^^^^^^^^^^^^^^^^^^^^^^^^^^^^^^^^^^^^^^^^^^^^^^^^^^^^^^^^^^^^
  File "/home/alex/Downloads/new-pr/ai_env/lib/python3.12/site-packages/uvicorn/middleware/proxy_headers.py", line 60, in __call__
    return await self.app(scope, receive, send)
           ^^^^^^^^^^^^^^^^^^^^^^^^^^^^^^^^^^^^
  File "/home/alex/Downloads/new-pr/ai_env/lib/python3.12/site-packages/fastapi/applications.py", line 1054, in __call__
    await super().__call__(scope, receive, send)
  File "/home/alex/Downloads/new-pr/ai_env/lib/python3.12/site-packages/starlette/applications.py", line 113, in __call__
    await self.middleware_stack(scope, receive, send)
  File "/home/alex/Downloads/new-pr/ai_env/lib/python3.12/site-packages/starlette/middleware/errors.py", line 151, in __call__
    await self.app(scope, receive, send)
  File "/home/alex/Downloads/new-pr/ai_env/lib/python3.12/site-packages/starlette/middleware/trustedhost.py", line 36, in __call__
    await self.app(scope, receive, send)
  File "/home/alex/Downloads/new-pr/ai_env/lib/python3.12/site-packages/starlette/middleware/cors.py", line 77, in __call__
    await self.app(scope, receive, send)
  File "/home/alex/Downloads/new-pr/ai_env/lib/python3.12/site-packages/starlette/middleware/exceptions.py", line 63, in __call__
    await wrap_app_handling_exceptions(self.app, conn)(scope, receive, send)
  File "/home/alex/Downloads/new-pr/ai_env/lib/python3.12/site-packages/starlette/_exception_handler.py", line 53, in wrapped_app
    raise exc
  File "/home/alex/Downloads/new-pr/ai_env/lib/python3.12/site-packages/starlette/_exception_handler.py", line 42, in wrapped_app
    await app(scope, receive, sender)
  File "/home/alex/Downloads/new-pr/ai_env/lib/python3.12/site-packages/starlette/routing.py", line 716, in __call__
    await self.middleware_stack(scope, receive, send)
  File "/home/alex/Downloads/new-pr/ai_env/lib/python3.12/site-packages/starlette/routing.py", line 736, in app
    await route.handle(scope, receive, send)
  File "/home/alex/Downloads/new-pr/ai_env/lib/python3.12/site-packages/starlette/routing.py", line 364, in handle
    await self.app(scope, receive, send)
  File "/home/alex/Downloads/new-pr/ai_env/lib/python3.12/site-packages/starlette/routing.py", line 97, in app
    await wrap_app_handling_exceptions(app, session)(scope, receive, send)
  File "/home/alex/Downloads/new-pr/ai_env/lib/python3.12/site-packages/starlette/_exception_handler.py", line 53, in wrapped_app
    raise exc
  File "/home/alex/Downloads/new-pr/ai_env/lib/python3.12/site-packages/starlette/_exception_handler.py", line 42, in wrapped_app
    await app(scope, receive, sender)
  File "/home/alex/Downloads/new-pr/ai_env/lib/python3.12/site-packages/starlette/routing.py", line 95, in app
    await func(session)
  File "/home/alex/Downloads/new-pr/ai_env/lib/python3.12/site-packages/fastapi/routing.py", line 384, in app
    await dependant.call(**solved_result.values)
  File "/home/alex/Downloads/new-pr/backend/app/main.py", line 222, in simple_websocket_endpoint
    await websocket_manager.connect(websocket, client_id)
  File "/home/alex/Downloads/new-pr/backend/app/services/websocket_manager.py", line 40, in connect
    logger.info("Клиент подключен", client_id=client_id)
    ^^^^^^
NameError: name 'logger' is not defined
INFO:     connection open
INFO:     connection closed
INFO:     127.0.0.1:47670 - "GET /health HTTP/1.1" 200 OK
INFO:     127.0.0.1:47674 - "GET /health HTTP/1.1" 200 OK
WARNING:  StatReload detected changes in 'app/services/websocket_manager.py'. Reloading...
INFO:     127.0.0.1:47670 - "GET /health HTTP/1.1" 200 OK
WARNING:  StatReload detected changes in 'app/services/websocket_manager.py'. Reloading...
INFO:     Shutting down
WARNING:  StatReload detected changes in 'app/services/websocket_manager.py'. Reloading...
INFO:     Waiting for application shutdown.
INFO:     Application shutdown complete.
INFO:     Finished server process [30646]
ElevenLabs API ключ не установлен
ElevenLabs API ключ не установлен
ElevenLabs API ключ не установлен
INFO:     Started server process [30957]
INFO:     Waiting for application startup.
INFO:     Started server process [30959]
INFO:     Waiting for application startup.
INFO:     Application startup complete.
ERROR:    Traceback (most recent call last):
  File "/usr/lib/python3.12/asyncio/runners.py", line 194, in run
    return runner.run(main)
           ^^^^^^^^^^^^^^^^
  File "/usr/lib/python3.12/asyncio/runners.py", line 118, in run
    return self._loop.run_until_complete(task)
           ^^^^^^^^^^^^^^^^^^^^^^^^^^^^^^^^^^^
  File "/usr/lib/python3.12/asyncio/base_events.py", line 687, in run_until_complete
    return future.result()
           ^^^^^^^^^^^^^^^
  File "/home/alex/Downloads/new-pr/ai_env/lib/python3.12/site-packages/uvicorn/server.py", line 71, in serve
    await self._serve(sockets)
  File "/home/alex/Downloads/new-pr/ai_env/lib/python3.12/site-packages/uvicorn/server.py", line 86, in _serve
    await self.startup(sockets=sockets)
  File "/home/alex/Downloads/new-pr/ai_env/lib/python3.12/site-packages/uvicorn/server.py", line 136, in startup
    server = await loop.create_server(create_protocol, sock=sock, ssl=config.ssl, backlog=config.backlog)
             ^^^^^^^^^^^^^^^^^^^^^^^^^^^^^^^^^^^^^^^^^^^^^^^^^^^^^^^^^^^^^^^^^^^^^^^^^^^^^^^^^^^^^^^^^^^^
  File "/usr/lib/python3.12/asyncio/base_events.py", line 1597, in create_server
    server._start_serving()
  File "/usr/lib/python3.12/asyncio/base_events.py", line 317, in _start_serving
    sock.listen(self._backlog)
OSError: [Errno 98] Address already in use

During handling of the above exception, another exception occurred:

Traceback (most recent call last):
  File "/home/alex/Downloads/new-pr/ai_env/lib/python3.12/site-packages/starlette/routing.py", line 701, in lifespan
    await receive()
  File "/home/alex/Downloads/new-pr/ai_env/lib/python3.12/site-packages/uvicorn/lifespan/on.py", line 137, in receive
    return await self.receive_queue.get()
           ^^^^^^^^^^^^^^^^^^^^^^^^^^^^^^
  File "/usr/lib/python3.12/asyncio/queues.py", line 158, in get
    await getter
asyncio.exceptions.CancelledError

Process SpawnProcess-5:
Traceback (most recent call last):
  File "/usr/lib/python3.12/multiprocessing/process.py", line 314, in _bootstrap
    self.run()
  File "/usr/lib/python3.12/multiprocessing/process.py", line 108, in run
    self._target(*self._args, **self._kwargs)
  File "/home/alex/Downloads/new-pr/ai_env/lib/python3.12/site-packages/uvicorn/_subprocess.py", line 80, in subprocess_started
    target(sockets=sockets)
  File "/home/alex/Downloads/new-pr/ai_env/lib/python3.12/site-packages/uvicorn/server.py", line 67, in run
    return asyncio.run(self.serve(sockets=sockets))
           ^^^^^^^^^^^^^^^^^^^^^^^^^^^^^^^^^^^^^^^^
  File "/usr/lib/python3.12/asyncio/runners.py", line 194, in run
    return runner.run(main)
           ^^^^^^^^^^^^^^^^
  File "/usr/lib/python3.12/asyncio/runners.py", line 118, in run
    return self._loop.run_until_complete(task)
           ^^^^^^^^^^^^^^^^^^^^^^^^^^^^^^^^^^^
  File "/usr/lib/python3.12/asyncio/base_events.py", line 687, in run_until_complete
    return future.result()
           ^^^^^^^^^^^^^^^
  File "/home/alex/Downloads/new-pr/ai_env/lib/python3.12/site-packages/uvicorn/server.py", line 71, in serve
    await self._serve(sockets)
  File "/home/alex/Downloads/new-pr/ai_env/lib/python3.12/site-packages/uvicorn/server.py", line 86, in _serve
    await self.startup(sockets=sockets)
  File "/home/alex/Downloads/new-pr/ai_env/lib/python3.12/site-packages/uvicorn/server.py", line 136, in startup
    server = await loop.create_server(create_protocol, sock=sock, ssl=config.ssl, backlog=config.backlog)
             ^^^^^^^^^^^^^^^^^^^^^^^^^^^^^^^^^^^^^^^^^^^^^^^^^^^^^^^^^^^^^^^^^^^^^^^^^^^^^^^^^^^^^^^^^^^^
  File "/usr/lib/python3.12/asyncio/base_events.py", line 1597, in create_server
    server._start_serving()
  File "/usr/lib/python3.12/asyncio/base_events.py", line 317, in _start_serving
    sock.listen(self._backlog)
OSError: [Errno 98] Address already in use
INFO:     Application startup complete.
ERROR:    Traceback (most recent call last):
  File "/usr/lib/python3.12/asyncio/runners.py", line 194, in run
    return runner.run(main)
           ^^^^^^^^^^^^^^^^
  File "/usr/lib/python3.12/asyncio/runners.py", line 118, in run
    return self._loop.run_until_complete(task)
           ^^^^^^^^^^^^^^^^^^^^^^^^^^^^^^^^^^^
  File "/usr/lib/python3.12/asyncio/base_events.py", line 687, in run_until_complete
    return future.result()
           ^^^^^^^^^^^^^^^
  File "/home/alex/Downloads/new-pr/ai_env/lib/python3.12/site-packages/uvicorn/server.py", line 71, in serve
    await self._serve(sockets)
  File "/home/alex/Downloads/new-pr/ai_env/lib/python3.12/site-packages/uvicorn/server.py", line 86, in _serve
    await self.startup(sockets=sockets)
  File "/home/alex/Downloads/new-pr/ai_env/lib/python3.12/site-packages/uvicorn/server.py", line 136, in startup
    server = await loop.create_server(create_protocol, sock=sock, ssl=config.ssl, backlog=config.backlog)
             ^^^^^^^^^^^^^^^^^^^^^^^^^^^^^^^^^^^^^^^^^^^^^^^^^^^^^^^^^^^^^^^^^^^^^^^^^^^^^^^^^^^^^^^^^^^^
  File "/usr/lib/python3.12/asyncio/base_events.py", line 1597, in create_server
    server._start_serving()
  File "/usr/lib/python3.12/asyncio/base_events.py", line 317, in _start_serving
    sock.listen(self._backlog)
OSError: [Errno 98] Address already in use

During handling of the above exception, another exception occurred:

Traceback (most recent call last):
  File "/home/alex/Downloads/new-pr/ai_env/lib/python3.12/site-packages/starlette/routing.py", line 701, in lifespan
    await receive()
  File "/home/alex/Downloads/new-pr/ai_env/lib/python3.12/site-packages/uvicorn/lifespan/on.py", line 137, in receive
    return await self.receive_queue.get()
           ^^^^^^^^^^^^^^^^^^^^^^^^^^^^^^
  File "/usr/lib/python3.12/asyncio/queues.py", line 158, in get
    await getter
asyncio.exceptions.CancelledError

Process SpawnProcess-4:
Traceback (most recent call last):
  File "/usr/lib/python3.12/multiprocessing/process.py", line 314, in _bootstrap
    self.run()
  File "/usr/lib/python3.12/multiprocessing/process.py", line 108, in run
    self._target(*self._args, **self._kwargs)
  File "/home/alex/Downloads/new-pr/ai_env/lib/python3.12/site-packages/uvicorn/_subprocess.py", line 80, in subprocess_started
    target(sockets=sockets)
  File "/home/alex/Downloads/new-pr/ai_env/lib/python3.12/site-packages/uvicorn/server.py", line 67, in run
    return asyncio.run(self.serve(sockets=sockets))
           ^^^^^^^^^^^^^^^^^^^^^^^^^^^^^^^^^^^^^^^^
  File "/usr/lib/python3.12/asyncio/runners.py", line 194, in run
    return runner.run(main)
           ^^^^^^^^^^^^^^^^
  File "/usr/lib/python3.12/asyncio/runners.py", line 118, in run
    return self._loop.run_until_complete(task)
           ^^^^^^^^^^^^^^^^^^^^^^^^^^^^^^^^^^^
  File "/usr/lib/python3.12/asyncio/base_events.py", line 687, in run_until_complete
    return future.result()
           ^^^^^^^^^^^^^^^
  File "/home/alex/Downloads/new-pr/ai_env/lib/python3.12/site-packages/uvicorn/server.py", line 71, in serve
    await self._serve(sockets)
  File "/home/alex/Downloads/new-pr/ai_env/lib/python3.12/site-packages/uvicorn/server.py", line 86, in _serve
    await self.startup(sockets=sockets)
  File "/home/alex/Downloads/new-pr/ai_env/lib/python3.12/site-packages/uvicorn/server.py", line 136, in startup
    server = await loop.create_server(create_protocol, sock=sock, ssl=config.ssl, backlog=config.backlog)
             ^^^^^^^^^^^^^^^^^^^^^^^^^^^^^^^^^^^^^^^^^^^^^^^^^^^^^^^^^^^^^^^^^^^^^^^^^^^^^^^^^^^^^^^^^^^^
  File "/usr/lib/python3.12/asyncio/base_events.py", line 1597, in create_server
    server._start_serving()
  File "/usr/lib/python3.12/asyncio/base_events.py", line 317, in _start_serving
    sock.listen(self._backlog)
OSError: [Errno 98] Address already in use
INFO:     Started server process [30961]
INFO:     Waiting for application startup.
INFO:     Application startup complete.
INFO:     127.0.0.1:47688 - "WebSocket /ws" [accepted]
INFO:     connection open
INFO:     127.0.0.1:47702 - "WebSocket /ws" [accepted]
INFO:     connection open
INFO:     Will watch for changes in these directories: ['/home/alex/Downloads/new-pr/backend']
INFO:     Uvicorn running on http://127.0.0.1:8000 (Press CTRL+C to quit)
INFO:     Started reloader process [31502] using StatReload
ElevenLabs API ключ не установлен
INFO:     Started server process [31504]
INFO:     Waiting for application startup.
INFO:     Application startup complete.
INFO:     127.0.0.1:43970 - "WebSocket /ws" [accepted]
INFO:     connection open
INFO:     127.0.0.1:57824 - "GET /health HTTP/1.1" 200 OK
INFO:     127.0.0.1:57830 - "GET /health HTTP/1.1" 200 OK
INFO:     127.0.0.1:57830 - "GET /health HTTP/1.1" 200 OK
INFO:     127.0.0.1:36834 - "GET /health HTTP/1.1" 200 OK
INFO:     127.0.0.1:36840 - "GET /health HTTP/1.1" 200 OK
INFO:     127.0.0.1:36834 - "GET /health HTTP/1.1" 200 OK
INFO:     127.0.0.1:55094 - "GET /health HTTP/1.1" 200 OK
INFO:     127.0.0.1:55100 - "GET /health HTTP/1.1" 200 OK
INFO:     127.0.0.1:55094 - "GET /health HTTP/1.1" 200 OK
INFO:     Will watch for changes in these directories: ['/home/alex/Downloads/new-pr/backend']
INFO:     Uvicorn running on http://127.0.0.1:8000 (Press CTRL+C to quit)
INFO:     Started reloader process [32237] using StatReload
ElevenLabs API ключ не установлен
INFO:     Started server process [32239]
INFO:     Waiting for application startup.
INFO:     Application startup complete.
INFO:     127.0.0.1:56284 - "GET /health HTTP/1.1" 200 OK
INFO:     127.0.0.1:56296 - "GET /health HTTP/1.1" 200 OK
INFO:     127.0.0.1:56284 - "GET /health HTTP/1.1" 200 OK
INFO:     127.0.0.1:56298 - "WebSocket /ws" [accepted]
INFO:     connection open
INFO:     connection closed
INFO:     127.0.0.1:56308 - "GET /health HTTP/1.1" 200 OK
INFO:     127.0.0.1:56320 - "GET /health HTTP/1.1" 200 OK
INFO:     127.0.0.1:56324 - "WebSocket /ws" [accepted]
INFO:     127.0.0.1:56308 - "GET /health HTTP/1.1" 200 OK
INFO:     connection open
INFO:     127.0.0.1:56320 - "GET /health HTTP/1.1" 200 OK
INFO:     127.0.0.1:56330 - "GET /health HTTP/1.1" 200 OK
INFO:     127.0.0.1:56344 - "GET /health HTTP/1.1" 200 OK
INFO:     connection closed
INFO:     127.0.0.1:40216 - "WebSocket /ws" [accepted]
INFO:     connection open
INFO:     connection closed
INFO:     127.0.0.1:56320 - "GET /health HTTP/1.1" 200 OK
INFO:     127.0.0.1:56320 - "GET /health HTTP/1.1" 200 OK
INFO:     127.0.0.1:56308 - "GET /health HTTP/1.1" 200 OK
INFO:     127.0.0.1:40230 - "WebSocket /ws" [accepted]
INFO:     127.0.0.1:56344 - "GET /health HTTP/1.1" 200 OK
INFO:     connection open
INFO:     127.0.0.1:56308 - "GET /health HTTP/1.1" 200 OK
INFO:     127.0.0.1:56344 - "GET /health HTTP/1.1" 200 OK
INFO:     127.0.0.1:34318 - "GET /health HTTP/1.1" 200 OK
INFO:     127.0.0.1:34326 - "GET /health HTTP/1.1" 200 OK
INFO:     127.0.0.1:34318 - "GET /health HTTP/1.1" 200 OK
INFO:     127.0.0.1:47266 - "GET /health HTTP/1.1" 200 OK
INFO:     127.0.0.1:47272 - "GET /health HTTP/1.1" 200 OK
INFO:     127.0.0.1:47266 - "GET /health HTTP/1.1" 200 OK
INFO:     127.0.0.1:36782 - "GET /health HTTP/1.1" 200 OK
INFO:     127.0.0.1:36798 - "GET /health HTTP/1.1" 200 OK
INFO:     127.0.0.1:36782 - "GET /health HTTP/1.1" 200 OK
INFO:     connection closed
INFO:     127.0.0.1:40958 - "WebSocket /ws" [accepted]
INFO:     connection open
INFO:     127.0.0.1:40966 - "GET /health HTTP/1.1" 200 OK
INFO:     127.0.0.1:40966 - "GET /health HTTP/1.1" 200 OK
INFO:     127.0.0.1:40978 - "GET /health HTTP/1.1" 200 OK
INFO:     127.0.0.1:56060 - "GET /health HTTP/1.1" 200 OK
INFO:     127.0.0.1:56076 - "GET /health HTTP/1.1" 200 OK
INFO:     127.0.0.1:56060 - "GET /health HTTP/1.1" 200 OK
INFO:     Will watch for changes in these directories: ['/home/alex/Downloads/new-pr/backend']
INFO:     Uvicorn running on http://127.0.0.1:8000 (Press CTRL+C to quit)
INFO:     Started reloader process [33141] using StatReload
ElevenLabs API ключ не установлен
INFO:     Started server process [33143]
INFO:     Waiting for application startup.
INFO:     Application startup complete.
INFO:     127.0.0.1:42564 - "WebSocket /ws" [accepted]
INFO:     connection open
INFO:     127.0.0.1:42024 - "GET /health HTTP/1.1" 200 OK
INFO:     127.0.0.1:42036 - "GET /health HTTP/1.1" 200 OK
INFO:     127.0.0.1:42036 - "GET /health HTTP/1.1" 200 OK
INFO:     connection closed
INFO:     127.0.0.1:57228 - "WebSocket /ws" [accepted]
INFO:     connection open
INFO:     connection closed
INFO:     127.0.0.1:57234 - "GET /health HTTP/1.1" 200 OK
INFO:     127.0.0.1:57236 - "WebSocket /ws" [accepted]
INFO:     connection open
INFO:     connection closed
INFO:     127.0.0.1:57252 - "GET /health HTTP/1.1" 200 OK
INFO:     127.0.0.1:57234 - "GET /health HTTP/1.1" 200 OK
INFO:     127.0.0.1:57258 - "WebSocket /ws" [accepted]
INFO:     connection open
INFO:     127.0.0.1:57252 - "GET /health HTTP/1.1" 200 OK
INFO:     127.0.0.1:57262 - "GET /health HTTP/1.1" 200 OK
INFO:     127.0.0.1:57272 - "GET /health HTTP/1.1" 200 OK
INFO:     connection closed
INFO:     127.0.0.1:57284 - "WebSocket /ws" [accepted]
INFO:     connection open
INFO:     127.0.0.1:39654 - "GET /health HTTP/1.1" 200 OK
INFO:     127.0.0.1:39662 - "GET /health HTTP/1.1" 200 OK
INFO:     127.0.0.1:39654 - "GET /health HTTP/1.1" 200 OK
WARNING:  StatReload detected changes in 'app/main.py'. Reloading...
WARNING:  StatReload detected changes in 'app/main.py'. Reloading...
WARNING:  StatReload detected changes in 'app/main.py'. Reloading...
INFO:     Shutting down
INFO:     connection closed
INFO:     Waiting for application shutdown.
INFO:     Application shutdown complete.
INFO:     Finished server process [33143]
ElevenLabs API ключ не установлен
ElevenLabs API ключ не установлен
ElevenLabs API ключ не установлен
INFO:     Started server process [33764]
INFO:     Waiting for application startup.
INFO:     Started server process [33765]
INFO:     Waiting for application startup.
INFO:     Application startup complete.
ERROR:    Traceback (most recent call last):
  File "/usr/lib/python3.12/asyncio/runners.py", line 194, in run
    return runner.run(main)
           ^^^^^^^^^^^^^^^^
  File "/usr/lib/python3.12/asyncio/runners.py", line 118, in run
    return self._loop.run_until_complete(task)
           ^^^^^^^^^^^^^^^^^^^^^^^^^^^^^^^^^^^
  File "/usr/lib/python3.12/asyncio/base_events.py", line 687, in run_until_complete
    return future.result()
           ^^^^^^^^^^^^^^^
  File "/home/alex/Downloads/new-pr/ai_env/lib/python3.12/site-packages/uvicorn/server.py", line 71, in serve
    await self._serve(sockets)
  File "/home/alex/Downloads/new-pr/ai_env/lib/python3.12/site-packages/uvicorn/server.py", line 86, in _serve
    await self.startup(sockets=sockets)
  File "/home/alex/Downloads/new-pr/ai_env/lib/python3.12/site-packages/uvicorn/server.py", line 136, in startup
    server = await loop.create_server(create_protocol, sock=sock, ssl=config.ssl, backlog=config.backlog)
             ^^^^^^^^^^^^^^^^^^^^^^^^^^^^^^^^^^^^^^^^^^^^^^^^^^^^^^^^^^^^^^^^^^^^^^^^^^^^^^^^^^^^^^^^^^^^
  File "/usr/lib/python3.12/asyncio/base_events.py", line 1597, in create_server
    server._start_serving()
  File "/usr/lib/python3.12/asyncio/base_events.py", line 317, in _start_serving
    sock.listen(self._backlog)
OSError: [Errno 98] Address already in use

During handling of the above exception, another exception occurred:

Traceback (most recent call last):
  File "/home/alex/Downloads/new-pr/ai_env/lib/python3.12/site-packages/starlette/routing.py", line 701, in lifespan
    await receive()
  File "/home/alex/Downloads/new-pr/ai_env/lib/python3.12/site-packages/uvicorn/lifespan/on.py", line 137, in receive
    return await self.receive_queue.get()
           ^^^^^^^^^^^^^^^^^^^^^^^^^^^^^^
  File "/usr/lib/python3.12/asyncio/queues.py", line 158, in get
    await getter
asyncio.exceptions.CancelledError

Process SpawnProcess-5:
Traceback (most recent call last):
  File "/usr/lib/python3.12/multiprocessing/process.py", line 314, in _bootstrap
    self.run()
  File "/usr/lib/python3.12/multiprocessing/process.py", line 108, in run
    self._target(*self._args, **self._kwargs)
  File "/home/alex/Downloads/new-pr/ai_env/lib/python3.12/site-packages/uvicorn/_subprocess.py", line 80, in subprocess_started
    target(sockets=sockets)
  File "/home/alex/Downloads/new-pr/ai_env/lib/python3.12/site-packages/uvicorn/server.py", line 67, in run
    return asyncio.run(self.serve(sockets=sockets))
           ^^^^^^^^^^^^^^^^^^^^^^^^^^^^^^^^^^^^^^^^
  File "/usr/lib/python3.12/asyncio/runners.py", line 194, in run
    return runner.run(main)
           ^^^^^^^^^^^^^^^^
  File "/usr/lib/python3.12/asyncio/runners.py", line 118, in run
    return self._loop.run_until_complete(task)
           ^^^^^^^^^^^^^^^^^^^^^^^^^^^^^^^^^^^
  File "/usr/lib/python3.12/asyncio/base_events.py", line 687, in run_until_complete
    return future.result()
           ^^^^^^^^^^^^^^^
  File "/home/alex/Downloads/new-pr/ai_env/lib/python3.12/site-packages/uvicorn/server.py", line 71, in serve
    await self._serve(sockets)
  File "/home/alex/Downloads/new-pr/ai_env/lib/python3.12/site-packages/uvicorn/server.py", line 86, in _serve
    await self.startup(sockets=sockets)
  File "/home/alex/Downloads/new-pr/ai_env/lib/python3.12/site-packages/uvicorn/server.py", line 136, in startup
    server = await loop.create_server(create_protocol, sock=sock, ssl=config.ssl, backlog=config.backlog)
             ^^^^^^^^^^^^^^^^^^^^^^^^^^^^^^^^^^^^^^^^^^^^^^^^^^^^^^^^^^^^^^^^^^^^^^^^^^^^^^^^^^^^^^^^^^^^
  File "/usr/lib/python3.12/asyncio/base_events.py", line 1597, in create_server
    server._start_serving()
  File "/usr/lib/python3.12/asyncio/base_events.py", line 317, in _start_serving
    sock.listen(self._backlog)
OSError: [Errno 98] Address already in use
INFO:     Application startup complete.
ERROR:    Traceback (most recent call last):
  File "/usr/lib/python3.12/asyncio/runners.py", line 194, in run
    return runner.run(main)
           ^^^^^^^^^^^^^^^^
  File "/usr/lib/python3.12/asyncio/runners.py", line 118, in run
    return self._loop.run_until_complete(task)
           ^^^^^^^^^^^^^^^^^^^^^^^^^^^^^^^^^^^
  File "/usr/lib/python3.12/asyncio/base_events.py", line 687, in run_until_complete
    return future.result()
           ^^^^^^^^^^^^^^^
  File "/home/alex/Downloads/new-pr/ai_env/lib/python3.12/site-packages/uvicorn/server.py", line 71, in serve
    await self._serve(sockets)
  File "/home/alex/Downloads/new-pr/ai_env/lib/python3.12/site-packages/uvicorn/server.py", line 86, in _serve
    await self.startup(sockets=sockets)
  File "/home/alex/Downloads/new-pr/ai_env/lib/python3.12/site-packages/uvicorn/server.py", line 136, in startup
    server = await loop.create_server(create_protocol, sock=sock, ssl=config.ssl, backlog=config.backlog)
             ^^^^^^^^^^^^^^^^^^^^^^^^^^^^^^^^^^^^^^^^^^^^^^^^^^^^^^^^^^^^^^^^^^^^^^^^^^^^^^^^^^^^^^^^^^^^
  File "/usr/lib/python3.12/asyncio/base_events.py", line 1597, in create_server
    server._start_serving()
  File "/usr/lib/python3.12/asyncio/base_events.py", line 317, in _start_serving
    sock.listen(self._backlog)
OSError: [Errno 98] Address already in use

During handling of the above exception, another exception occurred:

Traceback (most recent call last):
  File "/home/alex/Downloads/new-pr/ai_env/lib/python3.12/site-packages/starlette/routing.py", line 701, in lifespan
    await receive()
  File "/home/alex/Downloads/new-pr/ai_env/lib/python3.12/site-packages/uvicorn/lifespan/on.py", line 137, in receive
    return await self.receive_queue.get()
           ^^^^^^^^^^^^^^^^^^^^^^^^^^^^^^
  File "/usr/lib/python3.12/asyncio/queues.py", line 158, in get
    await getter
asyncio.exceptions.CancelledError

Process SpawnProcess-6:
Traceback (most recent call last):
  File "/usr/lib/python3.12/multiprocessing/process.py", line 314, in _bootstrap
    self.run()
  File "/usr/lib/python3.12/multiprocessing/process.py", line 108, in run
    self._target(*self._args, **self._kwargs)
  File "/home/alex/Downloads/new-pr/ai_env/lib/python3.12/site-packages/uvicorn/_subprocess.py", line 80, in subprocess_started
    target(sockets=sockets)
  File "/home/alex/Downloads/new-pr/ai_env/lib/python3.12/site-packages/uvicorn/server.py", line 67, in run
    return asyncio.run(self.serve(sockets=sockets))
           ^^^^^^^^^^^^^^^^^^^^^^^^^^^^^^^^^^^^^^^^
  File "/usr/lib/python3.12/asyncio/runners.py", line 194, in run
    return runner.run(main)
           ^^^^^^^^^^^^^^^^
  File "/usr/lib/python3.12/asyncio/runners.py", line 118, in run
    return self._loop.run_until_complete(task)
           ^^^^^^^^^^^^^^^^^^^^^^^^^^^^^^^^^^^
  File "/usr/lib/python3.12/asyncio/base_events.py", line 687, in run_until_complete
    return future.result()
           ^^^^^^^^^^^^^^^
  File "/home/alex/Downloads/new-pr/ai_env/lib/python3.12/site-packages/uvicorn/server.py", line 71, in serve
    await self._serve(sockets)
  File "/home/alex/Downloads/new-pr/ai_env/lib/python3.12/site-packages/uvicorn/server.py", line 86, in _serve
    await self.startup(sockets=sockets)
  File "/home/alex/Downloads/new-pr/ai_env/lib/python3.12/site-packages/uvicorn/server.py", line 136, in startup
    server = await loop.create_server(create_protocol, sock=sock, ssl=config.ssl, backlog=config.backlog)
             ^^^^^^^^^^^^^^^^^^^^^^^^^^^^^^^^^^^^^^^^^^^^^^^^^^^^^^^^^^^^^^^^^^^^^^^^^^^^^^^^^^^^^^^^^^^^
  File "/usr/lib/python3.12/asyncio/base_events.py", line 1597, in create_server
    server._start_serving()
  File "/usr/lib/python3.12/asyncio/base_events.py", line 317, in _start_serving
    sock.listen(self._backlog)
OSError: [Errno 98] Address already in use
INFO:     Started server process [33766]
INFO:     Waiting for application startup.
INFO:     Application startup complete.
INFO:     127.0.0.1:42620 - "WebSocket /ws" [accepted]
INFO:     connection open
INFO:     127.0.0.1:37648 - "GET /health HTTP/1.1" 200 OK
INFO:     127.0.0.1:37662 - "GET /health HTTP/1.1" 200 OK
INFO:     127.0.0.1:37648 - "GET /health HTTP/1.1" 200 OK
WARNING:  StatReload detected changes in 'app/main.py'. Reloading...
WARNING:  StatReload detected changes in 'app/main.py'. Reloading...
WARNING:  StatReload detected changes in 'app/main.py'. Reloading...
INFO:     Shutting down
INFO:     connection closed
INFO:     Waiting for application shutdown.
INFO:     Application shutdown complete.
INFO:     Finished server process [33766]
ElevenLabs API ключ не установлен
ElevenLabs API ключ не установлен
ElevenLabs API ключ не установлен
INFO:     Started server process [33967]
INFO:     Waiting for application startup.
INFO:     Started server process [33966]
INFO:     Waiting for application startup.
INFO:     Application startup complete.
ERROR:    Traceback (most recent call last):
  File "/usr/lib/python3.12/asyncio/runners.py", line 194, in run
    return runner.run(main)
           ^^^^^^^^^^^^^^^^
  File "/usr/lib/python3.12/asyncio/runners.py", line 118, in run
    return self._loop.run_until_complete(task)
           ^^^^^^^^^^^^^^^^^^^^^^^^^^^^^^^^^^^
  File "/usr/lib/python3.12/asyncio/base_events.py", line 687, in run_until_complete
    return future.result()
           ^^^^^^^^^^^^^^^
  File "/home/alex/Downloads/new-pr/ai_env/lib/python3.12/site-packages/uvicorn/server.py", line 71, in serve
    await self._serve(sockets)
  File "/home/alex/Downloads/new-pr/ai_env/lib/python3.12/site-packages/uvicorn/server.py", line 86, in _serve
    await self.startup(sockets=sockets)
  File "/home/alex/Downloads/new-pr/ai_env/lib/python3.12/site-packages/uvicorn/server.py", line 136, in startup
    server = await loop.create_server(create_protocol, sock=sock, ssl=config.ssl, backlog=config.backlog)
             ^^^^^^^^^^^^^^^^^^^^^^^^^^^^^^^^^^^^^^^^^^^^^^^^^^^^^^^^^^^^^^^^^^^^^^^^^^^^^^^^^^^^^^^^^^^^
  File "/usr/lib/python3.12/asyncio/base_events.py", line 1597, in create_server
    server._start_serving()
  File "/usr/lib/python3.12/asyncio/base_events.py", line 317, in _start_serving
    sock.listen(self._backlog)
OSError: [Errno 98] Address already in use

During handling of the above exception, another exception occurred:

Traceback (most recent call last):
  File "/home/alex/Downloads/new-pr/ai_env/lib/python3.12/site-packages/starlette/routing.py", line 701, in lifespan
    await receive()
  File "/home/alex/Downloads/new-pr/ai_env/lib/python3.12/site-packages/uvicorn/lifespan/on.py", line 137, in receive
    return await self.receive_queue.get()
           ^^^^^^^^^^^^^^^^^^^^^^^^^^^^^^
  File "/usr/lib/python3.12/asyncio/queues.py", line 158, in get
    await getter
asyncio.exceptions.CancelledError

Process SpawnProcess-7:
Traceback (most recent call last):
  File "/usr/lib/python3.12/multiprocessing/process.py", line 314, in _bootstrap
    self.run()
  File "/usr/lib/python3.12/multiprocessing/process.py", line 108, in run
    self._target(*self._args, **self._kwargs)
  File "/home/alex/Downloads/new-pr/ai_env/lib/python3.12/site-packages/uvicorn/_subprocess.py", line 80, in subprocess_started
    target(sockets=sockets)
  File "/home/alex/Downloads/new-pr/ai_env/lib/python3.12/site-packages/uvicorn/server.py", line 67, in run
    return asyncio.run(self.serve(sockets=sockets))
           ^^^^^^^^^^^^^^^^^^^^^^^^^^^^^^^^^^^^^^^^
  File "/usr/lib/python3.12/asyncio/runners.py", line 194, in run
    return runner.run(main)
           ^^^^^^^^^^^^^^^^
  File "/usr/lib/python3.12/asyncio/runners.py", line 118, in run
    return self._loop.run_until_complete(task)
           ^^^^^^^^^^^^^^^^^^^^^^^^^^^^^^^^^^^
  File "/usr/lib/python3.12/asyncio/base_events.py", line 687, in run_until_complete
    return future.result()
           ^^^^^^^^^^^^^^^
  File "/home/alex/Downloads/new-pr/ai_env/lib/python3.12/site-packages/uvicorn/server.py", line 71, in serve
    await self._serve(sockets)
  File "/home/alex/Downloads/new-pr/ai_env/lib/python3.12/site-packages/uvicorn/server.py", line 86, in _serve
    await self.startup(sockets=sockets)
  File "/home/alex/Downloads/new-pr/ai_env/lib/python3.12/site-packages/uvicorn/server.py", line 136, in startup
    server = await loop.create_server(create_protocol, sock=sock, ssl=config.ssl, backlog=config.backlog)
             ^^^^^^^^^^^^^^^^^^^^^^^^^^^^^^^^^^^^^^^^^^^^^^^^^^^^^^^^^^^^^^^^^^^^^^^^^^^^^^^^^^^^^^^^^^^^
  File "/usr/lib/python3.12/asyncio/base_events.py", line 1597, in create_server
    server._start_serving()
  File "/usr/lib/python3.12/asyncio/base_events.py", line 317, in _start_serving
    sock.listen(self._backlog)
OSError: [Errno 98] Address already in use
INFO:     Application startup complete.
ERROR:    Traceback (most recent call last):
  File "/usr/lib/python3.12/asyncio/runners.py", line 194, in run
    return runner.run(main)
           ^^^^^^^^^^^^^^^^
  File "/usr/lib/python3.12/asyncio/runners.py", line 118, in run
    return self._loop.run_until_complete(task)
           ^^^^^^^^^^^^^^^^^^^^^^^^^^^^^^^^^^^
  File "/usr/lib/python3.12/asyncio/base_events.py", line 687, in run_until_complete
    return future.result()
           ^^^^^^^^^^^^^^^
  File "/home/alex/Downloads/new-pr/ai_env/lib/python3.12/site-packages/uvicorn/server.py", line 71, in serve
    await self._serve(sockets)
  File "/home/alex/Downloads/new-pr/ai_env/lib/python3.12/site-packages/uvicorn/server.py", line 86, in _serve
    await self.startup(sockets=sockets)
  File "/home/alex/Downloads/new-pr/ai_env/lib/python3.12/site-packages/uvicorn/server.py", line 136, in startup
    server = await loop.create_server(create_protocol, sock=sock, ssl=config.ssl, backlog=config.backlog)
             ^^^^^^^^^^^^^^^^^^^^^^^^^^^^^^^^^^^^^^^^^^^^^^^^^^^^^^^^^^^^^^^^^^^^^^^^^^^^^^^^^^^^^^^^^^^^
  File "/usr/lib/python3.12/asyncio/base_events.py", line 1597, in create_server
    server._start_serving()
  File "/usr/lib/python3.12/asyncio/base_events.py", line 317, in _start_serving
    sock.listen(self._backlog)
OSError: [Errno 98] Address already in use

During handling of the above exception, another exception occurred:

Traceback (most recent call last):
  File "/home/alex/Downloads/new-pr/ai_env/lib/python3.12/site-packages/starlette/routing.py", line 701, in lifespan
    await receive()
  File "/home/alex/Downloads/new-pr/ai_env/lib/python3.12/site-packages/uvicorn/lifespan/on.py", line 137, in receive
    return await self.receive_queue.get()
           ^^^^^^^^^^^^^^^^^^^^^^^^^^^^^^
  File "/usr/lib/python3.12/asyncio/queues.py", line 158, in get
    await getter
asyncio.exceptions.CancelledError

Process SpawnProcess-6:
Traceback (most recent call last):
  File "/usr/lib/python3.12/multiprocessing/process.py", line 314, in _bootstrap
    self.run()
  File "/usr/lib/python3.12/multiprocessing/process.py", line 108, in run
    self._target(*self._args, **self._kwargs)
  File "/home/alex/Downloads/new-pr/ai_env/lib/python3.12/site-packages/uvicorn/_subprocess.py", line 80, in subprocess_started
    target(sockets=sockets)
  File "/home/alex/Downloads/new-pr/ai_env/lib/python3.12/site-packages/uvicorn/server.py", line 67, in run
    return asyncio.run(self.serve(sockets=sockets))
           ^^^^^^^^^^^^^^^^^^^^^^^^^^^^^^^^^^^^^^^^
  File "/usr/lib/python3.12/asyncio/runners.py", line 194, in run
    return runner.run(main)
           ^^^^^^^^^^^^^^^^
  File "/usr/lib/python3.12/asyncio/runners.py", line 118, in run
    return self._loop.run_until_complete(task)
           ^^^^^^^^^^^^^^^^^^^^^^^^^^^^^^^^^^^
  File "/usr/lib/python3.12/asyncio/base_events.py", line 687, in run_until_complete
    return future.result()
           ^^^^^^^^^^^^^^^
  File "/home/alex/Downloads/new-pr/ai_env/lib/python3.12/site-packages/uvicorn/server.py", line 71, in serve
    await self._serve(sockets)
  File "/home/alex/Downloads/new-pr/ai_env/lib/python3.12/site-packages/uvicorn/server.py", line 86, in _serve
    await self.startup(sockets=sockets)
  File "/home/alex/Downloads/new-pr/ai_env/lib/python3.12/site-packages/uvicorn/server.py", line 136, in startup
    server = await loop.create_server(create_protocol, sock=sock, ssl=config.ssl, backlog=config.backlog)
             ^^^^^^^^^^^^^^^^^^^^^^^^^^^^^^^^^^^^^^^^^^^^^^^^^^^^^^^^^^^^^^^^^^^^^^^^^^^^^^^^^^^^^^^^^^^^
  File "/usr/lib/python3.12/asyncio/base_events.py", line 1597, in create_server
    server._start_serving()
  File "/usr/lib/python3.12/asyncio/base_events.py", line 317, in _start_serving
    sock.listen(self._backlog)
OSError: [Errno 98] Address already in use
INFO:     Started server process [33968]
INFO:     Waiting for application startup.
INFO:     Application startup complete.
INFO:     127.0.0.1:51502 - "WebSocket /ws" [accepted]
INFO:     connection open
WARNING:  StatReload detected changes in 'app/main.py'. Reloading...
WARNING:  StatReload detected changes in 'app/main.py'. Reloading...
WARNING:  StatReload detected changes in 'app/main.py'. Reloading...
INFO:     Shutting down
INFO:     connection closed
INFO:     Waiting for application shutdown.
INFO:     Application shutdown complete.
INFO:     Finished server process [33968]
ElevenLabs API ключ не установлен
ElevenLabs API ключ не установлен
ElevenLabs API ключ не установлен
INFO:     Started server process [34061]
INFO:     Waiting for application startup.
INFO:     Started server process [34062]
INFO:     Waiting for application startup.
INFO:     Application startup complete.
ERROR:    Traceback (most recent call last):
  File "/usr/lib/python3.12/asyncio/runners.py", line 194, in run
    return runner.run(main)
           ^^^^^^^^^^^^^^^^
  File "/usr/lib/python3.12/asyncio/runners.py", line 118, in run
    return self._loop.run_until_complete(task)
           ^^^^^^^^^^^^^^^^^^^^^^^^^^^^^^^^^^^
  File "/usr/lib/python3.12/asyncio/base_events.py", line 687, in run_until_complete
    return future.result()
           ^^^^^^^^^^^^^^^
  File "/home/alex/Downloads/new-pr/ai_env/lib/python3.12/site-packages/uvicorn/server.py", line 71, in serve
    await self._serve(sockets)
  File "/home/alex/Downloads/new-pr/ai_env/lib/python3.12/site-packages/uvicorn/server.py", line 86, in _serve
    await self.startup(sockets=sockets)
  File "/home/alex/Downloads/new-pr/ai_env/lib/python3.12/site-packages/uvicorn/server.py", line 136, in startup
    server = await loop.create_server(create_protocol, sock=sock, ssl=config.ssl, backlog=config.backlog)
             ^^^^^^^^^^^^^^^^^^^^^^^^^^^^^^^^^^^^^^^^^^^^^^^^^^^^^^^^^^^^^^^^^^^^^^^^^^^^^^^^^^^^^^^^^^^^
  File "/usr/lib/python3.12/asyncio/base_events.py", line 1597, in create_server
    server._start_serving()
  File "/usr/lib/python3.12/asyncio/base_events.py", line 317, in _start_serving
    sock.listen(self._backlog)
OSError: [Errno 98] Address already in use

During handling of the above exception, another exception occurred:

Traceback (most recent call last):
  File "/home/alex/Downloads/new-pr/ai_env/lib/python3.12/site-packages/starlette/routing.py", line 701, in lifespan
    await receive()
  File "/home/alex/Downloads/new-pr/ai_env/lib/python3.12/site-packages/uvicorn/lifespan/on.py", line 137, in receive
    return await self.receive_queue.get()
           ^^^^^^^^^^^^^^^^^^^^^^^^^^^^^^
  File "/usr/lib/python3.12/asyncio/queues.py", line 158, in get
    await getter
asyncio.exceptions.CancelledError

Process SpawnProcess-7:
Traceback (most recent call last):
  File "/usr/lib/python3.12/multiprocessing/process.py", line 314, in _bootstrap
    self.run()
  File "/usr/lib/python3.12/multiprocessing/process.py", line 108, in run
    self._target(*self._args, **self._kwargs)
  File "/home/alex/Downloads/new-pr/ai_env/lib/python3.12/site-packages/uvicorn/_subprocess.py", line 80, in subprocess_started
    target(sockets=sockets)
  File "/home/alex/Downloads/new-pr/ai_env/lib/python3.12/site-packages/uvicorn/server.py", line 67, in run
    return asyncio.run(self.serve(sockets=sockets))
           ^^^^^^^^^^^^^^^^^^^^^^^^^^^^^^^^^^^^^^^^
  File "/usr/lib/python3.12/asyncio/runners.py", line 194, in run
    return runner.run(main)
           ^^^^^^^^^^^^^^^^
  File "/usr/lib/python3.12/asyncio/runners.py", line 118, in run
    return self._loop.run_until_complete(task)
           ^^^^^^^^^^^^^^^^^^^^^^^^^^^^^^^^^^^
  File "/usr/lib/python3.12/asyncio/base_events.py", line 687, in run_until_complete
    return future.result()
           ^^^^^^^^^^^^^^^
  File "/home/alex/Downloads/new-pr/ai_env/lib/python3.12/site-packages/uvicorn/server.py", line 71, in serve
    await self._serve(sockets)
  File "/home/alex/Downloads/new-pr/ai_env/lib/python3.12/site-packages/uvicorn/server.py", line 86, in _serve
    await self.startup(sockets=sockets)
  File "/home/alex/Downloads/new-pr/ai_env/lib/python3.12/site-packages/uvicorn/server.py", line 136, in startup
    server = await loop.create_server(create_protocol, sock=sock, ssl=config.ssl, backlog=config.backlog)
             ^^^^^^^^^^^^^^^^^^^^^^^^^^^^^^^^^^^^^^^^^^^^^^^^^^^^^^^^^^^^^^^^^^^^^^^^^^^^^^^^^^^^^^^^^^^^
  File "/usr/lib/python3.12/asyncio/base_events.py", line 1597, in create_server
    server._start_serving()
  File "/usr/lib/python3.12/asyncio/base_events.py", line 317, in _start_serving
    sock.listen(self._backlog)
OSError: [Errno 98] Address already in use
INFO:     Application startup complete.
ERROR:    Traceback (most recent call last):
  File "/usr/lib/python3.12/asyncio/runners.py", line 194, in run
    return runner.run(main)
           ^^^^^^^^^^^^^^^^
  File "/usr/lib/python3.12/asyncio/runners.py", line 118, in run
    return self._loop.run_until_complete(task)
           ^^^^^^^^^^^^^^^^^^^^^^^^^^^^^^^^^^^
  File "/usr/lib/python3.12/asyncio/base_events.py", line 687, in run_until_complete
    return future.result()
           ^^^^^^^^^^^^^^^
  File "/home/alex/Downloads/new-pr/ai_env/lib/python3.12/site-packages/uvicorn/server.py", line 71, in serve
    await self._serve(sockets)
  File "/home/alex/Downloads/new-pr/ai_env/lib/python3.12/site-packages/uvicorn/server.py", line 86, in _serve
    await self.startup(sockets=sockets)
  File "/home/alex/Downloads/new-pr/ai_env/lib/python3.12/site-packages/uvicorn/server.py", line 136, in startup
    server = await loop.create_server(create_protocol, sock=sock, ssl=config.ssl, backlog=config.backlog)
             ^^^^^^^^^^^^^^^^^^^^^^^^^^^^^^^^^^^^^^^^^^^^^^^^^^^^^^^^^^^^^^^^^^^^^^^^^^^^^^^^^^^^^^^^^^^^
  File "/usr/lib/python3.12/asyncio/base_events.py", line 1597, in create_server
    server._start_serving()
  File "/usr/lib/python3.12/asyncio/base_events.py", line 317, in _start_serving
    sock.listen(self._backlog)
OSError: [Errno 98] Address already in use

During handling of the above exception, another exception occurred:

Traceback (most recent call last):
  File "/home/alex/Downloads/new-pr/ai_env/lib/python3.12/site-packages/starlette/routing.py", line 701, in lifespan
    await receive()
  File "/home/alex/Downloads/new-pr/ai_env/lib/python3.12/site-packages/uvicorn/lifespan/on.py", line 137, in receive
    return await self.receive_queue.get()
           ^^^^^^^^^^^^^^^^^^^^^^^^^^^^^^
  File "/usr/lib/python3.12/asyncio/queues.py", line 158, in get
    await getter
asyncio.exceptions.CancelledError

Process SpawnProcess-8:
Traceback (most recent call last):
  File "/usr/lib/python3.12/multiprocessing/process.py", line 314, in _bootstrap
    self.run()
  File "/usr/lib/python3.12/multiprocessing/process.py", line 108, in run
    self._target(*self._args, **self._kwargs)
  File "/home/alex/Downloads/new-pr/ai_env/lib/python3.12/site-packages/uvicorn/_subprocess.py", line 80, in subprocess_started
    target(sockets=sockets)
  File "/home/alex/Downloads/new-pr/ai_env/lib/python3.12/site-packages/uvicorn/server.py", line 67, in run
    return asyncio.run(self.serve(sockets=sockets))
           ^^^^^^^^^^^^^^^^^^^^^^^^^^^^^^^^^^^^^^^^
  File "/usr/lib/python3.12/asyncio/runners.py", line 194, in run
    return runner.run(main)
           ^^^^^^^^^^^^^^^^
  File "/usr/lib/python3.12/asyncio/runners.py", line 118, in run
    return self._loop.run_until_complete(task)
           ^^^^^^^^^^^^^^^^^^^^^^^^^^^^^^^^^^^
  File "/usr/lib/python3.12/asyncio/base_events.py", line 687, in run_until_complete
    return future.result()
           ^^^^^^^^^^^^^^^
  File "/home/alex/Downloads/new-pr/ai_env/lib/python3.12/site-packages/uvicorn/server.py", line 71, in serve
    await self._serve(sockets)
  File "/home/alex/Downloads/new-pr/ai_env/lib/python3.12/site-packages/uvicorn/server.py", line 86, in _serve
    await self.startup(sockets=sockets)
  File "/home/alex/Downloads/new-pr/ai_env/lib/python3.12/site-packages/uvicorn/server.py", line 136, in startup
    server = await loop.create_server(create_protocol, sock=sock, ssl=config.ssl, backlog=config.backlog)
             ^^^^^^^^^^^^^^^^^^^^^^^^^^^^^^^^^^^^^^^^^^^^^^^^^^^^^^^^^^^^^^^^^^^^^^^^^^^^^^^^^^^^^^^^^^^^
  File "/usr/lib/python3.12/asyncio/base_events.py", line 1597, in create_server
    server._start_serving()
  File "/usr/lib/python3.12/asyncio/base_events.py", line 317, in _start_serving
    sock.listen(self._backlog)
OSError: [Errno 98] Address already in use
INFO:     Started server process [34063]
INFO:     Waiting for application startup.
INFO:     Application startup complete.
INFO:     127.0.0.1:47900 - "WebSocket /ws" [accepted]
INFO:     connection open
INFO:     Will watch for changes in these directories: ['/home/alex/Downloads/new-pr/backend']
INFO:     Uvicorn running on http://127.0.0.1:8000 (Press CTRL+C to quit)
INFO:     Started reloader process [34179] using StatReload
ElevenLabs API ключ не установлен
INFO:     Started server process [34181]
INFO:     Waiting for application startup.
INFO:     Application startup complete.
INFO:     127.0.0.1:47906 - "WebSocket /ws" [accepted]
INFO:     connection open
INFO:     127.0.0.1:39552 - "GET /health HTTP/1.1" 200 OK
INFO:     127.0.0.1:39568 - "GET /health HTTP/1.1" 200 OK
INFO:     127.0.0.1:39552 - "GET /health HTTP/1.1" 200 OK
INFO:     connection closed
INFO:     127.0.0.1:39576 - "WebSocket /ws" [accepted]
INFO:     connection open
INFO:     127.0.0.1:39552 - "GET /health HTTP/1.1" 200 OK
INFO:     connection closed
INFO:     127.0.0.1:39568 - "GET /health HTTP/1.1" 200 OK
INFO:     127.0.0.1:39590 - "WebSocket /ws" [accepted]
INFO:     connection open
INFO:     127.0.0.1:39552 - "GET /health HTTP/1.1" 200 OK
INFO:     127.0.0.1:39568 - "GET /health HTTP/1.1" 200 OK
INFO:     127.0.0.1:39592 - "GET /health HTTP/1.1" 200 OK
INFO:     127.0.0.1:39600 - "GET /health HTTP/1.1" 200 OK
INFO:     connection closed
INFO:     127.0.0.1:39608 - "WebSocket /ws" [accepted]
INFO:     connection open
INFO:     127.0.0.1:52868 - "GET /health HTTP/1.1" 200 OK
INFO:     127.0.0.1:52878 - "GET /health HTTP/1.1" 200 OK
INFO:     127.0.0.1:52868 - "GET /health HTTP/1.1" 200 OK
INFO:     127.0.0.1:33430 - "GET /health HTTP/1.1" 200 OK
INFO:     127.0.0.1:33434 - "GET /health HTTP/1.1" 200 OK
INFO:     127.0.0.1:33430 - "GET /health HTTP/1.1" 200 OK
INFO:     127.0.0.1:48582 - "GET /health HTTP/1.1" 200 OK
INFO:     127.0.0.1:48588 - "GET /health HTTP/1.1" 200 OK
INFO:     127.0.0.1:48582 - "GET /health HTTP/1.1" 200 OK
INFO:     127.0.0.1:55478 - "GET /health HTTP/1.1" 200 OK
INFO:     127.0.0.1:55478 - "GET /health HTTP/1.1" 200 OK
INFO:     127.0.0.1:55486 - "GET /health HTTP/1.1" 200 OK
WARNING:  StatReload detected changes in 'app/config.py'. Reloading...
WARNING:  StatReload detected changes in 'app/config.py'. Reloading...
WARNING:  StatReload detected changes in 'app/config.py'. Reloading...
INFO:     Shutting down
INFO:     connection closed
INFO:     Waiting for application shutdown.
INFO:     Application shutdown complete.
INFO:     Finished server process [34181]
ElevenLabs API ключ не установлен
ElevenLabs API ключ не установлен
ElevenLabs API ключ не установлен
INFO:     Started server process [34919]
INFO:     Waiting for application startup.
INFO:     Started server process [34920]
INFO:     Waiting for application startup.
INFO:     Application startup complete.
ERROR:    Traceback (most recent call last):
  File "/usr/lib/python3.12/asyncio/runners.py", line 194, in run
    return runner.run(main)
           ^^^^^^^^^^^^^^^^
  File "/usr/lib/python3.12/asyncio/runners.py", line 118, in run
    return self._loop.run_until_complete(task)
           ^^^^^^^^^^^^^^^^^^^^^^^^^^^^^^^^^^^
  File "/usr/lib/python3.12/asyncio/base_events.py", line 687, in run_until_complete
    return future.result()
           ^^^^^^^^^^^^^^^
  File "/home/alex/Downloads/new-pr/ai_env/lib/python3.12/site-packages/uvicorn/server.py", line 71, in serve
    await self._serve(sockets)
  File "/home/alex/Downloads/new-pr/ai_env/lib/python3.12/site-packages/uvicorn/server.py", line 86, in _serve
    await self.startup(sockets=sockets)
  File "/home/alex/Downloads/new-pr/ai_env/lib/python3.12/site-packages/uvicorn/server.py", line 136, in startup
    server = await loop.create_server(create_protocol, sock=sock, ssl=config.ssl, backlog=config.backlog)
             ^^^^^^^^^^^^^^^^^^^^^^^^^^^^^^^^^^^^^^^^^^^^^^^^^^^^^^^^^^^^^^^^^^^^^^^^^^^^^^^^^^^^^^^^^^^^
  File "/usr/lib/python3.12/asyncio/base_events.py", line 1597, in create_server
    server._start_serving()
  File "/usr/lib/python3.12/asyncio/base_events.py", line 317, in _start_serving
    sock.listen(self._backlog)
OSError: [Errno 98] Address already in use

During handling of the above exception, another exception occurred:

Traceback (most recent call last):
  File "/home/alex/Downloads/new-pr/ai_env/lib/python3.12/site-packages/starlette/routing.py", line 701, in lifespan
    await receive()
  File "/home/alex/Downloads/new-pr/ai_env/lib/python3.12/site-packages/uvicorn/lifespan/on.py", line 137, in receive
    return await self.receive_queue.get()
           ^^^^^^^^^^^^^^^^^^^^^^^^^^^^^^
  File "/usr/lib/python3.12/asyncio/queues.py", line 158, in get
    await getter
asyncio.exceptions.CancelledError

Process SpawnProcess-9:
Traceback (most recent call last):
  File "/usr/lib/python3.12/multiprocessing/process.py", line 314, in _bootstrap
    self.run()
  File "/usr/lib/python3.12/multiprocessing/process.py", line 108, in run
    self._target(*self._args, **self._kwargs)
  File "/home/alex/Downloads/new-pr/ai_env/lib/python3.12/site-packages/uvicorn/_subprocess.py", line 80, in subprocess_started
    target(sockets=sockets)
  File "/home/alex/Downloads/new-pr/ai_env/lib/python3.12/site-packages/uvicorn/server.py", line 67, in run
    return asyncio.run(self.serve(sockets=sockets))
           ^^^^^^^^^^^^^^^^^^^^^^^^^^^^^^^^^^^^^^^^
  File "/usr/lib/python3.12/asyncio/runners.py", line 194, in run
    return runner.run(main)
           ^^^^^^^^^^^^^^^^
  File "/usr/lib/python3.12/asyncio/runners.py", line 118, in run
    return self._loop.run_until_complete(task)
           ^^^^^^^^^^^^^^^^^^^^^^^^^^^^^^^^^^^
  File "/usr/lib/python3.12/asyncio/base_events.py", line 687, in run_until_complete
    return future.result()
           ^^^^^^^^^^^^^^^
  File "/home/alex/Downloads/new-pr/ai_env/lib/python3.12/site-packages/uvicorn/server.py", line 71, in serve
    await self._serve(sockets)
  File "/home/alex/Downloads/new-pr/ai_env/lib/python3.12/site-packages/uvicorn/server.py", line 86, in _serve
    await self.startup(sockets=sockets)
  File "/home/alex/Downloads/new-pr/ai_env/lib/python3.12/site-packages/uvicorn/server.py", line 136, in startup
    server = await loop.create_server(create_protocol, sock=sock, ssl=config.ssl, backlog=config.backlog)
             ^^^^^^^^^^^^^^^^^^^^^^^^^^^^^^^^^^^^^^^^^^^^^^^^^^^^^^^^^^^^^^^^^^^^^^^^^^^^^^^^^^^^^^^^^^^^
  File "/usr/lib/python3.12/asyncio/base_events.py", line 1597, in create_server
    server._start_serving()
  File "/usr/lib/python3.12/asyncio/base_events.py", line 317, in _start_serving
    sock.listen(self._backlog)
OSError: [Errno 98] Address already in use
INFO:     Application startup complete.
ERROR:    Traceback (most recent call last):
  File "/usr/lib/python3.12/asyncio/runners.py", line 194, in run
    return runner.run(main)
           ^^^^^^^^^^^^^^^^
  File "/usr/lib/python3.12/asyncio/runners.py", line 118, in run
    return self._loop.run_until_complete(task)
           ^^^^^^^^^^^^^^^^^^^^^^^^^^^^^^^^^^^
  File "/usr/lib/python3.12/asyncio/base_events.py", line 687, in run_until_complete
    return future.result()
           ^^^^^^^^^^^^^^^
  File "/home/alex/Downloads/new-pr/ai_env/lib/python3.12/site-packages/uvicorn/server.py", line 71, in serve
    await self._serve(sockets)
  File "/home/alex/Downloads/new-pr/ai_env/lib/python3.12/site-packages/uvicorn/server.py", line 86, in _serve
    await self.startup(sockets=sockets)
  File "/home/alex/Downloads/new-pr/ai_env/lib/python3.12/site-packages/uvicorn/server.py", line 136, in startup
    server = await loop.create_server(create_protocol, sock=sock, ssl=config.ssl, backlog=config.backlog)
             ^^^^^^^^^^^^^^^^^^^^^^^^^^^^^^^^^^^^^^^^^^^^^^^^^^^^^^^^^^^^^^^^^^^^^^^^^^^^^^^^^^^^^^^^^^^^
  File "/usr/lib/python3.12/asyncio/base_events.py", line 1597, in create_server
    server._start_serving()
  File "/usr/lib/python3.12/asyncio/base_events.py", line 317, in _start_serving
    sock.listen(self._backlog)
OSError: [Errno 98] Address already in use

During handling of the above exception, another exception occurred:

Traceback (most recent call last):
  File "/home/alex/Downloads/new-pr/ai_env/lib/python3.12/site-packages/starlette/routing.py", line 701, in lifespan
    await receive()
  File "/home/alex/Downloads/new-pr/ai_env/lib/python3.12/site-packages/uvicorn/lifespan/on.py", line 137, in receive
    return await self.receive_queue.get()
           ^^^^^^^^^^^^^^^^^^^^^^^^^^^^^^
  File "/usr/lib/python3.12/asyncio/queues.py", line 158, in get
    await getter
asyncio.exceptions.CancelledError

Process SpawnProcess-8:
Traceback (most recent call last):
  File "/usr/lib/python3.12/multiprocessing/process.py", line 314, in _bootstrap
    self.run()
  File "/usr/lib/python3.12/multiprocessing/process.py", line 108, in run
    self._target(*self._args, **self._kwargs)
  File "/home/alex/Downloads/new-pr/ai_env/lib/python3.12/site-packages/uvicorn/_subprocess.py", line 80, in subprocess_started
    target(sockets=sockets)
  File "/home/alex/Downloads/new-pr/ai_env/lib/python3.12/site-packages/uvicorn/server.py", line 67, in run
    return asyncio.run(self.serve(sockets=sockets))
           ^^^^^^^^^^^^^^^^^^^^^^^^^^^^^^^^^^^^^^^^
  File "/usr/lib/python3.12/asyncio/runners.py", line 194, in run
    return runner.run(main)
           ^^^^^^^^^^^^^^^^
  File "/usr/lib/python3.12/asyncio/runners.py", line 118, in run
    return self._loop.run_until_complete(task)
           ^^^^^^^^^^^^^^^^^^^^^^^^^^^^^^^^^^^
  File "/usr/lib/python3.12/asyncio/base_events.py", line 687, in run_until_complete
    return future.result()
           ^^^^^^^^^^^^^^^
  File "/home/alex/Downloads/new-pr/ai_env/lib/python3.12/site-packages/uvicorn/server.py", line 71, in serve
    await self._serve(sockets)
  File "/home/alex/Downloads/new-pr/ai_env/lib/python3.12/site-packages/uvicorn/server.py", line 86, in _serve
    await self.startup(sockets=sockets)
  File "/home/alex/Downloads/new-pr/ai_env/lib/python3.12/site-packages/uvicorn/server.py", line 136, in startup
    server = await loop.create_server(create_protocol, sock=sock, ssl=config.ssl, backlog=config.backlog)
             ^^^^^^^^^^^^^^^^^^^^^^^^^^^^^^^^^^^^^^^^^^^^^^^^^^^^^^^^^^^^^^^^^^^^^^^^^^^^^^^^^^^^^^^^^^^^
  File "/usr/lib/python3.12/asyncio/base_events.py", line 1597, in create_server
    server._start_serving()
  File "/usr/lib/python3.12/asyncio/base_events.py", line 317, in _start_serving
    sock.listen(self._backlog)
OSError: [Errno 98] Address already in use
INFO:     Started server process [34921]
INFO:     Waiting for application startup.
INFO:     Application startup complete.
INFO:     127.0.0.1:42328 - "WebSocket /ws" [accepted]
INFO:     connection open
WARNING:  StatReload detected changes in 'app/config.py'. Reloading...
INFO:     Shutting down
INFO:     connection closed
WARNING:  StatReload detected changes in 'app/config.py'. Reloading...
INFO:     Waiting for application shutdown.
INFO:     Application shutdown complete.
INFO:     Finished server process [34921]
WARNING:  StatReload detected changes in 'app/config.py'. Reloading...
Process SpawnProcess-10:
Traceback (most recent call last):
  File "/usr/lib/python3.12/multiprocessing/process.py", line 314, in _bootstrap
    self.run()
  File "/usr/lib/python3.12/multiprocessing/process.py", line 108, in run
    self._target(*self._args, **self._kwargs)
  File "/home/alex/Downloads/new-pr/ai_env/lib/python3.12/site-packages/uvicorn/_subprocess.py", line 80, in subprocess_started
    target(sockets=sockets)
  File "/home/alex/Downloads/new-pr/ai_env/lib/python3.12/site-packages/uvicorn/server.py", line 67, in run
    return asyncio.run(self.serve(sockets=sockets))
           ^^^^^^^^^^^^^^^^^^^^^^^^^^^^^^^^^^^^^^^^
  File "/usr/lib/python3.12/asyncio/runners.py", line 194, in run
    return runner.run(main)
           ^^^^^^^^^^^^^^^^
  File "/usr/lib/python3.12/asyncio/runners.py", line 118, in run
    return self._loop.run_until_complete(task)
           ^^^^^^^^^^^^^^^^^^^^^^^^^^^^^^^^^^^
  File "/usr/lib/python3.12/asyncio/base_events.py", line 687, in run_until_complete
    return future.result()
           ^^^^^^^^^^^^^^^
  File "/home/alex/Downloads/new-pr/ai_env/lib/python3.12/site-packages/uvicorn/server.py", line 71, in serve
    await self._serve(sockets)
  File "/home/alex/Downloads/new-pr/ai_env/lib/python3.12/site-packages/uvicorn/server.py", line 78, in _serve
    config.load()
  File "/home/alex/Downloads/new-pr/ai_env/lib/python3.12/site-packages/uvicorn/config.py", line 436, in load
    self.loaded_app = import_from_string(self.app)
                      ^^^^^^^^^^^^^^^^^^^^^^^^^^^^
  File "/home/alex/Downloads/new-pr/ai_env/lib/python3.12/site-packages/uvicorn/importer.py", line 19, in import_from_string
    module = importlib.import_module(module_str)
             ^^^^^^^^^^^^^^^^^^^^^^^^^^^^^^^^^^^
  File "/usr/lib/python3.12/importlib/__init__.py", line 90, in import_module
    return _bootstrap._gcd_import(name[level:], package, level)
           ^^^^^^^^^^^^^^^^^^^^^^^^^^^^^^^^^^^^^^^^^^^^^^^^^^^^
  File "<frozen importlib._bootstrap>", line 1387, in _gcd_import
  File "<frozen importlib._bootstrap>", line 1360, in _find_and_load
  File "<frozen importlib._bootstrap>", line 1331, in _find_and_load_unlocked
  File "<frozen importlib._bootstrap>", line 935, in _load_unlocked
  File "<frozen importlib._bootstrap_external>", line 995, in exec_module
  File "<frozen importlib._bootstrap>", line 488, in _call_with_frames_removed
  File "/home/alex/Downloads/new-pr/backend/app/main.py", line 21, in <module>
    from .config import settings
  File "/home/alex/Downloads/new-pr/backend/app/config.py", line 13, in <module>
    from pydantic import BaseSettings, validator, ConfigDict
  File "/home/alex/Downloads/new-pr/ai_env/lib/python3.12/site-packages/pydantic/__init__.py", line 426, in __getattr__
    return _getattr_migration(attr_name)
           ^^^^^^^^^^^^^^^^^^^^^^^^^^^^^
  File "/home/alex/Downloads/new-pr/ai_env/lib/python3.12/site-packages/pydantic/_migration.py", line 296, in wrapper
    raise PydanticImportError(
pydantic.errors.PydanticImportError: `BaseSettings` has been moved to the `pydantic-settings` package. See https://docs.pydantic.dev/2.11/migration/#basesettings-has-moved-to-pydantic-settings for more details.

For further information visit https://errors.pydantic.dev/2.11/u/import-error
Process SpawnProcess-9:
Traceback (most recent call last):
  File "/usr/lib/python3.12/multiprocessing/process.py", line 314, in _bootstrap
    self.run()
  File "/usr/lib/python3.12/multiprocessing/process.py", line 108, in run
    self._target(*self._args, **self._kwargs)
  File "/home/alex/Downloads/new-pr/ai_env/lib/python3.12/site-packages/uvicorn/_subprocess.py", line 80, in subprocess_started
    target(sockets=sockets)
  File "/home/alex/Downloads/new-pr/ai_env/lib/python3.12/site-packages/uvicorn/server.py", line 67, in run
    return asyncio.run(self.serve(sockets=sockets))
           ^^^^^^^^^^^^^^^^^^^^^^^^^^^^^^^^^^^^^^^^
  File "/usr/lib/python3.12/asyncio/runners.py", line 194, in run
    return runner.run(main)
           ^^^^^^^^^^^^^^^^
  File "/usr/lib/python3.12/asyncio/runners.py", line 118, in run
    return self._loop.run_until_complete(task)
           ^^^^^^^^^^^^^^^^^^^^^^^^^^^^^^^^^^^
  File "/usr/lib/python3.12/asyncio/base_events.py", line 687, in run_until_complete
    return future.result()
           ^^^^^^^^^^^^^^^
  File "/home/alex/Downloads/new-pr/ai_env/lib/python3.12/site-packages/uvicorn/server.py", line 71, in serve
    await self._serve(sockets)
  File "/home/alex/Downloads/new-pr/ai_env/lib/python3.12/site-packages/uvicorn/server.py", line 78, in _serve
    config.load()
  File "/home/alex/Downloads/new-pr/ai_env/lib/python3.12/site-packages/uvicorn/config.py", line 436, in load
    self.loaded_app = import_from_string(self.app)
                      ^^^^^^^^^^^^^^^^^^^^^^^^^^^^
  File "/home/alex/Downloads/new-pr/ai_env/lib/python3.12/site-packages/uvicorn/importer.py", line 19, in import_from_string
    module = importlib.import_module(module_str)
             ^^^^^^^^^^^^^^^^^^^^^^^^^^^^^^^^^^^
  File "/usr/lib/python3.12/importlib/__init__.py", line 90, in import_module
    return _bootstrap._gcd_import(name[level:], package, level)
           ^^^^^^^^^^^^^^^^^^^^^^^^^^^^^^^^^^^^^^^^^^^^^^^^^^^^
  File "<frozen importlib._bootstrap>", line 1387, in _gcd_import
  File "<frozen importlib._bootstrap>", line 1360, in _find_and_load
  File "<frozen importlib._bootstrap>", line 1331, in _find_and_load_unlocked
  File "<frozen importlib._bootstrap>", line 935, in _load_unlocked
  File "<frozen importlib._bootstrap_external>", line 995, in exec_module
  File "<frozen importlib._bootstrap>", line 488, in _call_with_frames_removed
  File "/home/alex/Downloads/new-pr/backend/app/main.py", line 21, in <module>
    from .config import settings
  File "/home/alex/Downloads/new-pr/backend/app/config.py", line 13, in <module>
    from pydantic import BaseSettings, validator, ConfigDict
  File "/home/alex/Downloads/new-pr/ai_env/lib/python3.12/site-packages/pydantic/__init__.py", line 426, in __getattr__
    return _getattr_migration(attr_name)
           ^^^^^^^^^^^^^^^^^^^^^^^^^^^^^
  File "/home/alex/Downloads/new-pr/ai_env/lib/python3.12/site-packages/pydantic/_migration.py", line 296, in wrapper
    raise PydanticImportError(
pydantic.errors.PydanticImportError: `BaseSettings` has been moved to the `pydantic-settings` package. See https://docs.pydantic.dev/2.11/migration/#basesettings-has-moved-to-pydantic-settings for more details.

For further information visit https://errors.pydantic.dev/2.11/u/import-error
Process SpawnProcess-3:
Traceback (most recent call last):
  File "/usr/lib/python3.12/multiprocessing/process.py", line 314, in _bootstrap
    self.run()
  File "/usr/lib/python3.12/multiprocessing/process.py", line 108, in run
    self._target(*self._args, **self._kwargs)
  File "/home/alex/Downloads/new-pr/ai_env/lib/python3.12/site-packages/uvicorn/_subprocess.py", line 80, in subprocess_started
    target(sockets=sockets)
  File "/home/alex/Downloads/new-pr/ai_env/lib/python3.12/site-packages/uvicorn/server.py", line 67, in run
    return asyncio.run(self.serve(sockets=sockets))
           ^^^^^^^^^^^^^^^^^^^^^^^^^^^^^^^^^^^^^^^^
  File "/usr/lib/python3.12/asyncio/runners.py", line 194, in run
    return runner.run(main)
           ^^^^^^^^^^^^^^^^
  File "/usr/lib/python3.12/asyncio/runners.py", line 118, in run
    return self._loop.run_until_complete(task)
           ^^^^^^^^^^^^^^^^^^^^^^^^^^^^^^^^^^^
  File "/usr/lib/python3.12/asyncio/base_events.py", line 687, in run_until_complete
    return future.result()
           ^^^^^^^^^^^^^^^
  File "/home/alex/Downloads/new-pr/ai_env/lib/python3.12/site-packages/uvicorn/server.py", line 71, in serve
    await self._serve(sockets)
  File "/home/alex/Downloads/new-pr/ai_env/lib/python3.12/site-packages/uvicorn/server.py", line 78, in _serve
    config.load()
  File "/home/alex/Downloads/new-pr/ai_env/lib/python3.12/site-packages/uvicorn/config.py", line 436, in load
    self.loaded_app = import_from_string(self.app)
                      ^^^^^^^^^^^^^^^^^^^^^^^^^^^^
  File "/home/alex/Downloads/new-pr/ai_env/lib/python3.12/site-packages/uvicorn/importer.py", line 19, in import_from_string
    module = importlib.import_module(module_str)
             ^^^^^^^^^^^^^^^^^^^^^^^^^^^^^^^^^^^
  File "/usr/lib/python3.12/importlib/__init__.py", line 90, in import_module
    return _bootstrap._gcd_import(name[level:], package, level)
           ^^^^^^^^^^^^^^^^^^^^^^^^^^^^^^^^^^^^^^^^^^^^^^^^^^^^
  File "<frozen importlib._bootstrap>", line 1387, in _gcd_import
  File "<frozen importlib._bootstrap>", line 1360, in _find_and_load
  File "<frozen importlib._bootstrap>", line 1331, in _find_and_load_unlocked
  File "<frozen importlib._bootstrap>", line 935, in _load_unlocked
  File "<frozen importlib._bootstrap_external>", line 995, in exec_module
  File "<frozen importlib._bootstrap>", line 488, in _call_with_frames_removed
  File "/home/alex/Downloads/new-pr/backend/app/main.py", line 21, in <module>
    from .config import settings
  File "/home/alex/Downloads/new-pr/backend/app/config.py", line 13, in <module>
    from pydantic import BaseSettings, validator, ConfigDict
  File "/home/alex/Downloads/new-pr/ai_env/lib/python3.12/site-packages/pydantic/__init__.py", line 426, in __getattr__
    return _getattr_migration(attr_name)
           ^^^^^^^^^^^^^^^^^^^^^^^^^^^^^
  File "/home/alex/Downloads/new-pr/ai_env/lib/python3.12/site-packages/pydantic/_migration.py", line 296, in wrapper
    raise PydanticImportError(
pydantic.errors.PydanticImportError: `BaseSettings` has been moved to the `pydantic-settings` package. See https://docs.pydantic.dev/2.11/migration/#basesettings-has-moved-to-pydantic-settings for more details.

For further information visit https://errors.pydantic.dev/2.11/u/import-error
WARNING:  StatReload detected changes in 'app/config.py'. Reloading...
WARNING:  StatReload detected changes in 'app/config.py'. Reloading...
WARNING:  StatReload detected changes in 'app/config.py'. Reloading...
Process SpawnProcess-11:
Traceback (most recent call last):
  File "/usr/lib/python3.12/multiprocessing/process.py", line 314, in _bootstrap
    self.run()
  File "/usr/lib/python3.12/multiprocessing/process.py", line 108, in run
    self._target(*self._args, **self._kwargs)
  File "/home/alex/Downloads/new-pr/ai_env/lib/python3.12/site-packages/uvicorn/_subprocess.py", line 80, in subprocess_started
    target(sockets=sockets)
  File "/home/alex/Downloads/new-pr/ai_env/lib/python3.12/site-packages/uvicorn/server.py", line 67, in run
    return asyncio.run(self.serve(sockets=sockets))
           ^^^^^^^^^^^^^^^^^^^^^^^^^^^^^^^^^^^^^^^^
  File "/usr/lib/python3.12/asyncio/runners.py", line 194, in run
    return runner.run(main)
           ^^^^^^^^^^^^^^^^
  File "/usr/lib/python3.12/asyncio/runners.py", line 118, in run
    return self._loop.run_until_complete(task)
           ^^^^^^^^^^^^^^^^^^^^^^^^^^^^^^^^^^^
  File "/usr/lib/python3.12/asyncio/base_events.py", line 687, in run_until_complete
    return future.result()
           ^^^^^^^^^^^^^^^
  File "/home/alex/Downloads/new-pr/ai_env/lib/python3.12/site-packages/uvicorn/server.py", line 71, in serve
    await self._serve(sockets)
  File "/home/alex/Downloads/new-pr/ai_env/lib/python3.12/site-packages/uvicorn/server.py", line 78, in _serve
    config.load()
  File "/home/alex/Downloads/new-pr/ai_env/lib/python3.12/site-packages/uvicorn/config.py", line 436, in load
    self.loaded_app = import_from_string(self.app)
                      ^^^^^^^^^^^^^^^^^^^^^^^^^^^^
  File "/home/alex/Downloads/new-pr/ai_env/lib/python3.12/site-packages/uvicorn/importer.py", line 19, in import_from_string
    module = importlib.import_module(module_str)
             ^^^^^^^^^^^^^^^^^^^^^^^^^^^^^^^^^^^
  File "/usr/lib/python3.12/importlib/__init__.py", line 90, in import_module
    return _bootstrap._gcd_import(name[level:], package, level)
           ^^^^^^^^^^^^^^^^^^^^^^^^^^^^^^^^^^^^^^^^^^^^^^^^^^^^
  File "<frozen importlib._bootstrap>", line 1387, in _gcd_import
  File "<frozen importlib._bootstrap>", line 1360, in _find_and_load
  File "<frozen importlib._bootstrap>", line 1331, in _find_and_load_unlocked
  File "<frozen importlib._bootstrap>", line 935, in _load_unlocked
  File "<frozen importlib._bootstrap_external>", line 995, in exec_module
  File "<frozen importlib._bootstrap>", line 488, in _call_with_frames_removed
  File "/home/alex/Downloads/new-pr/backend/app/main.py", line 21, in <module>
    from .config import settings
  File "/home/alex/Downloads/new-pr/backend/app/config.py", line 13, in <module>
    from pydantic import BaseSettings, validator
  File "/home/alex/Downloads/new-pr/ai_env/lib/python3.12/site-packages/pydantic/__init__.py", line 426, in __getattr__
    return _getattr_migration(attr_name)
           ^^^^^^^^^^^^^^^^^^^^^^^^^^^^^
  File "/home/alex/Downloads/new-pr/ai_env/lib/python3.12/site-packages/pydantic/_migration.py", line 296, in wrapper
    raise PydanticImportError(
pydantic.errors.PydanticImportError: `BaseSettings` has been moved to the `pydantic-settings` package. See https://docs.pydantic.dev/2.11/migration/#basesettings-has-moved-to-pydantic-settings for more details.

For further information visit https://errors.pydantic.dev/2.11/u/import-error
Process SpawnProcess-4:
Traceback (most recent call last):
  File "/usr/lib/python3.12/multiprocessing/process.py", line 314, in _bootstrap
    self.run()
  File "/usr/lib/python3.12/multiprocessing/process.py", line 108, in run
    self._target(*self._args, **self._kwargs)
  File "/home/alex/Downloads/new-pr/ai_env/lib/python3.12/site-packages/uvicorn/_subprocess.py", line 80, in subprocess_started
    target(sockets=sockets)
  File "/home/alex/Downloads/new-pr/ai_env/lib/python3.12/site-packages/uvicorn/server.py", line 67, in run
    return asyncio.run(self.serve(sockets=sockets))
           ^^^^^^^^^^^^^^^^^^^^^^^^^^^^^^^^^^^^^^^^
  File "/usr/lib/python3.12/asyncio/runners.py", line 194, in run
    return runner.run(main)
           ^^^^^^^^^^^^^^^^
  File "/usr/lib/python3.12/asyncio/runners.py", line 118, in run
    return self._loop.run_until_complete(task)
           ^^^^^^^^^^^^^^^^^^^^^^^^^^^^^^^^^^^
  File "/usr/lib/python3.12/asyncio/base_events.py", line 687, in run_until_complete
    return future.result()
           ^^^^^^^^^^^^^^^
  File "/home/alex/Downloads/new-pr/ai_env/lib/python3.12/site-packages/uvicorn/server.py", line 71, in serve
    await self._serve(sockets)
  File "/home/alex/Downloads/new-pr/ai_env/lib/python3.12/site-packages/uvicorn/server.py", line 78, in _serve
    config.load()
  File "/home/alex/Downloads/new-pr/ai_env/lib/python3.12/site-packages/uvicorn/config.py", line 436, in load
    self.loaded_app = import_from_string(self.app)
                      ^^^^^^^^^^^^^^^^^^^^^^^^^^^^
  File "/home/alex/Downloads/new-pr/ai_env/lib/python3.12/site-packages/uvicorn/importer.py", line 19, in import_from_string
    module = importlib.import_module(module_str)
             ^^^^^^^^^^^^^^^^^^^^^^^^^^^^^^^^^^^
  File "/usr/lib/python3.12/importlib/__init__.py", line 90, in import_module
    return _bootstrap._gcd_import(name[level:], package, level)
           ^^^^^^^^^^^^^^^^^^^^^^^^^^^^^^^^^^^^^^^^^^^^^^^^^^^^
  File "<frozen importlib._bootstrap>", line 1387, in _gcd_import
  File "<frozen importlib._bootstrap>", line 1360, in _find_and_load
  File "<frozen importlib._bootstrap>", line 1331, in _find_and_load_unlocked
  File "<frozen importlib._bootstrap>", line 935, in _load_unlocked
  File "<frozen importlib._bootstrap_external>", line 995, in exec_module
  File "<frozen importlib._bootstrap>", line 488, in _call_with_frames_removed
  File "/home/alex/Downloads/new-pr/backend/app/main.py", line 21, in <module>
    from .config import settings
  File "/home/alex/Downloads/new-pr/backend/app/config.py", line 13, in <module>
    from pydantic import BaseSettings, validator
  File "/home/alex/Downloads/new-pr/ai_env/lib/python3.12/site-packages/pydantic/__init__.py", line 426, in __getattr__
    return _getattr_migration(attr_name)
           ^^^^^^^^^^^^^^^^^^^^^^^^^^^^^
  File "/home/alex/Downloads/new-pr/ai_env/lib/python3.12/site-packages/pydantic/_migration.py", line 296, in wrapper
    raise PydanticImportError(
pydantic.errors.PydanticImportError: `BaseSettings` has been moved to the `pydantic-settings` package. See https://docs.pydantic.dev/2.11/migration/#basesettings-has-moved-to-pydantic-settings for more details.

For further information visit https://errors.pydantic.dev/2.11/u/import-error
Process SpawnProcess-10:
Traceback (most recent call last):
  File "/usr/lib/python3.12/multiprocessing/process.py", line 314, in _bootstrap
    self.run()
  File "/usr/lib/python3.12/multiprocessing/process.py", line 108, in run
    self._target(*self._args, **self._kwargs)
  File "/home/alex/Downloads/new-pr/ai_env/lib/python3.12/site-packages/uvicorn/_subprocess.py", line 80, in subprocess_started
    target(sockets=sockets)
  File "/home/alex/Downloads/new-pr/ai_env/lib/python3.12/site-packages/uvicorn/server.py", line 67, in run
    return asyncio.run(self.serve(sockets=sockets))
           ^^^^^^^^^^^^^^^^^^^^^^^^^^^^^^^^^^^^^^^^
  File "/usr/lib/python3.12/asyncio/runners.py", line 194, in run
    return runner.run(main)
           ^^^^^^^^^^^^^^^^
  File "/usr/lib/python3.12/asyncio/runners.py", line 118, in run
    return self._loop.run_until_complete(task)
           ^^^^^^^^^^^^^^^^^^^^^^^^^^^^^^^^^^^
  File "/usr/lib/python3.12/asyncio/base_events.py", line 687, in run_until_complete
    return future.result()
           ^^^^^^^^^^^^^^^
  File "/home/alex/Downloads/new-pr/ai_env/lib/python3.12/site-packages/uvicorn/server.py", line 71, in serve
    await self._serve(sockets)
  File "/home/alex/Downloads/new-pr/ai_env/lib/python3.12/site-packages/uvicorn/server.py", line 78, in _serve
    config.load()
  File "/home/alex/Downloads/new-pr/ai_env/lib/python3.12/site-packages/uvicorn/config.py", line 436, in load
    self.loaded_app = import_from_string(self.app)
                      ^^^^^^^^^^^^^^^^^^^^^^^^^^^^
  File "/home/alex/Downloads/new-pr/ai_env/lib/python3.12/site-packages/uvicorn/importer.py", line 19, in import_from_string
    module = importlib.import_module(module_str)
             ^^^^^^^^^^^^^^^^^^^^^^^^^^^^^^^^^^^
  File "/usr/lib/python3.12/importlib/__init__.py", line 90, in import_module
    return _bootstrap._gcd_import(name[level:], package, level)
           ^^^^^^^^^^^^^^^^^^^^^^^^^^^^^^^^^^^^^^^^^^^^^^^^^^^^
  File "<frozen importlib._bootstrap>", line 1387, in _gcd_import
  File "<frozen importlib._bootstrap>", line 1360, in _find_and_load
  File "<frozen importlib._bootstrap>", line 1331, in _find_and_load_unlocked
  File "<frozen importlib._bootstrap>", line 935, in _load_unlocked
  File "<frozen importlib._bootstrap_external>", line 995, in exec_module
  File "<frozen importlib._bootstrap>", line 488, in _call_with_frames_removed
  File "/home/alex/Downloads/new-pr/backend/app/main.py", line 21, in <module>
    from .config import settings
  File "/home/alex/Downloads/new-pr/backend/app/config.py", line 13, in <module>
    from pydantic import BaseSettings, validator
  File "/home/alex/Downloads/new-pr/ai_env/lib/python3.12/site-packages/pydantic/__init__.py", line 426, in __getattr__
    return _getattr_migration(attr_name)
           ^^^^^^^^^^^^^^^^^^^^^^^^^^^^^
  File "/home/alex/Downloads/new-pr/ai_env/lib/python3.12/site-packages/pydantic/_migration.py", line 296, in wrapper
    raise PydanticImportError(
pydantic.errors.PydanticImportError: `BaseSettings` has been moved to the `pydantic-settings` package. See https://docs.pydantic.dev/2.11/migration/#basesettings-has-moved-to-pydantic-settings for more details.

For further information visit https://errors.pydantic.dev/2.11/u/import-error
WARNING:  StatReload detected changes in 'app/config.py'. Reloading...
WARNING:  StatReload detected changes in 'app/config.py'. Reloading...
WARNING:  StatReload detected changes in 'app/config.py'. Reloading...
Process SpawnProcess-12:
Traceback (most recent call last):
  File "/usr/lib/python3.12/multiprocessing/process.py", line 314, in _bootstrap
    self.run()
  File "/usr/lib/python3.12/multiprocessing/process.py", line 108, in run
    self._target(*self._args, **self._kwargs)
  File "/home/alex/Downloads/new-pr/ai_env/lib/python3.12/site-packages/uvicorn/_subprocess.py", line 80, in subprocess_started
    target(sockets=sockets)
  File "/home/alex/Downloads/new-pr/ai_env/lib/python3.12/site-packages/uvicorn/server.py", line 67, in run
    return asyncio.run(self.serve(sockets=sockets))
           ^^^^^^^^^^^^^^^^^^^^^^^^^^^^^^^^^^^^^^^^
  File "/usr/lib/python3.12/asyncio/runners.py", line 194, in run
    return runner.run(main)
           ^^^^^^^^^^^^^^^^
  File "/usr/lib/python3.12/asyncio/runners.py", line 118, in run
    return self._loop.run_until_complete(task)
           ^^^^^^^^^^^^^^^^^^^^^^^^^^^^^^^^^^^
  File "/usr/lib/python3.12/asyncio/base_events.py", line 687, in run_until_complete
    return future.result()
           ^^^^^^^^^^^^^^^
  File "/home/alex/Downloads/new-pr/ai_env/lib/python3.12/site-packages/uvicorn/server.py", line 71, in serve
    await self._serve(sockets)
  File "/home/alex/Downloads/new-pr/ai_env/lib/python3.12/site-packages/uvicorn/server.py", line 78, in _serve
    config.load()
  File "/home/alex/Downloads/new-pr/ai_env/lib/python3.12/site-packages/uvicorn/config.py", line 436, in load
    self.loaded_app = import_from_string(self.app)
                      ^^^^^^^^^^^^^^^^^^^^^^^^^^^^
  File "/home/alex/Downloads/new-pr/ai_env/lib/python3.12/site-packages/uvicorn/importer.py", line 19, in import_from_string
    module = importlib.import_module(module_str)
             ^^^^^^^^^^^^^^^^^^^^^^^^^^^^^^^^^^^
  File "/usr/lib/python3.12/importlib/__init__.py", line 90, in import_module
    return _bootstrap._gcd_import(name[level:], package, level)
           ^^^^^^^^^^^^^^^^^^^^^^^^^^^^^^^^^^^^^^^^^^^^^^^^^^^^
  File "<frozen importlib._bootstrap>", line 1387, in _gcd_import
  File "<frozen importlib._bootstrap>", line 1360, in _find_and_load
  File "<frozen importlib._bootstrap>", line 1331, in _find_and_load_unlocked
  File "<frozen importlib._bootstrap>", line 935, in _load_unlocked
  File "<frozen importlib._bootstrap_external>", line 995, in exec_module
  File "<frozen importlib._bootstrap>", line 488, in _call_with_frames_removed
  File "/home/alex/Downloads/new-pr/backend/app/main.py", line 21, in <module>
    from .config import settings
  File "/home/alex/Downloads/new-pr/backend/app/config.py", line 13, in <module>
    from pydantic import BaseSettings, validator
  File "/home/alex/Downloads/new-pr/ai_env/lib/python3.12/site-packages/pydantic/__init__.py", line 426, in __getattr__
    return _getattr_migration(attr_name)
           ^^^^^^^^^^^^^^^^^^^^^^^^^^^^^
  File "/home/alex/Downloads/new-pr/ai_env/lib/python3.12/site-packages/pydantic/_migration.py", line 296, in wrapper
    raise PydanticImportError(
pydantic.errors.PydanticImportError: `BaseSettings` has been moved to the `pydantic-settings` package. See https://docs.pydantic.dev/2.11/migration/#basesettings-has-moved-to-pydantic-settings for more details.

For further information visit https://errors.pydantic.dev/2.11/u/import-error
Process SpawnProcess-11:
Traceback (most recent call last):
  File "/usr/lib/python3.12/multiprocessing/process.py", line 314, in _bootstrap
    self.run()
  File "/usr/lib/python3.12/multiprocessing/process.py", line 108, in run
    self._target(*self._args, **self._kwargs)
  File "/home/alex/Downloads/new-pr/ai_env/lib/python3.12/site-packages/uvicorn/_subprocess.py", line 80, in subprocess_started
    target(sockets=sockets)
  File "/home/alex/Downloads/new-pr/ai_env/lib/python3.12/site-packages/uvicorn/server.py", line 67, in run
    return asyncio.run(self.serve(sockets=sockets))
           ^^^^^^^^^^^^^^^^^^^^^^^^^^^^^^^^^^^^^^^^
  File "/usr/lib/python3.12/asyncio/runners.py", line 194, in run
    return runner.run(main)
           ^^^^^^^^^^^^^^^^
  File "/usr/lib/python3.12/asyncio/runners.py", line 118, in run
    return self._loop.run_until_complete(task)
           ^^^^^^^^^^^^^^^^^^^^^^^^^^^^^^^^^^^
  File "/usr/lib/python3.12/asyncio/base_events.py", line 687, in run_until_complete
    return future.result()
           ^^^^^^^^^^^^^^^
  File "/home/alex/Downloads/new-pr/ai_env/lib/python3.12/site-packages/uvicorn/server.py", line 71, in serve
    await self._serve(sockets)
  File "/home/alex/Downloads/new-pr/ai_env/lib/python3.12/site-packages/uvicorn/server.py", line 78, in _serve
    config.load()
  File "/home/alex/Downloads/new-pr/ai_env/lib/python3.12/site-packages/uvicorn/config.py", line 436, in load
    self.loaded_app = import_from_string(self.app)
                      ^^^^^^^^^^^^^^^^^^^^^^^^^^^^
  File "/home/alex/Downloads/new-pr/ai_env/lib/python3.12/site-packages/uvicorn/importer.py", line 19, in import_from_string
    module = importlib.import_module(module_str)
             ^^^^^^^^^^^^^^^^^^^^^^^^^^^^^^^^^^^
  File "/usr/lib/python3.12/importlib/__init__.py", line 90, in import_module
    return _bootstrap._gcd_import(name[level:], package, level)
           ^^^^^^^^^^^^^^^^^^^^^^^^^^^^^^^^^^^^^^^^^^^^^^^^^^^^
  File "<frozen importlib._bootstrap>", line 1387, in _gcd_import
  File "<frozen importlib._bootstrap>", line 1360, in _find_and_load
  File "<frozen importlib._bootstrap>", line 1331, in _find_and_load_unlocked
  File "<frozen importlib._bootstrap>", line 935, in _load_unlocked
  File "<frozen importlib._bootstrap_external>", line 995, in exec_module
  File "<frozen importlib._bootstrap>", line 488, in _call_with_frames_removed
  File "/home/alex/Downloads/new-pr/backend/app/main.py", line 21, in <module>
    from .config import settings
  File "/home/alex/Downloads/new-pr/backend/app/config.py", line 13, in <module>
    from pydantic import BaseSettings, validator
  File "/home/alex/Downloads/new-pr/ai_env/lib/python3.12/site-packages/pydantic/__init__.py", line 426, in __getattr__
    return _getattr_migration(attr_name)
           ^^^^^^^^^^^^^^^^^^^^^^^^^^^^^
  File "/home/alex/Downloads/new-pr/ai_env/lib/python3.12/site-packages/pydantic/_migration.py", line 296, in wrapper
    raise PydanticImportError(
pydantic.errors.PydanticImportError: `BaseSettings` has been moved to the `pydantic-settings` package. See https://docs.pydantic.dev/2.11/migration/#basesettings-has-moved-to-pydantic-settings for more details.

For further information visit https://errors.pydantic.dev/2.11/u/import-error
Process SpawnProcess-5:
Traceback (most recent call last):
  File "/usr/lib/python3.12/multiprocessing/process.py", line 314, in _bootstrap
    self.run()
  File "/usr/lib/python3.12/multiprocessing/process.py", line 108, in run
    self._target(*self._args, **self._kwargs)
  File "/home/alex/Downloads/new-pr/ai_env/lib/python3.12/site-packages/uvicorn/_subprocess.py", line 80, in subprocess_started
    target(sockets=sockets)
  File "/home/alex/Downloads/new-pr/ai_env/lib/python3.12/site-packages/uvicorn/server.py", line 67, in run
    return asyncio.run(self.serve(sockets=sockets))
           ^^^^^^^^^^^^^^^^^^^^^^^^^^^^^^^^^^^^^^^^
  File "/usr/lib/python3.12/asyncio/runners.py", line 194, in run
    return runner.run(main)
           ^^^^^^^^^^^^^^^^
  File "/usr/lib/python3.12/asyncio/runners.py", line 118, in run
    return self._loop.run_until_complete(task)
           ^^^^^^^^^^^^^^^^^^^^^^^^^^^^^^^^^^^
  File "/usr/lib/python3.12/asyncio/base_events.py", line 687, in run_until_complete
    return future.result()
           ^^^^^^^^^^^^^^^
  File "/home/alex/Downloads/new-pr/ai_env/lib/python3.12/site-packages/uvicorn/server.py", line 71, in serve
    await self._serve(sockets)
  File "/home/alex/Downloads/new-pr/ai_env/lib/python3.12/site-packages/uvicorn/server.py", line 78, in _serve
    config.load()
  File "/home/alex/Downloads/new-pr/ai_env/lib/python3.12/site-packages/uvicorn/config.py", line 436, in load
    self.loaded_app = import_from_string(self.app)
                      ^^^^^^^^^^^^^^^^^^^^^^^^^^^^
  File "/home/alex/Downloads/new-pr/ai_env/lib/python3.12/site-packages/uvicorn/importer.py", line 19, in import_from_string
    module = importlib.import_module(module_str)
             ^^^^^^^^^^^^^^^^^^^^^^^^^^^^^^^^^^^
  File "/usr/lib/python3.12/importlib/__init__.py", line 90, in import_module
    return _bootstrap._gcd_import(name[level:], package, level)
           ^^^^^^^^^^^^^^^^^^^^^^^^^^^^^^^^^^^^^^^^^^^^^^^^^^^^
  File "<frozen importlib._bootstrap>", line 1387, in _gcd_import
  File "<frozen importlib._bootstrap>", line 1360, in _find_and_load
  File "<frozen importlib._bootstrap>", line 1331, in _find_and_load_unlocked
  File "<frozen importlib._bootstrap>", line 935, in _load_unlocked
  File "<frozen importlib._bootstrap_external>", line 995, in exec_module
  File "<frozen importlib._bootstrap>", line 488, in _call_with_frames_removed
  File "/home/alex/Downloads/new-pr/backend/app/main.py", line 21, in <module>
    from .config import settings
  File "/home/alex/Downloads/new-pr/backend/app/config.py", line 13, in <module>
    from pydantic import BaseSettings, validator
  File "/home/alex/Downloads/new-pr/ai_env/lib/python3.12/site-packages/pydantic/__init__.py", line 426, in __getattr__
    return _getattr_migration(attr_name)
           ^^^^^^^^^^^^^^^^^^^^^^^^^^^^^
  File "/home/alex/Downloads/new-pr/ai_env/lib/python3.12/site-packages/pydantic/_migration.py", line 296, in wrapper
    raise PydanticImportError(
pydantic.errors.PydanticImportError: `BaseSettings` has been moved to the `pydantic-settings` package. See https://docs.pydantic.dev/2.11/migration/#basesettings-has-moved-to-pydantic-settings for more details.

For further information visit https://errors.pydantic.dev/2.11/u/import-error
WARNING:  StatReload detected changes in 'app/config.py'. Reloading...
WARNING:  StatReload detected changes in 'app/config.py'. Reloading...
WARNING:  StatReload detected changes in 'app/config.py'. Reloading...
Process SpawnProcess-13:
Traceback (most recent call last):
  File "/usr/lib/python3.12/multiprocessing/process.py", line 314, in _bootstrap
    self.run()
  File "/usr/lib/python3.12/multiprocessing/process.py", line 108, in run
    self._target(*self._args, **self._kwargs)
  File "/home/alex/Downloads/new-pr/ai_env/lib/python3.12/site-packages/uvicorn/_subprocess.py", line 80, in subprocess_started
    target(sockets=sockets)
  File "/home/alex/Downloads/new-pr/ai_env/lib/python3.12/site-packages/uvicorn/server.py", line 67, in run
    return asyncio.run(self.serve(sockets=sockets))
           ^^^^^^^^^^^^^^^^^^^^^^^^^^^^^^^^^^^^^^^^
  File "/usr/lib/python3.12/asyncio/runners.py", line 194, in run
    return runner.run(main)
           ^^^^^^^^^^^^^^^^
  File "/usr/lib/python3.12/asyncio/runners.py", line 118, in run
    return self._loop.run_until_complete(task)
           ^^^^^^^^^^^^^^^^^^^^^^^^^^^^^^^^^^^
  File "/usr/lib/python3.12/asyncio/base_events.py", line 687, in run_until_complete
    return future.result()
           ^^^^^^^^^^^^^^^
  File "/home/alex/Downloads/new-pr/ai_env/lib/python3.12/site-packages/uvicorn/server.py", line 71, in serve
    await self._serve(sockets)
  File "/home/alex/Downloads/new-pr/ai_env/lib/python3.12/site-packages/uvicorn/server.py", line 78, in _serve
    config.load()
  File "/home/alex/Downloads/new-pr/ai_env/lib/python3.12/site-packages/uvicorn/config.py", line 436, in load
    self.loaded_app = import_from_string(self.app)
                      ^^^^^^^^^^^^^^^^^^^^^^^^^^^^
  File "/home/alex/Downloads/new-pr/ai_env/lib/python3.12/site-packages/uvicorn/importer.py", line 19, in import_from_string
    module = importlib.import_module(module_str)
             ^^^^^^^^^^^^^^^^^^^^^^^^^^^^^^^^^^^
  File "/usr/lib/python3.12/importlib/__init__.py", line 90, in import_module
    return _bootstrap._gcd_import(name[level:], package, level)
           ^^^^^^^^^^^^^^^^^^^^^^^^^^^^^^^^^^^^^^^^^^^^^^^^^^^^
  File "<frozen importlib._bootstrap>", line 1387, in _gcd_import
  File "<frozen importlib._bootstrap>", line 1360, in _find_and_load
  File "<frozen importlib._bootstrap>", line 1331, in _find_and_load_unlocked
  File "<frozen importlib._bootstrap>", line 935, in _load_unlocked
  File "<frozen importlib._bootstrap_external>", line 995, in exec_module
  File "<frozen importlib._bootstrap>", line 488, in _call_with_frames_removed
  File "/home/alex/Downloads/new-pr/backend/app/main.py", line 21, in <module>
    from .config import settings
  File "/home/alex/Downloads/new-pr/backend/app/config.py", line 13, in <module>
    from pydantic import BaseSettings, validator
  File "/home/alex/Downloads/new-pr/ai_env/lib/python3.12/site-packages/pydantic/__init__.py", line 426, in __getattr__
    return _getattr_migration(attr_name)
           ^^^^^^^^^^^^^^^^^^^^^^^^^^^^^
  File "/home/alex/Downloads/new-pr/ai_env/lib/python3.12/site-packages/pydantic/_migration.py", line 296, in wrapper
    raise PydanticImportError(
pydantic.errors.PydanticImportError: `BaseSettings` has been moved to the `pydantic-settings` package. See https://docs.pydantic.dev/2.11/migration/#basesettings-has-moved-to-pydantic-settings for more details.

For further information visit https://errors.pydantic.dev/2.11/u/import-error
Process SpawnProcess-12:
Traceback (most recent call last):
  File "/usr/lib/python3.12/multiprocessing/process.py", line 314, in _bootstrap
    self.run()
  File "/usr/lib/python3.12/multiprocessing/process.py", line 108, in run
    self._target(*self._args, **self._kwargs)
  File "/home/alex/Downloads/new-pr/ai_env/lib/python3.12/site-packages/uvicorn/_subprocess.py", line 80, in subprocess_started
    target(sockets=sockets)
  File "/home/alex/Downloads/new-pr/ai_env/lib/python3.12/site-packages/uvicorn/server.py", line 67, in run
    return asyncio.run(self.serve(sockets=sockets))
           ^^^^^^^^^^^^^^^^^^^^^^^^^^^^^^^^^^^^^^^^
  File "/usr/lib/python3.12/asyncio/runners.py", line 194, in run
    return runner.run(main)
           ^^^^^^^^^^^^^^^^
  File "/usr/lib/python3.12/asyncio/runners.py", line 118, in run
    return self._loop.run_until_complete(task)
           ^^^^^^^^^^^^^^^^^^^^^^^^^^^^^^^^^^^
  File "/usr/lib/python3.12/asyncio/base_events.py", line 687, in run_until_complete
    return future.result()
           ^^^^^^^^^^^^^^^
  File "/home/alex/Downloads/new-pr/ai_env/lib/python3.12/site-packages/uvicorn/server.py", line 71, in serve
    await self._serve(sockets)
  File "/home/alex/Downloads/new-pr/ai_env/lib/python3.12/site-packages/uvicorn/server.py", line 78, in _serve
    config.load()
  File "/home/alex/Downloads/new-pr/ai_env/lib/python3.12/site-packages/uvicorn/config.py", line 436, in load
    self.loaded_app = import_from_string(self.app)
                      ^^^^^^^^^^^^^^^^^^^^^^^^^^^^
  File "/home/alex/Downloads/new-pr/ai_env/lib/python3.12/site-packages/uvicorn/importer.py", line 19, in import_from_string
    module = importlib.import_module(module_str)
             ^^^^^^^^^^^^^^^^^^^^^^^^^^^^^^^^^^^
  File "/usr/lib/python3.12/importlib/__init__.py", line 90, in import_module
    return _bootstrap._gcd_import(name[level:], package, level)
           ^^^^^^^^^^^^^^^^^^^^^^^^^^^^^^^^^^^^^^^^^^^^^^^^^^^^
  File "<frozen importlib._bootstrap>", line 1387, in _gcd_import
  File "<frozen importlib._bootstrap>", line 1360, in _find_and_load
  File "<frozen importlib._bootstrap>", line 1331, in _find_and_load_unlocked
  File "<frozen importlib._bootstrap>", line 935, in _load_unlocked
  File "<frozen importlib._bootstrap_external>", line 995, in exec_module
  File "<frozen importlib._bootstrap>", line 488, in _call_with_frames_removed
  File "/home/alex/Downloads/new-pr/backend/app/main.py", line 21, in <module>
    from .config import settings
  File "/home/alex/Downloads/new-pr/backend/app/config.py", line 13, in <module>
    from pydantic import BaseSettings, validator
  File "/home/alex/Downloads/new-pr/ai_env/lib/python3.12/site-packages/pydantic/__init__.py", line 426, in __getattr__
    return _getattr_migration(attr_name)
           ^^^^^^^^^^^^^^^^^^^^^^^^^^^^^
  File "/home/alex/Downloads/new-pr/ai_env/lib/python3.12/site-packages/pydantic/_migration.py", line 296, in wrapper
    raise PydanticImportError(
pydantic.errors.PydanticImportError: `BaseSettings` has been moved to the `pydantic-settings` package. See https://docs.pydantic.dev/2.11/migration/#basesettings-has-moved-to-pydantic-settings for more details.

For further information visit https://errors.pydantic.dev/2.11/u/import-error
Process SpawnProcess-6:
Traceback (most recent call last):
  File "/usr/lib/python3.12/multiprocessing/process.py", line 314, in _bootstrap
    self.run()
  File "/usr/lib/python3.12/multiprocessing/process.py", line 108, in run
    self._target(*self._args, **self._kwargs)
  File "/home/alex/Downloads/new-pr/ai_env/lib/python3.12/site-packages/uvicorn/_subprocess.py", line 80, in subprocess_started
    target(sockets=sockets)
  File "/home/alex/Downloads/new-pr/ai_env/lib/python3.12/site-packages/uvicorn/server.py", line 67, in run
    return asyncio.run(self.serve(sockets=sockets))
           ^^^^^^^^^^^^^^^^^^^^^^^^^^^^^^^^^^^^^^^^
  File "/usr/lib/python3.12/asyncio/runners.py", line 194, in run
    return runner.run(main)
           ^^^^^^^^^^^^^^^^
  File "/usr/lib/python3.12/asyncio/runners.py", line 118, in run
    return self._loop.run_until_complete(task)
           ^^^^^^^^^^^^^^^^^^^^^^^^^^^^^^^^^^^
  File "/usr/lib/python3.12/asyncio/base_events.py", line 687, in run_until_complete
    return future.result()
           ^^^^^^^^^^^^^^^
  File "/home/alex/Downloads/new-pr/ai_env/lib/python3.12/site-packages/uvicorn/server.py", line 71, in serve
    await self._serve(sockets)
  File "/home/alex/Downloads/new-pr/ai_env/lib/python3.12/site-packages/uvicorn/server.py", line 78, in _serve
    config.load()
  File "/home/alex/Downloads/new-pr/ai_env/lib/python3.12/site-packages/uvicorn/config.py", line 436, in load
    self.loaded_app = import_from_string(self.app)
                      ^^^^^^^^^^^^^^^^^^^^^^^^^^^^
  File "/home/alex/Downloads/new-pr/ai_env/lib/python3.12/site-packages/uvicorn/importer.py", line 19, in import_from_string
    module = importlib.import_module(module_str)
             ^^^^^^^^^^^^^^^^^^^^^^^^^^^^^^^^^^^
  File "/usr/lib/python3.12/importlib/__init__.py", line 90, in import_module
    return _bootstrap._gcd_import(name[level:], package, level)
           ^^^^^^^^^^^^^^^^^^^^^^^^^^^^^^^^^^^^^^^^^^^^^^^^^^^^
  File "<frozen importlib._bootstrap>", line 1387, in _gcd_import
  File "<frozen importlib._bootstrap>", line 1360, in _find_and_load
  File "<frozen importlib._bootstrap>", line 1331, in _find_and_load_unlocked
  File "<frozen importlib._bootstrap>", line 935, in _load_unlocked
  File "<frozen importlib._bootstrap_external>", line 995, in exec_module
  File "<frozen importlib._bootstrap>", line 488, in _call_with_frames_removed
  File "/home/alex/Downloads/new-pr/backend/app/main.py", line 21, in <module>
    from .config import settings
  File "/home/alex/Downloads/new-pr/backend/app/config.py", line 13, in <module>
    from pydantic import BaseSettings, validator
  File "/home/alex/Downloads/new-pr/ai_env/lib/python3.12/site-packages/pydantic/__init__.py", line 426, in __getattr__
    return _getattr_migration(attr_name)
           ^^^^^^^^^^^^^^^^^^^^^^^^^^^^^
  File "/home/alex/Downloads/new-pr/ai_env/lib/python3.12/site-packages/pydantic/_migration.py", line 296, in wrapper
    raise PydanticImportError(
pydantic.errors.PydanticImportError: `BaseSettings` has been moved to the `pydantic-settings` package. See https://docs.pydantic.dev/2.11/migration/#basesettings-has-moved-to-pydantic-settings for more details.

For further information visit https://errors.pydantic.dev/2.11/u/import-error
WARNING:  StatReload detected changes in 'app/config.py'. Reloading...
WARNING:  StatReload detected changes in 'app/config.py'. Reloading...
WARNING:  StatReload detected changes in 'app/config.py'. Reloading...
Process SpawnProcess-7:
Traceback (most recent call last):
  File "/usr/lib/python3.12/multiprocessing/process.py", line 314, in _bootstrap
    self.run()
  File "/usr/lib/python3.12/multiprocessing/process.py", line 108, in run
    self._target(*self._args, **self._kwargs)
  File "/home/alex/Downloads/new-pr/ai_env/lib/python3.12/site-packages/uvicorn/_subprocess.py", line 80, in subprocess_started
    target(sockets=sockets)
  File "/home/alex/Downloads/new-pr/ai_env/lib/python3.12/site-packages/uvicorn/server.py", line 67, in run
    return asyncio.run(self.serve(sockets=sockets))
           ^^^^^^^^^^^^^^^^^^^^^^^^^^^^^^^^^^^^^^^^
  File "/usr/lib/python3.12/asyncio/runners.py", line 194, in run
    return runner.run(main)
           ^^^^^^^^^^^^^^^^
  File "/usr/lib/python3.12/asyncio/runners.py", line 118, in run
    return self._loop.run_until_complete(task)
           ^^^^^^^^^^^^^^^^^^^^^^^^^^^^^^^^^^^
  File "/usr/lib/python3.12/asyncio/base_events.py", line 687, in run_until_complete
    return future.result()
           ^^^^^^^^^^^^^^^
  File "/home/alex/Downloads/new-pr/ai_env/lib/python3.12/site-packages/uvicorn/server.py", line 71, in serve
    await self._serve(sockets)
  File "/home/alex/Downloads/new-pr/ai_env/lib/python3.12/site-packages/uvicorn/server.py", line 78, in _serve
    config.load()
  File "/home/alex/Downloads/new-pr/ai_env/lib/python3.12/site-packages/uvicorn/config.py", line 436, in load
    self.loaded_app = import_from_string(self.app)
                      ^^^^^^^^^^^^^^^^^^^^^^^^^^^^
  File "/home/alex/Downloads/new-pr/ai_env/lib/python3.12/site-packages/uvicorn/importer.py", line 19, in import_from_string
    module = importlib.import_module(module_str)
             ^^^^^^^^^^^^^^^^^^^^^^^^^^^^^^^^^^^
  File "/usr/lib/python3.12/importlib/__init__.py", line 90, in import_module
    return _bootstrap._gcd_import(name[level:], package, level)
           ^^^^^^^^^^^^^^^^^^^^^^^^^^^^^^^^^^^^^^^^^^^^^^^^^^^^
  File "<frozen importlib._bootstrap>", line 1387, in _gcd_import
  File "<frozen importlib._bootstrap>", line 1360, in _find_and_load
  File "<frozen importlib._bootstrap>", line 1331, in _find_and_load_unlocked
  File "<frozen importlib._bootstrap>", line 935, in _load_unlocked
  File "<frozen importlib._bootstrap_external>", line 995, in exec_module
  File "<frozen importlib._bootstrap>", line 488, in _call_with_frames_removed
  File "/home/alex/Downloads/new-pr/backend/app/main.py", line 21, in <module>
    from .config import settings
  File "/home/alex/Downloads/new-pr/backend/app/config.py", line 13, in <module>
    from pydantic import BaseSettings, validator
  File "/home/alex/Downloads/new-pr/ai_env/lib/python3.12/site-packages/pydantic/__init__.py", line 426, in __getattr__
    return _getattr_migration(attr_name)
           ^^^^^^^^^^^^^^^^^^^^^^^^^^^^^
  File "/home/alex/Downloads/new-pr/ai_env/lib/python3.12/site-packages/pydantic/_migration.py", line 296, in wrapper
    raise PydanticImportError(
pydantic.errors.PydanticImportError: `BaseSettings` has been moved to the `pydantic-settings` package. See https://docs.pydantic.dev/2.11/migration/#basesettings-has-moved-to-pydantic-settings for more details.

For further information visit https://errors.pydantic.dev/2.11/u/import-error
Process SpawnProcess-14:
Traceback (most recent call last):
  File "/usr/lib/python3.12/multiprocessing/process.py", line 314, in _bootstrap
    self.run()
  File "/usr/lib/python3.12/multiprocessing/process.py", line 108, in run
    self._target(*self._args, **self._kwargs)
  File "/home/alex/Downloads/new-pr/ai_env/lib/python3.12/site-packages/uvicorn/_subprocess.py", line 80, in subprocess_started
    target(sockets=sockets)
  File "/home/alex/Downloads/new-pr/ai_env/lib/python3.12/site-packages/uvicorn/server.py", line 67, in run
    return asyncio.run(self.serve(sockets=sockets))
           ^^^^^^^^^^^^^^^^^^^^^^^^^^^^^^^^^^^^^^^^
  File "/usr/lib/python3.12/asyncio/runners.py", line 194, in run
    return runner.run(main)
           ^^^^^^^^^^^^^^^^
  File "/usr/lib/python3.12/asyncio/runners.py", line 118, in run
    return self._loop.run_until_complete(task)
           ^^^^^^^^^^^^^^^^^^^^^^^^^^^^^^^^^^^
  File "/usr/lib/python3.12/asyncio/base_events.py", line 687, in run_until_complete
    return future.result()
           ^^^^^^^^^^^^^^^
  File "/home/alex/Downloads/new-pr/ai_env/lib/python3.12/site-packages/uvicorn/server.py", line 71, in serve
    await self._serve(sockets)
  File "/home/alex/Downloads/new-pr/ai_env/lib/python3.12/site-packages/uvicorn/server.py", line 78, in _serve
    config.load()
  File "/home/alex/Downloads/new-pr/ai_env/lib/python3.12/site-packages/uvicorn/config.py", line 436, in load
    self.loaded_app = import_from_string(self.app)
                      ^^^^^^^^^^^^^^^^^^^^^^^^^^^^
  File "/home/alex/Downloads/new-pr/ai_env/lib/python3.12/site-packages/uvicorn/importer.py", line 19, in import_from_string
    module = importlib.import_module(module_str)
             ^^^^^^^^^^^^^^^^^^^^^^^^^^^^^^^^^^^
  File "/usr/lib/python3.12/importlib/__init__.py", line 90, in import_module
    return _bootstrap._gcd_import(name[level:], package, level)
           ^^^^^^^^^^^^^^^^^^^^^^^^^^^^^^^^^^^^^^^^^^^^^^^^^^^^
  File "<frozen importlib._bootstrap>", line 1387, in _gcd_import
  File "<frozen importlib._bootstrap>", line 1360, in _find_and_load
  File "<frozen importlib._bootstrap>", line 1331, in _find_and_load_unlocked
  File "<frozen importlib._bootstrap>", line 935, in _load_unlocked
  File "<frozen importlib._bootstrap_external>", line 995, in exec_module
  File "<frozen importlib._bootstrap>", line 488, in _call_with_frames_removed
  File "/home/alex/Downloads/new-pr/backend/app/main.py", line 21, in <module>
    from .config import settings
  File "/home/alex/Downloads/new-pr/backend/app/config.py", line 13, in <module>
    from pydantic import BaseSettings, validator
  File "/home/alex/Downloads/new-pr/ai_env/lib/python3.12/site-packages/pydantic/__init__.py", line 426, in __getattr__
    return _getattr_migration(attr_name)
           ^^^^^^^^^^^^^^^^^^^^^^^^^^^^^
  File "/home/alex/Downloads/new-pr/ai_env/lib/python3.12/site-packages/pydantic/_migration.py", line 296, in wrapper
    raise PydanticImportError(
pydantic.errors.PydanticImportError: `BaseSettings` has been moved to the `pydantic-settings` package. See https://docs.pydantic.dev/2.11/migration/#basesettings-has-moved-to-pydantic-settings for more details.

For further information visit https://errors.pydantic.dev/2.11/u/import-error
Process SpawnProcess-13:
Traceback (most recent call last):
  File "/usr/lib/python3.12/multiprocessing/process.py", line 314, in _bootstrap
    self.run()
  File "/usr/lib/python3.12/multiprocessing/process.py", line 108, in run
    self._target(*self._args, **self._kwargs)
  File "/home/alex/Downloads/new-pr/ai_env/lib/python3.12/site-packages/uvicorn/_subprocess.py", line 80, in subprocess_started
    target(sockets=sockets)
  File "/home/alex/Downloads/new-pr/ai_env/lib/python3.12/site-packages/uvicorn/server.py", line 67, in run
    return asyncio.run(self.serve(sockets=sockets))
           ^^^^^^^^^^^^^^^^^^^^^^^^^^^^^^^^^^^^^^^^
  File "/usr/lib/python3.12/asyncio/runners.py", line 194, in run
    return runner.run(main)
           ^^^^^^^^^^^^^^^^
  File "/usr/lib/python3.12/asyncio/runners.py", line 118, in run
    return self._loop.run_until_complete(task)
           ^^^^^^^^^^^^^^^^^^^^^^^^^^^^^^^^^^^
  File "/usr/lib/python3.12/asyncio/base_events.py", line 687, in run_until_complete
    return future.result()
           ^^^^^^^^^^^^^^^
  File "/home/alex/Downloads/new-pr/ai_env/lib/python3.12/site-packages/uvicorn/server.py", line 71, in serve
    await self._serve(sockets)
  File "/home/alex/Downloads/new-pr/ai_env/lib/python3.12/site-packages/uvicorn/server.py", line 78, in _serve
    config.load()
  File "/home/alex/Downloads/new-pr/ai_env/lib/python3.12/site-packages/uvicorn/config.py", line 436, in load
    self.loaded_app = import_from_string(self.app)
                      ^^^^^^^^^^^^^^^^^^^^^^^^^^^^
  File "/home/alex/Downloads/new-pr/ai_env/lib/python3.12/site-packages/uvicorn/importer.py", line 19, in import_from_string
    module = importlib.import_module(module_str)
             ^^^^^^^^^^^^^^^^^^^^^^^^^^^^^^^^^^^
  File "/usr/lib/python3.12/importlib/__init__.py", line 90, in import_module
    return _bootstrap._gcd_import(name[level:], package, level)
           ^^^^^^^^^^^^^^^^^^^^^^^^^^^^^^^^^^^^^^^^^^^^^^^^^^^^
  File "<frozen importlib._bootstrap>", line 1387, in _gcd_import
  File "<frozen importlib._bootstrap>", line 1360, in _find_and_load
  File "<frozen importlib._bootstrap>", line 1331, in _find_and_load_unlocked
  File "<frozen importlib._bootstrap>", line 935, in _load_unlocked
  File "<frozen importlib._bootstrap_external>", line 995, in exec_module
  File "<frozen importlib._bootstrap>", line 488, in _call_with_frames_removed
  File "/home/alex/Downloads/new-pr/backend/app/main.py", line 21, in <module>
    from .config import settings
  File "/home/alex/Downloads/new-pr/backend/app/config.py", line 13, in <module>
    from pydantic import BaseSettings, validator
  File "/home/alex/Downloads/new-pr/ai_env/lib/python3.12/site-packages/pydantic/__init__.py", line 426, in __getattr__
    return _getattr_migration(attr_name)
           ^^^^^^^^^^^^^^^^^^^^^^^^^^^^^
  File "/home/alex/Downloads/new-pr/ai_env/lib/python3.12/site-packages/pydantic/_migration.py", line 296, in wrapper
    raise PydanticImportError(
pydantic.errors.PydanticImportError: `BaseSettings` has been moved to the `pydantic-settings` package. See https://docs.pydantic.dev/2.11/migration/#basesettings-has-moved-to-pydantic-settings for more details.

For further information visit https://errors.pydantic.dev/2.11/u/import-error
INFO:     Will watch for changes in these directories: ['/home/alex/Downloads/new-pr/backend']
INFO:     Uvicorn running on http://127.0.0.1:8000 (Press CTRL+C to quit)
INFO:     Started reloader process [35109] using StatReload
Process SpawnProcess-1:
Traceback (most recent call last):
  File "/usr/lib/python3.12/multiprocessing/process.py", line 314, in _bootstrap
    self.run()
  File "/usr/lib/python3.12/multiprocessing/process.py", line 108, in run
    self._target(*self._args, **self._kwargs)
  File "/home/alex/Downloads/new-pr/ai_env/lib/python3.12/site-packages/uvicorn/_subprocess.py", line 80, in subprocess_started
    target(sockets=sockets)
  File "/home/alex/Downloads/new-pr/ai_env/lib/python3.12/site-packages/uvicorn/server.py", line 67, in run
    return asyncio.run(self.serve(sockets=sockets))
           ^^^^^^^^^^^^^^^^^^^^^^^^^^^^^^^^^^^^^^^^
  File "/usr/lib/python3.12/asyncio/runners.py", line 194, in run
    return runner.run(main)
           ^^^^^^^^^^^^^^^^
  File "/usr/lib/python3.12/asyncio/runners.py", line 118, in run
    return self._loop.run_until_complete(task)
           ^^^^^^^^^^^^^^^^^^^^^^^^^^^^^^^^^^^
  File "/usr/lib/python3.12/asyncio/base_events.py", line 687, in run_until_complete
    return future.result()
           ^^^^^^^^^^^^^^^
  File "/home/alex/Downloads/new-pr/ai_env/lib/python3.12/site-packages/uvicorn/server.py", line 71, in serve
    await self._serve(sockets)
  File "/home/alex/Downloads/new-pr/ai_env/lib/python3.12/site-packages/uvicorn/server.py", line 78, in _serve
    config.load()
  File "/home/alex/Downloads/new-pr/ai_env/lib/python3.12/site-packages/uvicorn/config.py", line 436, in load
    self.loaded_app = import_from_string(self.app)
                      ^^^^^^^^^^^^^^^^^^^^^^^^^^^^
  File "/home/alex/Downloads/new-pr/ai_env/lib/python3.12/site-packages/uvicorn/importer.py", line 19, in import_from_string
    module = importlib.import_module(module_str)
             ^^^^^^^^^^^^^^^^^^^^^^^^^^^^^^^^^^^
  File "/usr/lib/python3.12/importlib/__init__.py", line 90, in import_module
    return _bootstrap._gcd_import(name[level:], package, level)
           ^^^^^^^^^^^^^^^^^^^^^^^^^^^^^^^^^^^^^^^^^^^^^^^^^^^^
  File "<frozen importlib._bootstrap>", line 1387, in _gcd_import
  File "<frozen importlib._bootstrap>", line 1360, in _find_and_load
  File "<frozen importlib._bootstrap>", line 1331, in _find_and_load_unlocked
  File "<frozen importlib._bootstrap>", line 935, in _load_unlocked
  File "<frozen importlib._bootstrap_external>", line 995, in exec_module
  File "<frozen importlib._bootstrap>", line 488, in _call_with_frames_removed
  File "/home/alex/Downloads/new-pr/backend/app/main.py", line 21, in <module>
    from .config import settings
  File "/home/alex/Downloads/new-pr/backend/app/config.py", line 13, in <module>
    from pydantic import BaseSettings, validator
  File "/home/alex/Downloads/new-pr/ai_env/lib/python3.12/site-packages/pydantic/__init__.py", line 426, in __getattr__
    return _getattr_migration(attr_name)
           ^^^^^^^^^^^^^^^^^^^^^^^^^^^^^
  File "/home/alex/Downloads/new-pr/ai_env/lib/python3.12/site-packages/pydantic/_migration.py", line 296, in wrapper
    raise PydanticImportError(
pydantic.errors.PydanticImportError: `BaseSettings` has been moved to the `pydantic-settings` package. See https://docs.pydantic.dev/2.11/migration/#basesettings-has-moved-to-pydantic-settings for more details.

For further information visit https://errors.pydantic.dev/2.11/u/import-error
INFO:     Will watch for changes in these directories: ['/home/alex/Downloads/new-pr/backend']
INFO:     Uvicorn running on http://127.0.0.1:8000 (Press CTRL+C to quit)
INFO:     Started reloader process [36674] using StatReload
Process SpawnProcess-1:
Traceback (most recent call last):
  File "/usr/lib/python3.12/multiprocessing/process.py", line 314, in _bootstrap
    self.run()
  File "/usr/lib/python3.12/multiprocessing/process.py", line 108, in run
    self._target(*self._args, **self._kwargs)
  File "/home/alex/Downloads/new-pr/ai_env/lib/python3.12/site-packages/uvicorn/_subprocess.py", line 80, in subprocess_started
    target(sockets=sockets)
  File "/home/alex/Downloads/new-pr/ai_env/lib/python3.12/site-packages/uvicorn/server.py", line 67, in run
    return asyncio.run(self.serve(sockets=sockets))
           ^^^^^^^^^^^^^^^^^^^^^^^^^^^^^^^^^^^^^^^^
  File "/usr/lib/python3.12/asyncio/runners.py", line 194, in run
    return runner.run(main)
           ^^^^^^^^^^^^^^^^
  File "/usr/lib/python3.12/asyncio/runners.py", line 118, in run
    return self._loop.run_until_complete(task)
           ^^^^^^^^^^^^^^^^^^^^^^^^^^^^^^^^^^^
  File "/usr/lib/python3.12/asyncio/base_events.py", line 687, in run_until_complete
    return future.result()
           ^^^^^^^^^^^^^^^
  File "/home/alex/Downloads/new-pr/ai_env/lib/python3.12/site-packages/uvicorn/server.py", line 71, in serve
    await self._serve(sockets)
  File "/home/alex/Downloads/new-pr/ai_env/lib/python3.12/site-packages/uvicorn/server.py", line 78, in _serve
    config.load()
  File "/home/alex/Downloads/new-pr/ai_env/lib/python3.12/site-packages/uvicorn/config.py", line 436, in load
    self.loaded_app = import_from_string(self.app)
                      ^^^^^^^^^^^^^^^^^^^^^^^^^^^^
  File "/home/alex/Downloads/new-pr/ai_env/lib/python3.12/site-packages/uvicorn/importer.py", line 19, in import_from_string
    module = importlib.import_module(module_str)
             ^^^^^^^^^^^^^^^^^^^^^^^^^^^^^^^^^^^
  File "/usr/lib/python3.12/importlib/__init__.py", line 90, in import_module
    return _bootstrap._gcd_import(name[level:], package, level)
           ^^^^^^^^^^^^^^^^^^^^^^^^^^^^^^^^^^^^^^^^^^^^^^^^^^^^
  File "<frozen importlib._bootstrap>", line 1387, in _gcd_import
  File "<frozen importlib._bootstrap>", line 1360, in _find_and_load
  File "<frozen importlib._bootstrap>", line 1331, in _find_and_load_unlocked
  File "<frozen importlib._bootstrap>", line 935, in _load_unlocked
  File "<frozen importlib._bootstrap_external>", line 995, in exec_module
  File "<frozen importlib._bootstrap>", line 488, in _call_with_frames_removed
  File "/home/alex/Downloads/new-pr/backend/app/main.py", line 21, in <module>
    from .config import settings
  File "/home/alex/Downloads/new-pr/backend/app/config.py", line 13, in <module>
    from pydantic import BaseSettings, validator
  File "/home/alex/Downloads/new-pr/ai_env/lib/python3.12/site-packages/pydantic/__init__.py", line 426, in __getattr__
    return _getattr_migration(attr_name)
           ^^^^^^^^^^^^^^^^^^^^^^^^^^^^^
  File "/home/alex/Downloads/new-pr/ai_env/lib/python3.12/site-packages/pydantic/_migration.py", line 296, in wrapper
    raise PydanticImportError(
pydantic.errors.PydanticImportError: `BaseSettings` has been moved to the `pydantic-settings` package. See https://docs.pydantic.dev/2.11/migration/#basesettings-has-moved-to-pydantic-settings for more details.

For further information visit https://errors.pydantic.dev/2.11/u/import-error
WARNING:  StatReload detected changes in 'app/config.py'. Reloading...
WARNING:  StatReload detected changes in 'app/config.py'. Reloading...
WARNING:  StatReload detected changes in 'app/config.py'. Reloading...
WARNING:  StatReload detected changes in 'app/config.py'. Reloading...
Process SpawnProcess-2:
Traceback (most recent call last):
  File "/usr/lib/python3.12/multiprocessing/process.py", line 314, in _bootstrap
    self.run()
  File "/usr/lib/python3.12/multiprocessing/process.py", line 108, in run
    self._target(*self._args, **self._kwargs)
  File "/home/alex/Downloads/new-pr/ai_env/lib/python3.12/site-packages/uvicorn/_subprocess.py", line 80, in subprocess_started
    target(sockets=sockets)
  File "/home/alex/Downloads/new-pr/ai_env/lib/python3.12/site-packages/uvicorn/server.py", line 67, in run
    return asyncio.run(self.serve(sockets=sockets))
           ^^^^^^^^^^^^^^^^^^^^^^^^^^^^^^^^^^^^^^^^
  File "/usr/lib/python3.12/asyncio/runners.py", line 194, in run
    return runner.run(main)
           ^^^^^^^^^^^^^^^^
  File "/usr/lib/python3.12/asyncio/runners.py", line 118, in run
    return self._loop.run_until_complete(task)
           ^^^^^^^^^^^^^^^^^^^^^^^^^^^^^^^^^^^
  File "/usr/lib/python3.12/asyncio/base_events.py", line 687, in run_until_complete
    return future.result()
           ^^^^^^^^^^^^^^^
  File "/home/alex/Downloads/new-pr/ai_env/lib/python3.12/site-packages/uvicorn/server.py", line 71, in serve
    await self._serve(sockets)
  File "/home/alex/Downloads/new-pr/ai_env/lib/python3.12/site-packages/uvicorn/server.py", line 78, in _serve
    config.load()
  File "/home/alex/Downloads/new-pr/ai_env/lib/python3.12/site-packages/uvicorn/config.py", line 436, in load
    self.loaded_app = import_from_string(self.app)
                      ^^^^^^^^^^^^^^^^^^^^^^^^^^^^
  File "/home/alex/Downloads/new-pr/ai_env/lib/python3.12/site-packages/uvicorn/importer.py", line 19, in import_from_string
    module = importlib.import_module(module_str)
             ^^^^^^^^^^^^^^^^^^^^^^^^^^^^^^^^^^^
  File "/usr/lib/python3.12/importlib/__init__.py", line 90, in import_module
    return _bootstrap._gcd_import(name[level:], package, level)
           ^^^^^^^^^^^^^^^^^^^^^^^^^^^^^^^^^^^^^^^^^^^^^^^^^^^^
  File "<frozen importlib._bootstrap>", line 1387, in _gcd_import
  File "<frozen importlib._bootstrap>", line 1360, in _find_and_load
  File "<frozen importlib._bootstrap>", line 1331, in _find_and_load_unlocked
  File "<frozen importlib._bootstrap>", line 935, in _load_unlocked
  File "<frozen importlib._bootstrap_external>", line 995, in exec_module
  File "<frozen importlib._bootstrap>", line 488, in _call_with_frames_removed
  File "/home/alex/Downloads/new-pr/backend/app/main.py", line 21, in <module>
    from .config import settings
  File "/home/alex/Downloads/new-pr/backend/app/config.py", line 13, in <module>
    from pydantic_settings import BaseSettings, ConfigDict
ImportError: cannot import name 'ConfigDict' from 'pydantic_settings' (/home/alex/Downloads/new-pr/ai_env/lib/python3.12/site-packages/pydantic_settings/__init__.py)
Process SpawnProcess-15:
Traceback (most recent call last):
  File "/usr/lib/python3.12/multiprocessing/process.py", line 314, in _bootstrap
    self.run()
  File "/usr/lib/python3.12/multiprocessing/process.py", line 108, in run
    self._target(*self._args, **self._kwargs)
  File "/home/alex/Downloads/new-pr/ai_env/lib/python3.12/site-packages/uvicorn/_subprocess.py", line 80, in subprocess_started
    target(sockets=sockets)
  File "/home/alex/Downloads/new-pr/ai_env/lib/python3.12/site-packages/uvicorn/server.py", line 67, in run
    return asyncio.run(self.serve(sockets=sockets))
           ^^^^^^^^^^^^^^^^^^^^^^^^^^^^^^^^^^^^^^^^
  File "/usr/lib/python3.12/asyncio/runners.py", line 194, in run
    return runner.run(main)
           ^^^^^^^^^^^^^^^^
  File "/usr/lib/python3.12/asyncio/runners.py", line 118, in run
    return self._loop.run_until_complete(task)
           ^^^^^^^^^^^^^^^^^^^^^^^^^^^^^^^^^^^
  File "/usr/lib/python3.12/asyncio/base_events.py", line 687, in run_until_complete
    return future.result()
           ^^^^^^^^^^^^^^^
  File "/home/alex/Downloads/new-pr/ai_env/lib/python3.12/site-packages/uvicorn/server.py", line 71, in serve
    await self._serve(sockets)
  File "/home/alex/Downloads/new-pr/ai_env/lib/python3.12/site-packages/uvicorn/server.py", line 78, in _serve
    config.load()
  File "/home/alex/Downloads/new-pr/ai_env/lib/python3.12/site-packages/uvicorn/config.py", line 436, in load
    self.loaded_app = import_from_string(self.app)
                      ^^^^^^^^^^^^^^^^^^^^^^^^^^^^
  File "/home/alex/Downloads/new-pr/ai_env/lib/python3.12/site-packages/uvicorn/importer.py", line 19, in import_from_string
    module = importlib.import_module(module_str)
             ^^^^^^^^^^^^^^^^^^^^^^^^^^^^^^^^^^^
  File "/usr/lib/python3.12/importlib/__init__.py", line 90, in import_module
    return _bootstrap._gcd_import(name[level:], package, level)
           ^^^^^^^^^^^^^^^^^^^^^^^^^^^^^^^^^^^^^^^^^^^^^^^^^^^^
  File "<frozen importlib._bootstrap>", line 1387, in _gcd_import
  File "<frozen importlib._bootstrap>", line 1360, in _find_and_load
  File "<frozen importlib._bootstrap>", line 1331, in _find_and_load_unlocked
  File "<frozen importlib._bootstrap>", line 935, in _load_unlocked
  File "<frozen importlib._bootstrap_external>", line 995, in exec_module
  File "<frozen importlib._bootstrap>", line 488, in _call_with_frames_removed
  File "/home/alex/Downloads/new-pr/backend/app/main.py", line 21, in <module>
    from .config import settings
  File "/home/alex/Downloads/new-pr/backend/app/config.py", line 13, in <module>
    from pydantic_settings import BaseSettings, ConfigDict
ImportError: cannot import name 'ConfigDict' from 'pydantic_settings' (/home/alex/Downloads/new-pr/ai_env/lib/python3.12/site-packages/pydantic_settings/__init__.py)
Process SpawnProcess-2:
Traceback (most recent call last):
  File "/usr/lib/python3.12/multiprocessing/process.py", line 314, in _bootstrap
    self.run()
  File "/usr/lib/python3.12/multiprocessing/process.py", line 108, in run
    self._target(*self._args, **self._kwargs)
  File "/home/alex/Downloads/new-pr/ai_env/lib/python3.12/site-packages/uvicorn/_subprocess.py", line 80, in subprocess_started
    target(sockets=sockets)
  File "/home/alex/Downloads/new-pr/ai_env/lib/python3.12/site-packages/uvicorn/server.py", line 67, in run
    return asyncio.run(self.serve(sockets=sockets))
           ^^^^^^^^^^^^^^^^^^^^^^^^^^^^^^^^^^^^^^^^
  File "/usr/lib/python3.12/asyncio/runners.py", line 194, in run
    return runner.run(main)
           ^^^^^^^^^^^^^^^^
  File "/usr/lib/python3.12/asyncio/runners.py", line 118, in run
    return self._loop.run_until_complete(task)
           ^^^^^^^^^^^^^^^^^^^^^^^^^^^^^^^^^^^
  File "/usr/lib/python3.12/asyncio/base_events.py", line 687, in run_until_complete
    return future.result()
           ^^^^^^^^^^^^^^^
  File "/home/alex/Downloads/new-pr/ai_env/lib/python3.12/site-packages/uvicorn/server.py", line 71, in serve
    await self._serve(sockets)
  File "/home/alex/Downloads/new-pr/ai_env/lib/python3.12/site-packages/uvicorn/server.py", line 78, in _serve
    config.load()
  File "/home/alex/Downloads/new-pr/ai_env/lib/python3.12/site-packages/uvicorn/config.py", line 436, in load
    self.loaded_app = import_from_string(self.app)
                      ^^^^^^^^^^^^^^^^^^^^^^^^^^^^
  File "/home/alex/Downloads/new-pr/ai_env/lib/python3.12/site-packages/uvicorn/importer.py", line 19, in import_from_string
    module = importlib.import_module(module_str)
             ^^^^^^^^^^^^^^^^^^^^^^^^^^^^^^^^^^^
  File "/usr/lib/python3.12/importlib/__init__.py", line 90, in import_module
    return _bootstrap._gcd_import(name[level:], package, level)
           ^^^^^^^^^^^^^^^^^^^^^^^^^^^^^^^^^^^^^^^^^^^^^^^^^^^^
  File "<frozen importlib._bootstrap>", line 1387, in _gcd_import
  File "<frozen importlib._bootstrap>", line 1360, in _find_and_load
  File "<frozen importlib._bootstrap>", line 1331, in _find_and_load_unlocked
  File "<frozen importlib._bootstrap>", line 935, in _load_unlocked
  File "<frozen importlib._bootstrap_external>", line 995, in exec_module
  File "<frozen importlib._bootstrap>", line 488, in _call_with_frames_removed
  File "/home/alex/Downloads/new-pr/backend/app/main.py", line 21, in <module>
    from .config import settings
  File "/home/alex/Downloads/new-pr/backend/app/config.py", line 13, in <module>
    from pydantic_settings import BaseSettings, ConfigDict
ImportError: cannot import name 'ConfigDict' from 'pydantic_settings' (/home/alex/Downloads/new-pr/ai_env/lib/python3.12/site-packages/pydantic_settings/__init__.py)
Process SpawnProcess-14:
Traceback (most recent call last):
  File "/usr/lib/python3.12/multiprocessing/process.py", line 314, in _bootstrap
    self.run()
  File "/usr/lib/python3.12/multiprocessing/process.py", line 108, in run
    self._target(*self._args, **self._kwargs)
  File "/home/alex/Downloads/new-pr/ai_env/lib/python3.12/site-packages/uvicorn/_subprocess.py", line 80, in subprocess_started
    target(sockets=sockets)
  File "/home/alex/Downloads/new-pr/ai_env/lib/python3.12/site-packages/uvicorn/server.py", line 67, in run
    return asyncio.run(self.serve(sockets=sockets))
           ^^^^^^^^^^^^^^^^^^^^^^^^^^^^^^^^^^^^^^^^
  File "/usr/lib/python3.12/asyncio/runners.py", line 194, in run
    return runner.run(main)
           ^^^^^^^^^^^^^^^^
  File "/usr/lib/python3.12/asyncio/runners.py", line 118, in run
    return self._loop.run_until_complete(task)
           ^^^^^^^^^^^^^^^^^^^^^^^^^^^^^^^^^^^
  File "/usr/lib/python3.12/asyncio/base_events.py", line 687, in run_until_complete
    return future.result()
           ^^^^^^^^^^^^^^^
  File "/home/alex/Downloads/new-pr/ai_env/lib/python3.12/site-packages/uvicorn/server.py", line 71, in serve
    await self._serve(sockets)
  File "/home/alex/Downloads/new-pr/ai_env/lib/python3.12/site-packages/uvicorn/server.py", line 78, in _serve
    config.load()
  File "/home/alex/Downloads/new-pr/ai_env/lib/python3.12/site-packages/uvicorn/config.py", line 436, in load
    self.loaded_app = import_from_string(self.app)
                      ^^^^^^^^^^^^^^^^^^^^^^^^^^^^
  File "/home/alex/Downloads/new-pr/ai_env/lib/python3.12/site-packages/uvicorn/importer.py", line 19, in import_from_string
    module = importlib.import_module(module_str)
             ^^^^^^^^^^^^^^^^^^^^^^^^^^^^^^^^^^^
  File "/usr/lib/python3.12/importlib/__init__.py", line 90, in import_module
    return _bootstrap._gcd_import(name[level:], package, level)
           ^^^^^^^^^^^^^^^^^^^^^^^^^^^^^^^^^^^^^^^^^^^^^^^^^^^^
  File "<frozen importlib._bootstrap>", line 1387, in _gcd_import
  File "<frozen importlib._bootstrap>", line 1360, in _find_and_load
  File "<frozen importlib._bootstrap>", line 1331, in _find_and_load_unlocked
  File "<frozen importlib._bootstrap>", line 935, in _load_unlocked
  File "<frozen importlib._bootstrap_external>", line 995, in exec_module
  File "<frozen importlib._bootstrap>", line 488, in _call_with_frames_removed
  File "/home/alex/Downloads/new-pr/backend/app/main.py", line 21, in <module>
    from .config import settings
  File "/home/alex/Downloads/new-pr/backend/app/config.py", line 13, in <module>
    from pydantic_settings import BaseSettings, ConfigDict
ImportError: cannot import name 'ConfigDict' from 'pydantic_settings' (/home/alex/Downloads/new-pr/ai_env/lib/python3.12/site-packages/pydantic_settings/__init__.py)
WARNING:  StatReload detected changes in 'app/main.py'. Reloading...
WARNING:  StatReload detected changes in 'app/main.py'. Reloading...
WARNING:  StatReload detected changes in 'app/main.py'. Reloading...
WARNING:  StatReload detected changes in 'app/main.py'. Reloading...
Process SpawnProcess-3:
Traceback (most recent call last):
  File "/usr/lib/python3.12/multiprocessing/process.py", line 314, in _bootstrap
    self.run()
  File "/usr/lib/python3.12/multiprocessing/process.py", line 108, in run
    self._target(*self._args, **self._kwargs)
  File "/home/alex/Downloads/new-pr/ai_env/lib/python3.12/site-packages/uvicorn/_subprocess.py", line 80, in subprocess_started
    target(sockets=sockets)
  File "/home/alex/Downloads/new-pr/ai_env/lib/python3.12/site-packages/uvicorn/server.py", line 67, in run
    return asyncio.run(self.serve(sockets=sockets))
           ^^^^^^^^^^^^^^^^^^^^^^^^^^^^^^^^^^^^^^^^
  File "/usr/lib/python3.12/asyncio/runners.py", line 194, in run
    return runner.run(main)
           ^^^^^^^^^^^^^^^^
  File "/usr/lib/python3.12/asyncio/runners.py", line 118, in run
    return self._loop.run_until_complete(task)
           ^^^^^^^^^^^^^^^^^^^^^^^^^^^^^^^^^^^
  File "/usr/lib/python3.12/asyncio/base_events.py", line 687, in run_until_complete
    return future.result()
           ^^^^^^^^^^^^^^^
  File "/home/alex/Downloads/new-pr/ai_env/lib/python3.12/site-packages/uvicorn/server.py", line 71, in serve
    await self._serve(sockets)
  File "/home/alex/Downloads/new-pr/ai_env/lib/python3.12/site-packages/uvicorn/server.py", line 78, in _serve
    config.load()
  File "/home/alex/Downloads/new-pr/ai_env/lib/python3.12/site-packages/uvicorn/config.py", line 436, in load
    self.loaded_app = import_from_string(self.app)
                      ^^^^^^^^^^^^^^^^^^^^^^^^^^^^
  File "/home/alex/Downloads/new-pr/ai_env/lib/python3.12/site-packages/uvicorn/importer.py", line 19, in import_from_string
    module = importlib.import_module(module_str)
             ^^^^^^^^^^^^^^^^^^^^^^^^^^^^^^^^^^^
  File "/usr/lib/python3.12/importlib/__init__.py", line 90, in import_module
    return _bootstrap._gcd_import(name[level:], package, level)
           ^^^^^^^^^^^^^^^^^^^^^^^^^^^^^^^^^^^^^^^^^^^^^^^^^^^^
  File "<frozen importlib._bootstrap>", line 1387, in _gcd_import
  File "<frozen importlib._bootstrap>", line 1360, in _find_and_load
  File "<frozen importlib._bootstrap>", line 1331, in _find_and_load_unlocked
  File "<frozen importlib._bootstrap>", line 935, in _load_unlocked
  File "<frozen importlib._bootstrap_external>", line 995, in exec_module
  File "<frozen importlib._bootstrap>", line 488, in _call_with_frames_removed
  File "/home/alex/Downloads/new-pr/backend/app/main.py", line 21, in <module>
    from .config import settings
  File "/home/alex/Downloads/new-pr/backend/app/config.py", line 13, in <module>
    from pydantic_settings import BaseSettings, ConfigDict
ImportError: cannot import name 'ConfigDict' from 'pydantic_settings' (/home/alex/Downloads/new-pr/ai_env/lib/python3.12/site-packages/pydantic_settings/__init__.py)
Process SpawnProcess-16:
Traceback (most recent call last):
  File "/usr/lib/python3.12/multiprocessing/process.py", line 314, in _bootstrap
    self.run()
  File "/usr/lib/python3.12/multiprocessing/process.py", line 108, in run
    self._target(*self._args, **self._kwargs)
  File "/home/alex/Downloads/new-pr/ai_env/lib/python3.12/site-packages/uvicorn/_subprocess.py", line 80, in subprocess_started
    target(sockets=sockets)
  File "/home/alex/Downloads/new-pr/ai_env/lib/python3.12/site-packages/uvicorn/server.py", line 67, in run
    return asyncio.run(self.serve(sockets=sockets))
           ^^^^^^^^^^^^^^^^^^^^^^^^^^^^^^^^^^^^^^^^
  File "/usr/lib/python3.12/asyncio/runners.py", line 194, in run
    return runner.run(main)
           ^^^^^^^^^^^^^^^^
  File "/usr/lib/python3.12/asyncio/runners.py", line 118, in run
    return self._loop.run_until_complete(task)
           ^^^^^^^^^^^^^^^^^^^^^^^^^^^^^^^^^^^
  File "/usr/lib/python3.12/asyncio/base_events.py", line 687, in run_until_complete
    return future.result()
           ^^^^^^^^^^^^^^^
  File "/home/alex/Downloads/new-pr/ai_env/lib/python3.12/site-packages/uvicorn/server.py", line 71, in serve
    await self._serve(sockets)
  File "/home/alex/Downloads/new-pr/ai_env/lib/python3.12/site-packages/uvicorn/server.py", line 78, in _serve
    config.load()
  File "/home/alex/Downloads/new-pr/ai_env/lib/python3.12/site-packages/uvicorn/config.py", line 436, in load
    self.loaded_app = import_from_string(self.app)
                      ^^^^^^^^^^^^^^^^^^^^^^^^^^^^
  File "/home/alex/Downloads/new-pr/ai_env/lib/python3.12/site-packages/uvicorn/importer.py", line 19, in import_from_string
    module = importlib.import_module(module_str)
             ^^^^^^^^^^^^^^^^^^^^^^^^^^^^^^^^^^^
  File "/usr/lib/python3.12/importlib/__init__.py", line 90, in import_module
    return _bootstrap._gcd_import(name[level:], package, level)
           ^^^^^^^^^^^^^^^^^^^^^^^^^^^^^^^^^^^^^^^^^^^^^^^^^^^^
  File "<frozen importlib._bootstrap>", line 1387, in _gcd_import
  File "<frozen importlib._bootstrap>", line 1360, in _find_and_load
  File "<frozen importlib._bootstrap>", line 1331, in _find_and_load_unlocked
  File "<frozen importlib._bootstrap>", line 935, in _load_unlocked
  File "<frozen importlib._bootstrap_external>", line 995, in exec_module
  File "<frozen importlib._bootstrap>", line 488, in _call_with_frames_removed
  File "/home/alex/Downloads/new-pr/backend/app/main.py", line 21, in <module>
    from .config import settings
  File "/home/alex/Downloads/new-pr/backend/app/config.py", line 13, in <module>
    from pydantic_settings import BaseSettings, ConfigDict
ImportError: cannot import name 'ConfigDict' from 'pydantic_settings' (/home/alex/Downloads/new-pr/ai_env/lib/python3.12/site-packages/pydantic_settings/__init__.py)
Process SpawnProcess-3:
Traceback (most recent call last):
  File "/usr/lib/python3.12/multiprocessing/process.py", line 314, in _bootstrap
    self.run()
  File "/usr/lib/python3.12/multiprocessing/process.py", line 108, in run
    self._target(*self._args, **self._kwargs)
  File "/home/alex/Downloads/new-pr/ai_env/lib/python3.12/site-packages/uvicorn/_subprocess.py", line 80, in subprocess_started
    target(sockets=sockets)
  File "/home/alex/Downloads/new-pr/ai_env/lib/python3.12/site-packages/uvicorn/server.py", line 67, in run
    return asyncio.run(self.serve(sockets=sockets))
           ^^^^^^^^^^^^^^^^^^^^^^^^^^^^^^^^^^^^^^^^
  File "/usr/lib/python3.12/asyncio/runners.py", line 194, in run
    return runner.run(main)
           ^^^^^^^^^^^^^^^^
  File "/usr/lib/python3.12/asyncio/runners.py", line 118, in run
    return self._loop.run_until_complete(task)
           ^^^^^^^^^^^^^^^^^^^^^^^^^^^^^^^^^^^
  File "/usr/lib/python3.12/asyncio/base_events.py", line 687, in run_until_complete
    return future.result()
           ^^^^^^^^^^^^^^^
  File "/home/alex/Downloads/new-pr/ai_env/lib/python3.12/site-packages/uvicorn/server.py", line 71, in serve
    await self._serve(sockets)
  File "/home/alex/Downloads/new-pr/ai_env/lib/python3.12/site-packages/uvicorn/server.py", line 78, in _serve
    config.load()
  File "/home/alex/Downloads/new-pr/ai_env/lib/python3.12/site-packages/uvicorn/config.py", line 436, in load
    self.loaded_app = import_from_string(self.app)
                      ^^^^^^^^^^^^^^^^^^^^^^^^^^^^
  File "/home/alex/Downloads/new-pr/ai_env/lib/python3.12/site-packages/uvicorn/importer.py", line 19, in import_from_string
    module = importlib.import_module(module_str)
             ^^^^^^^^^^^^^^^^^^^^^^^^^^^^^^^^^^^
  File "/usr/lib/python3.12/importlib/__init__.py", line 90, in import_module
    return _bootstrap._gcd_import(name[level:], package, level)
           ^^^^^^^^^^^^^^^^^^^^^^^^^^^^^^^^^^^^^^^^^^^^^^^^^^^^
  File "<frozen importlib._bootstrap>", line 1387, in _gcd_import
  File "<frozen importlib._bootstrap>", line 1360, in _find_and_load
  File "<frozen importlib._bootstrap>", line 1331, in _find_and_load_unlocked
  File "<frozen importlib._bootstrap>", line 935, in _load_unlocked
  File "<frozen importlib._bootstrap_external>", line 995, in exec_module
  File "<frozen importlib._bootstrap>", line 488, in _call_with_frames_removed
  File "/home/alex/Downloads/new-pr/backend/app/main.py", line 21, in <module>
    from .config import settings
  File "/home/alex/Downloads/new-pr/backend/app/config.py", line 13, in <module>
    from pydantic_settings import BaseSettings, ConfigDict
ImportError: cannot import name 'ConfigDict' from 'pydantic_settings' (/home/alex/Downloads/new-pr/ai_env/lib/python3.12/site-packages/pydantic_settings/__init__.py)
Process SpawnProcess-15:
Traceback (most recent call last):
  File "/usr/lib/python3.12/multiprocessing/process.py", line 314, in _bootstrap
    self.run()
  File "/usr/lib/python3.12/multiprocessing/process.py", line 108, in run
    self._target(*self._args, **self._kwargs)
  File "/home/alex/Downloads/new-pr/ai_env/lib/python3.12/site-packages/uvicorn/_subprocess.py", line 80, in subprocess_started
    target(sockets=sockets)
  File "/home/alex/Downloads/new-pr/ai_env/lib/python3.12/site-packages/uvicorn/server.py", line 67, in run
    return asyncio.run(self.serve(sockets=sockets))
           ^^^^^^^^^^^^^^^^^^^^^^^^^^^^^^^^^^^^^^^^
  File "/usr/lib/python3.12/asyncio/runners.py", line 194, in run
    return runner.run(main)
           ^^^^^^^^^^^^^^^^
  File "/usr/lib/python3.12/asyncio/runners.py", line 118, in run
    return self._loop.run_until_complete(task)
           ^^^^^^^^^^^^^^^^^^^^^^^^^^^^^^^^^^^
  File "/usr/lib/python3.12/asyncio/base_events.py", line 687, in run_until_complete
    return future.result()
           ^^^^^^^^^^^^^^^
  File "/home/alex/Downloads/new-pr/ai_env/lib/python3.12/site-packages/uvicorn/server.py", line 71, in serve
    await self._serve(sockets)
  File "/home/alex/Downloads/new-pr/ai_env/lib/python3.12/site-packages/uvicorn/server.py", line 78, in _serve
    config.load()
  File "/home/alex/Downloads/new-pr/ai_env/lib/python3.12/site-packages/uvicorn/config.py", line 436, in load
    self.loaded_app = import_from_string(self.app)
                      ^^^^^^^^^^^^^^^^^^^^^^^^^^^^
  File "/home/alex/Downloads/new-pr/ai_env/lib/python3.12/site-packages/uvicorn/importer.py", line 19, in import_from_string
    module = importlib.import_module(module_str)
             ^^^^^^^^^^^^^^^^^^^^^^^^^^^^^^^^^^^
  File "/usr/lib/python3.12/importlib/__init__.py", line 90, in import_module
    return _bootstrap._gcd_import(name[level:], package, level)
           ^^^^^^^^^^^^^^^^^^^^^^^^^^^^^^^^^^^^^^^^^^^^^^^^^^^^
  File "<frozen importlib._bootstrap>", line 1387, in _gcd_import
  File "<frozen importlib._bootstrap>", line 1360, in _find_and_load
  File "<frozen importlib._bootstrap>", line 1331, in _find_and_load_unlocked
  File "<frozen importlib._bootstrap>", line 935, in _load_unlocked
  File "<frozen importlib._bootstrap_external>", line 995, in exec_module
  File "<frozen importlib._bootstrap>", line 488, in _call_with_frames_removed
  File "/home/alex/Downloads/new-pr/backend/app/main.py", line 21, in <module>
    from .config import settings
  File "/home/alex/Downloads/new-pr/backend/app/config.py", line 13, in <module>
    from pydantic_settings import BaseSettings, ConfigDict
ImportError: cannot import name 'ConfigDict' from 'pydantic_settings' (/home/alex/Downloads/new-pr/ai_env/lib/python3.12/site-packages/pydantic_settings/__init__.py)
WARNING:  StatReload detected changes in 'app/config.py'. Reloading...
WARNING:  StatReload detected changes in 'app/config.py'. Reloading...
WARNING:  StatReload detected changes in 'app/config.py'. Reloading...
WARNING:  StatReload detected changes in 'app/config.py'. Reloading...
Process SpawnProcess-4:
Traceback (most recent call last):
  File "/usr/lib/python3.12/multiprocessing/process.py", line 314, in _bootstrap
    self.run()
  File "/usr/lib/python3.12/multiprocessing/process.py", line 108, in run
    self._target(*self._args, **self._kwargs)
  File "/home/alex/Downloads/new-pr/ai_env/lib/python3.12/site-packages/uvicorn/_subprocess.py", line 80, in subprocess_started
    target(sockets=sockets)
  File "/home/alex/Downloads/new-pr/ai_env/lib/python3.12/site-packages/uvicorn/server.py", line 67, in run
    return asyncio.run(self.serve(sockets=sockets))
           ^^^^^^^^^^^^^^^^^^^^^^^^^^^^^^^^^^^^^^^^
  File "/usr/lib/python3.12/asyncio/runners.py", line 194, in run
    return runner.run(main)
           ^^^^^^^^^^^^^^^^
  File "/usr/lib/python3.12/asyncio/runners.py", line 118, in run
    return self._loop.run_until_complete(task)
           ^^^^^^^^^^^^^^^^^^^^^^^^^^^^^^^^^^^
  File "/usr/lib/python3.12/asyncio/base_events.py", line 687, in run_until_complete
    return future.result()
           ^^^^^^^^^^^^^^^
  File "/home/alex/Downloads/new-pr/ai_env/lib/python3.12/site-packages/uvicorn/server.py", line 71, in serve
    await self._serve(sockets)
  File "/home/alex/Downloads/new-pr/ai_env/lib/python3.12/site-packages/uvicorn/server.py", line 78, in _serve
    config.load()
  File "/home/alex/Downloads/new-pr/ai_env/lib/python3.12/site-packages/uvicorn/config.py", line 436, in load
    self.loaded_app = import_from_string(self.app)
                      ^^^^^^^^^^^^^^^^^^^^^^^^^^^^
  File "/home/alex/Downloads/new-pr/ai_env/lib/python3.12/site-packages/uvicorn/importer.py", line 19, in import_from_string
    module = importlib.import_module(module_str)
             ^^^^^^^^^^^^^^^^^^^^^^^^^^^^^^^^^^^
  File "/usr/lib/python3.12/importlib/__init__.py", line 90, in import_module
    return _bootstrap._gcd_import(name[level:], package, level)
           ^^^^^^^^^^^^^^^^^^^^^^^^^^^^^^^^^^^^^^^^^^^^^^^^^^^^
  File "<frozen importlib._bootstrap>", line 1387, in _gcd_import
  File "<frozen importlib._bootstrap>", line 1360, in _find_and_load
  File "<frozen importlib._bootstrap>", line 1331, in _find_and_load_unlocked
  File "<frozen importlib._bootstrap>", line 935, in _load_unlocked
  File "<frozen importlib._bootstrap_external>", line 995, in exec_module
  File "<frozen importlib._bootstrap>", line 488, in _call_with_frames_removed
  File "/home/alex/Downloads/new-pr/backend/app/main.py", line 21, in <module>
    from .config import settings
  File "/home/alex/Downloads/new-pr/backend/app/config.py", line 13, in <module>
    from pydantic_settings import BaseSettings, ConfigDict
ImportError: cannot import name 'ConfigDict' from 'pydantic_settings' (/home/alex/Downloads/new-pr/ai_env/lib/python3.12/site-packages/pydantic_settings/__init__.py)
Process SpawnProcess-16:
Traceback (most recent call last):
  File "/usr/lib/python3.12/multiprocessing/process.py", line 314, in _bootstrap
    self.run()
  File "/usr/lib/python3.12/multiprocessing/process.py", line 108, in run
    self._target(*self._args, **self._kwargs)
  File "/home/alex/Downloads/new-pr/ai_env/lib/python3.12/site-packages/uvicorn/_subprocess.py", line 80, in subprocess_started
    target(sockets=sockets)
  File "/home/alex/Downloads/new-pr/ai_env/lib/python3.12/site-packages/uvicorn/server.py", line 67, in run
    return asyncio.run(self.serve(sockets=sockets))
           ^^^^^^^^^^^^^^^^^^^^^^^^^^^^^^^^^^^^^^^^
  File "/usr/lib/python3.12/asyncio/runners.py", line 194, in run
    return runner.run(main)
           ^^^^^^^^^^^^^^^^
  File "/usr/lib/python3.12/asyncio/runners.py", line 118, in run
    return self._loop.run_until_complete(task)
           ^^^^^^^^^^^^^^^^^^^^^^^^^^^^^^^^^^^
  File "/usr/lib/python3.12/asyncio/base_events.py", line 687, in run_until_complete
    return future.result()
           ^^^^^^^^^^^^^^^
  File "/home/alex/Downloads/new-pr/ai_env/lib/python3.12/site-packages/uvicorn/server.py", line 71, in serve
    await self._serve(sockets)
  File "/home/alex/Downloads/new-pr/ai_env/lib/python3.12/site-packages/uvicorn/server.py", line 78, in _serve
    config.load()
  File "/home/alex/Downloads/new-pr/ai_env/lib/python3.12/site-packages/uvicorn/config.py", line 436, in load
    self.loaded_app = import_from_string(self.app)
                      ^^^^^^^^^^^^^^^^^^^^^^^^^^^^
  File "/home/alex/Downloads/new-pr/ai_env/lib/python3.12/site-packages/uvicorn/importer.py", line 19, in import_from_string
    module = importlib.import_module(module_str)
             ^^^^^^^^^^^^^^^^^^^^^^^^^^^^^^^^^^^
  File "/usr/lib/python3.12/importlib/__init__.py", line 90, in import_module
    return _bootstrap._gcd_import(name[level:], package, level)
           ^^^^^^^^^^^^^^^^^^^^^^^^^^^^^^^^^^^^^^^^^^^^^^^^^^^^
  File "<frozen importlib._bootstrap>", line 1387, in _gcd_import
  File "<frozen importlib._bootstrap>", line 1360, in _find_and_load
  File "<frozen importlib._bootstrap>", line 1331, in _find_and_load_unlocked
  File "<frozen importlib._bootstrap>", line 935, in _load_unlocked
  File "<frozen importlib._bootstrap_external>", line 995, in exec_module
  File "<frozen importlib._bootstrap>", line 488, in _call_with_frames_removed
  File "/home/alex/Downloads/new-pr/backend/app/main.py", line 21, in <module>
    from .config import settings
  File "/home/alex/Downloads/new-pr/backend/app/config.py", line 13, in <module>
    from pydantic_settings import BaseSettings, ConfigDict
ImportError: cannot import name 'ConfigDict' from 'pydantic_settings' (/home/alex/Downloads/new-pr/ai_env/lib/python3.12/site-packages/pydantic_settings/__init__.py)
Process SpawnProcess-4:
Traceback (most recent call last):
  File "/usr/lib/python3.12/multiprocessing/process.py", line 314, in _bootstrap
    self.run()
  File "/usr/lib/python3.12/multiprocessing/process.py", line 108, in run
    self._target(*self._args, **self._kwargs)
  File "/home/alex/Downloads/new-pr/ai_env/lib/python3.12/site-packages/uvicorn/_subprocess.py", line 80, in subprocess_started
    target(sockets=sockets)
  File "/home/alex/Downloads/new-pr/ai_env/lib/python3.12/site-packages/uvicorn/server.py", line 67, in run
    return asyncio.run(self.serve(sockets=sockets))
           ^^^^^^^^^^^^^^^^^^^^^^^^^^^^^^^^^^^^^^^^
  File "/usr/lib/python3.12/asyncio/runners.py", line 194, in run
    return runner.run(main)
           ^^^^^^^^^^^^^^^^
  File "/usr/lib/python3.12/asyncio/runners.py", line 118, in run
    return self._loop.run_until_complete(task)
           ^^^^^^^^^^^^^^^^^^^^^^^^^^^^^^^^^^^
  File "/usr/lib/python3.12/asyncio/base_events.py", line 687, in run_until_complete
    return future.result()
           ^^^^^^^^^^^^^^^
  File "/home/alex/Downloads/new-pr/ai_env/lib/python3.12/site-packages/uvicorn/server.py", line 71, in serve
    await self._serve(sockets)
  File "/home/alex/Downloads/new-pr/ai_env/lib/python3.12/site-packages/uvicorn/server.py", line 78, in _serve
    config.load()
  File "/home/alex/Downloads/new-pr/ai_env/lib/python3.12/site-packages/uvicorn/config.py", line 436, in load
    self.loaded_app = import_from_string(self.app)
                      ^^^^^^^^^^^^^^^^^^^^^^^^^^^^
  File "/home/alex/Downloads/new-pr/ai_env/lib/python3.12/site-packages/uvicorn/importer.py", line 19, in import_from_string
    module = importlib.import_module(module_str)
             ^^^^^^^^^^^^^^^^^^^^^^^^^^^^^^^^^^^
  File "/usr/lib/python3.12/importlib/__init__.py", line 90, in import_module
    return _bootstrap._gcd_import(name[level:], package, level)
           ^^^^^^^^^^^^^^^^^^^^^^^^^^^^^^^^^^^^^^^^^^^^^^^^^^^^
  File "<frozen importlib._bootstrap>", line 1387, in _gcd_import
  File "<frozen importlib._bootstrap>", line 1360, in _find_and_load
  File "<frozen importlib._bootstrap>", line 1331, in _find_and_load_unlocked
  File "<frozen importlib._bootstrap>", line 935, in _load_unlocked
  File "<frozen importlib._bootstrap_external>", line 995, in exec_module
  File "<frozen importlib._bootstrap>", line 488, in _call_with_frames_removed
  File "/home/alex/Downloads/new-pr/backend/app/main.py", line 21, in <module>
    from .config import settings
  File "/home/alex/Downloads/new-pr/backend/app/config.py", line 13, in <module>
    from pydantic_settings import BaseSettings, ConfigDict
ImportError: cannot import name 'ConfigDict' from 'pydantic_settings' (/home/alex/Downloads/new-pr/ai_env/lib/python3.12/site-packages/pydantic_settings/__init__.py)
Process SpawnProcess-17:
Traceback (most recent call last):
  File "/usr/lib/python3.12/multiprocessing/process.py", line 314, in _bootstrap
    self.run()
  File "/usr/lib/python3.12/multiprocessing/process.py", line 108, in run
    self._target(*self._args, **self._kwargs)
  File "/home/alex/Downloads/new-pr/ai_env/lib/python3.12/site-packages/uvicorn/_subprocess.py", line 80, in subprocess_started
    target(sockets=sockets)
  File "/home/alex/Downloads/new-pr/ai_env/lib/python3.12/site-packages/uvicorn/server.py", line 67, in run
    return asyncio.run(self.serve(sockets=sockets))
           ^^^^^^^^^^^^^^^^^^^^^^^^^^^^^^^^^^^^^^^^
  File "/usr/lib/python3.12/asyncio/runners.py", line 194, in run
    return runner.run(main)
           ^^^^^^^^^^^^^^^^
  File "/usr/lib/python3.12/asyncio/runners.py", line 118, in run
    return self._loop.run_until_complete(task)
           ^^^^^^^^^^^^^^^^^^^^^^^^^^^^^^^^^^^
  File "/usr/lib/python3.12/asyncio/base_events.py", line 687, in run_until_complete
    return future.result()
           ^^^^^^^^^^^^^^^
  File "/home/alex/Downloads/new-pr/ai_env/lib/python3.12/site-packages/uvicorn/server.py", line 71, in serve
    await self._serve(sockets)
  File "/home/alex/Downloads/new-pr/ai_env/lib/python3.12/site-packages/uvicorn/server.py", line 78, in _serve
    config.load()
  File "/home/alex/Downloads/new-pr/ai_env/lib/python3.12/site-packages/uvicorn/config.py", line 436, in load
    self.loaded_app = import_from_string(self.app)
                      ^^^^^^^^^^^^^^^^^^^^^^^^^^^^
  File "/home/alex/Downloads/new-pr/ai_env/lib/python3.12/site-packages/uvicorn/importer.py", line 19, in import_from_string
    module = importlib.import_module(module_str)
             ^^^^^^^^^^^^^^^^^^^^^^^^^^^^^^^^^^^
  File "/usr/lib/python3.12/importlib/__init__.py", line 90, in import_module
    return _bootstrap._gcd_import(name[level:], package, level)
           ^^^^^^^^^^^^^^^^^^^^^^^^^^^^^^^^^^^^^^^^^^^^^^^^^^^^
  File "<frozen importlib._bootstrap>", line 1387, in _gcd_import
  File "<frozen importlib._bootstrap>", line 1360, in _find_and_load
  File "<frozen importlib._bootstrap>", line 1331, in _find_and_load_unlocked
  File "<frozen importlib._bootstrap>", line 935, in _load_unlocked
  File "<frozen importlib._bootstrap_external>", line 995, in exec_module
  File "<frozen importlib._bootstrap>", line 488, in _call_with_frames_removed
  File "/home/alex/Downloads/new-pr/backend/app/main.py", line 21, in <module>
    from .config import settings
  File "/home/alex/Downloads/new-pr/backend/app/config.py", line 13, in <module>
    from pydantic_settings import BaseSettings, ConfigDict
ImportError: cannot import name 'ConfigDict' from 'pydantic_settings' (/home/alex/Downloads/new-pr/ai_env/lib/python3.12/site-packages/pydantic_settings/__init__.py)
INFO:     Stopping reloader process [29216]
INFO:     Stopping reloader process [35109]
INFO:     Stopping reloader process [36674]
INFO:     Stopping reloader process [29938]
